Workbook

Sheet PINJAMAN
A2: Tanggal | B2: Deskripsi | C2: Masuk | D2: Keluar | E2: Total | F2: Keterangan
B3: Saldo | E3: 0
A4: 45893 | B4: Dipinjamkan ke PKK | D4: 2000000 | E4: =IF(AND(C4="",D4=""),"",E3+C4-D4) -> -2000000
A5: 46168 | B5: Dipinjamkan ke PKK | D5: 2000000 | E5: =IF(AND(C5="",D5=""),"",E4+C5-D5) -> -4000000
A6: 46173 | B6: Pembayaran Cor Balai | D6: 4400000 | E6: =IF(AND(C6="",D6=""),"",E5+C6-D6) -> -8400000
E7: =IF(AND(C7="",D7=""),"",E6+C7-D7)
E8: =IF(AND(C8="",D8=""),"",E7+C8-D8)
E9: =IF(AND(C9="",D9=""),"",E8+C9-D9)
E10: =IF(AND(C10="",D10=""),"",E9+C10-D10)
E11: =IF(AND(C11="",D11=""),"",E10+C11-D11)
E12: =IF(AND(C12="",D12=""),"",E11+C12-D12)
E13: =IF(AND(C13="",D13=""),"",E12+C13-D13)
E14: =IF(AND(C14="",D14=""),"",E13+C14-D14)
E15: =IF(AND(C15="",D15=""),"",E14+C15-D15)
E16: =IF(AND(C16="",D16=""),"",E15+C16-D16)
E17: =IF(AND(C17="",D17=""),"",E16+C17-D17)
E18: =IF(AND(C18="",D18=""),"",E17+C18-D18)
E19: =IF(AND(C19="",D19=""),"",E18+C19-D19)

Sheet 11-07-26 (2)
A2: Nasabah | B2: Material | C2: Berat | D2: Harga | E2: Total | G2: Row Labels | H2: Sum of Berat | I2: Sum of Total | K2: Row Labels | L2: Sum of Berat | N2: Timbangan Kami Box | Q2: Sabtu, 11 Juli 2026 | T2: Timbangan Non Kami Box | W2: Sabtu, 11 Juli 2026 | Z2: Timbangan Non Kami Box | AC2: Sabtu, 11 Juli 2026
A3: MBA DIAN | B3: Baja Ringan | C3: 0.55 | D3: 1 | E3: =C3*D3 -> 0.55 | G3: AKHSAN | H3: 12.2 | I3: 16305 | K3: Aki | L3: 2.7 | N3: No | O3: Jenis Sampah | P3: Harga | Q3: Berat | R3: Total Harga | T3: No | U3: Jenis Sampah | V3: Harga | W3: Berat | X3: Total Harga | Z3: No | AA3: Jenis Sampah | AB3: Harga | AC3: Berat | AD3: Total Harga | AF3: Keuntungan Jelantah
A4: BU FEBRI | B4: Selang | C4: 1.1 | D4: 400 | E4: =C4*D4 -> 440 | G4: BU ANI | H4: 6 | I4: 6513 | K4: Aluminium Rongsok | L4: 0.45 | N4: 1 | O4: AC | P4: =VLOOKUP(O4,KamiBox!$C$2:$F$58,4,0) -> 200000 | Q4: =SUMIF($B$3:$B$346,O4,$C$3:$C$346) -> 0 | R4: =P4*Q4 -> 0 | T4: 1 | U4: Asoy | V4: =VLOOKUP(U4,KamiBox!$C$2:$F$58,4,0) -> 1500 | W4: =SUMIF($B$3:$B$346,U4,$C$3:$C$346) -> 19.7 | X4: =V4*W4 -> 29550 | Z4: 1 | AA4: Jelantah | AB4: 8800 | AC4: =(17*9)+15 -> 168 | AD4: 1482000 | AE4: 1080250 | AF4: =AD4-AE4 -> 401750
A5: BU SARTI | B5: Gabrukan | C5: 0.3 | D5: 1000 | E5: 300 | G5: BU ANI RW 21 | H5: 15.2 | I5: 106400 | K5: Asoy | L5: 19.7 | M5: =2.7+4.15 -> 6.85 | N5: 2 | O5: Aki | P5: =VLOOKUP(O5,KamiBox!$C$2:$F$58,4,0) -> 9000 | Q5: =SUMIF($B$3:$B$346,O5,$C$3:$C$346) -> 2.7 | R5: =P5*Q5 -> 24300 | T5: 2 | U5: Plastik PE | V5: 1700 | W5: =SUMIF($B$3:$B$346,U5,$C$3:$C$346) -> 0.6 | X5: =V5*W5 -> 1020
A6: BU SARTI | B6: Plastik Multilayer | C6: 0.4 | D6: 300 | E6: 120 | G6: BU ANWAR | H6: 5.73 | I6: 6345 | K6: Baja Ringan | L6: 0.55 | N6: 3 | O6: Akrilik Putih | P6: =VLOOKUP(O6,KamiBox!$C$2:$F$58,4,0) -> 4000 | Q6: =SUMIF($B$3:$B$346,O6,$C$3:$C$346) -> 0 | R6: =P6*Q6 -> 0 | T6: 3 | U6: Plastik PP | V6: 1700 | W6: =SUMIF($B$3:$B$346,U6,$C$3:$C$346) -> 4.15 | X6: =V6*W6 -> 7055
A7: BU SARTI | B7: Jelantah | C7: 2.15 | D7: 5000 | E7: 10750 | G7: BU BETRIA | H7: 12.3 | I7: 16223 | K7: Besi | L7: 9.4 | N7: 4 | O7: Alumunium | P7: =VLOOKUP(O7,KamiBox!$C$2:$F$58,4,0) -> 10000 | Q7: =GETPIVOTDATA("Berat",$K$2,"Material","Aluminium Rongsok") -> 0.45 | R7: =P7*Q7 -> 4500 | U7: TOTAL | W7: =SUM(W4:W6) -> 24.45 | X7: =SUM(X4:X6) -> 37625
A8: BU SARTI | B8: Emberan | C8: 0.55 | D8: 1000 | E8: 550 | G8: BU ECIN DWI | H8: 31.05 | I8: 34575 | K8: Botol Kaca Bening/Putih | L8: 22.95 | N8: 5 | O8: Arsip | P8: =VLOOKUP(O8,KamiBox!$C$2:$F$58,4,0) -> 1000 | Q8: =SUMIF($B$3:$B$346,O8,$C$3:$C$346) -> 0 | R8: =P8*Q8 -> 0
A9: BU SARTI | B9: Asoy | C9: 0.2 | D9: 500 | E9: 100 | G9: BU FATIMAH | H9: 2.15 | I9: 2150 | K9: Botol PET bersih | L9: 55.38 | M9: =6.35+3.6+2.65+2.85+2.8+3.15+4.05+5.4+4.9+4.2+4+4.9+6.25+3.3+0.1 -> 58.5 | N9: 6 | O9: Asoy | R9: =P9*Q9 -> 0 | Z9: Timbangan Non Kami Box | AC9: Sabtu, 11 Juli 2026
A10: BU SARTI | B10: Buku, majalah, brosur, koran | C10: 0.9 | D10: 800 | E10: 720 | G10: BU FEBRI | H10: 4.8 | I10: 2893 | K10: Botol PET Kotor | L10: 13.33 | N10: 7 | O10: Besi | P10: =VLOOKUP(O10,KamiBox!$C$2:$F$58,4,0) -> 4000 | Q10: =SUMIF($B$3:$B$346,O10,$C$3:$C$346) -> 9.4 | R10: =P10*Q10 -> 37600 | Z10: No | AA10: Jenis Sampah | AB10: Harga | AC10: Berat | AD10: Total Harga
A11: BU SARTI | B11: MIX A/Boncos | C11: 0.2 | D11: 500 | E11: 100 | G11: BU HADIYANA | H11: 27.15 | I11: 47675 | K11: Buku, majalah, brosur, koran | L11: 36.85 | N11: 8 | O11: Boncos Kotor | P11: =VLOOKUP(O11,KamiBox!$C$2:$F$58,4,0) -> 400 | Q11: =SUMIF($B$3:$B$346,O11,$C$3:$C$346) -> 0 | R11: =P11*Q11 -> 0 | Z11: 1 | AA11: Jelantah | AB11: 8800 | AC11: =SUMIF($B$3:$B$346,AA11,$C$3:$C$346) -> 82.1 | AD11: =AB11*AC11 -> 722480
A12: BU SARTI | B12: Kardus | C12: 7.85 | D12: 1000 | E12: 7850 | G12: BU HARTINAH | H12: 14.55 | I12: 10828 | K12: Emberan | L12: 68.65 | N12: 9 | O12: Botol Kaca Hijau | P12: =VLOOKUP(O12,KamiBox!$C$2:$F$58,4,0) -> 100 | Q12: =SUMIF($B$3:$B$346,O12,$C$3:$C$346) -> 0 | R12: =P12*Q12 -> 0 | AC12: 91.45 | AD12: 804760
A13: BU NURLAYLI | B13: Asoy | C13: 0.5 | D13: 500 | E13: 250 | G13: BU IRMA | H13: 5.5 | I13: 5235 | K13: Gabrukan | L13: 29 | N13: 10 | O13: Botol Kaca Bening/Putih | P13: =VLOOKUP(O13,KamiBox!$C$2:$F$58,4,0) -> 200 | Q13: =SUMIF($B$3:$B$346,O13,$C$3:$C$346) -> 22.95 | R13: =P13*Q13 -> 4590
A14: BU NURLAYLI | B14: Botol Kaca Bening/Putih | C14: 0.55 | D14: 150 | E14: 83 | G14: BU LINDA RW 19 | H14: 10.6 | I14: 13000 | K14: Gelas PP Bersih (bening) | L14: 0.3 | N14: 11 | O14: Botol Kaca Campur | P14: =VLOOKUP(O14,KamiBox!$C$2:$F$58,4,0) -> 100 | Q14: =SUMIF($B$3:$B$346,O14,$C$3:$C$346) -> 0 | R14: =P14*Q14 -> 0
A15: BU NURLAYLI | B15: MIX A/Boncos | C15: 0.6 | D15: 500 | E15: 300 | G15: BU MINAH | H15: 2.45 | I15: 4090 | K15: Gelas PP Warna | L15: 2.15 | N15: 12 | O15: Botol Kaca Coklat/Merah | P15: =VLOOKUP(O15,KamiBox!$C$2:$F$58,4,0) -> 800 | Q15: =SUMIF($B$3:$B$346,O15,$C$3:$C$346) -> 0 | R15: =P15*Q15 -> 0
A16: BU NURLAYLI | B16: Plastik Multilayer | C16: 0.45 | D16: 300 | E16: 135 | G16: BU NATIRA SALMAWATI | H16: 11 | I16: 15258 | K16: HVS/Putihan | L16: 7.15 | N16: 13 | O16: Botol PET bersih | P16: =VLOOKUP(O16,KamiBox!$C$2:$F$58,4,0) -> 5000 | Q16: 58.5 | R16: =P16*Q16 -> 292500
A17: BU IRMA | B17: Emberan | C17: 0.4 | D17: 1000 | E17: 400 | G17: BU NENI | H17: 10.95 | I17: 20150 | K17: Jelantah | L17: 82.1 | M17: 60.25 | N17: 14 | O17: Botol PET Kotor | P17: =VLOOKUP(O17,KamiBox!$C$2:$F$58,4,0) -> 2500 | Q17: =SUMIF($B$3:$B$346,O17,$C$3:$C$346) -> 13.33 | R17: =P17*Q17 -> 33325
A18: BU IRMA | B18: Plastik PE | C18: 0.2 | D18: 800 | E18: 160 | G18: BU NURJANAH | H18: 5.45 | I18: 6855 | K18: Kabel Alumunium | L18: 3.5 | M18: =GETPIVOTDATA("Berat",$K$2,"Material","Jelantah")-M17 -> 21.85 | N18: 15 | O18: Botol Plastik Kemasan Campur | P18: =VLOOKUP(O18,KamiBox!$C$2:$F$58,4,0) -> 1000 | Q18: =SUMIF($B$3:$B$346,O18,$C$3:$C$346) -> 0 | R18: =P18*Q18 -> 0
A19: BU IRMA | B19: Kardus | C19: 0.6 | D19: 1000 | E19: 600 | G19: BU NURLAYLI | H19: 2.1 | I19: 768 | K19: Kaleng | L19: 13.45 | N19: 16 | O19: Buku, majalah, brosur, koran | P19: =VLOOKUP(O19,KamiBox!$C$2:$F$58,4,0) -> 1000 | Q19: =SUMIF($B$3:$B$346,O19,$C$3:$C$346) -> 36.85 | R19: =P19*Q19 -> 36850
A20: BU IRMA | B20: Buku, majalah, brosur, koran | C20: 3.6 | D20: 800 | E20: 2880 | G20: BU RATIH RT 5 | H20: 8.05 | I20: 7825 | K20: Kardus | L20: 156.9 | N20: 17 | O20: Emberan | P20: =VLOOKUP(O20,KamiBox!$C$2:$F$58,4,0) -> 1200 | Q20: =SUMIF($B$3:$B$346,O20,$C$3:$C$346) -> 68.65 | R20: =P20*Q20 -> 82380
A21: BU IRMA | B21: Tutup Botol | C21: 0.05 | D21: 2500 | E21: 125 | G21: BU RINA | H21: 1.55 | I21: 7750 | K21: Karung | L21: 1.3 | N21: 18 | O21: Gabrukan | P21: =VLOOKUP(O21,KamiBox!$C$2:$F$58,4,0) -> 1000 | Q21: =SUMIF($B$3:$B$346,O21,$C$3:$C$346) -> 29 | R21: =P21*Q21 -> 29000
A22: BU IRMA | B22: Plastik Multilayer | C22: 0.3 | D22: 300 | E22: 90 | G22: BU RINDRA | H22: 5.05 | I22: 6680 | K22: Kristal Putih | L22: 0.4 | N22: 19 | O22: Galon PC | P22: =VLOOKUP(O22,KamiBox!$C$2:$F$58,4,0) -> 3000 | Q22: =SUMIF($B$3:$B$346,O22,$C$3:$C$346) -> 0 | R22: =P22*Q22 -> 0
A23: BU IRMA | B23: Botol PET bersih | C23: 0.35 | D23: 2800 | E23: 980 | G23: BU RUMIYATI | H23: 6.7 | I23: 9775 | K23: MIX A/Boncos | L23: 36.1 | N23: 20 | O23: Gelas PP Bersih | P23: =VLOOKUP(O23,KamiBox!$C$2:$F$58,4,0) -> 4000 | Q23: =GETPIVOTDATA("Berat",$K$2,"Material","Gelas PP Bersih (bening)") -> 0.3 | R23: =P23*Q23 -> 1200
A24: KAS | B24: Plastik PP | C24: 1.35 | D24: 1000 | E24: 1350 | G24: BU SANDRA | H24: 32.93 | I24: 36074 | K24: Plastik Multilayer | L24: 33.97 | M24: =7.9+9.45+6.9+9.25+8.05+8+7.85+6.1 -> 63.5 | N24: 21 | O24: Gelas PP Warna | P24: =VLOOKUP(O24,KamiBox!$C$2:$F$58,4,0) -> 2000 | Q24: =SUMIF($B$3:$B$346,O24,$C$3:$C$346) -> 2.15 | R24: =P24*Q24 -> 4300
A25: KAS | B25: Asoy | C25: 2.3 | D25: 500 | E25: 1150 | G25: BU SARIYANTI | H25: 6.5 | I25: 5440 | K25: Plastik PE | L25: 0.6 | N25: 22 | O25: Handphone | P25: =VLOOKUP(O25,KamiBox!$C$2:$F$58,4,0) -> 5000 | Q25: =SUMIF($B$3:$B$346,O25,$C$3:$C$346) -> 0 | R25: =P25*Q25 -> 0
A26: KAS | B26: Kristal Putih | C26: 0.4 | D26: 2700 | E26: 1080 | G26: BU SARTI | H26: 12.55 | I26: 20490 | K26: Plastik PP | L26: 4.15 | N26: 23 | O26: HVS/Putihan | P26: =VLOOKUP(O26,KamiBox!$C$2:$F$58,4,0) -> 2000 | Q26: =SUMIF($B$3:$B$346,O26,$C$3:$C$346) -> 7.15 | R26: =P26*Q26 -> 14300
A27: BU TETTY HAMDI | B27: STAL/Kabin/Enamel | C27: 0.65 | D27: 1800 | E27: 1170 | G27: BU SITI ALFIYAH | H27: 10.4 | I27: 12005 | K27: PVC | L27: 2.6 | N27: 24 | O27: Impact | P27: =VLOOKUP(O27,KamiBox!$C$2:$F$58,4,0) -> 700 | Q27: =SUMIF($B$3:$B$346,O27,$C$3:$C$346) -> 0 | R27: =P27*Q27 -> 0
A28: BU TETTY HAMDI | B28: Plastik Multilayer | C28: 1 | D28: 300 | E28: 300 | G28: BU SRI RETNO | H28: 35.35 | I28: 36000 | K28: Selang | L28: 1.1 | N28: 25 | O28: Jelantah
A29: BU TETTY HAMDI | B29: Botol Kaca Bening/Putih | C29: 0.6 | D29: 150 | E29: 90 | G29: BU SUHERMIATI | H29: 4.85 | I29: 5815 | K29: Seng/Kawat | L29: 0.3 | N29: 26 | O29: Kabel | P29: =VLOOKUP(O29,KamiBox!$C$2:$F$58,4,0) -> 1500 | Q29: =GETPIVOTDATA("Berat",$K$2,"Material","Kabel Alumunium") -> 3.5 | R29: =P29*Q29 -> 5250
A30: BU TETTY HAMDI | B30: MIX A/Boncos | C30: 0.75 | D30: 500 | E30: 375 | G30: BU SURIYA | H30: 2.85 | I30: 2860 | K30: STAL/Kabin/Enamel | L30: 9.7 | N30: 27 | O30: Kabin | P30: =VLOOKUP(O30,KamiBox!$C$2:$F$58,4,0) -> 2000 | Q30: =GETPIVOTDATA("Berat",$K$2,"Material","STAL/Kabin/Enamel") -> 9.7 | R30: =P30*Q30 -> 19400
A31: BU TETTY HAMDI | B31: Gabrukan | C31: 1.2 | D31: 1000 | E31: 1200 | G31: BU TERMIN | H31: 5.55 | I31: 9385 | K31: Tutup Botol | L31: 4.85 | M31: =3.85+11.1 -> 14.95 | N31: 28 | O31: Kaca | P31: =VLOOKUP(O31,KamiBox!$C$2:$F$58,4,0) -> 100 | Q31: =SUMIF($B$3:$B$346,O31,$C$3:$C$346) -> 0 | R31: =P31*Q31 -> 0
A32: BU TETTY HAMDI | B32: Emberan | C32: 0.4 | D32: 1000 | E32: 400 | G32: BU TETTY HAMDI | H32: 14.9 | I32: 14260 | K32: Tutup Galon | L32: 1.63 | M32: 2.4 | N32: 29 | O32: Kaleng | P32: =VLOOKUP(O32,KamiBox!$C$2:$F$58,4,0) -> 2000 | Q32: =SUMIF($B$3:$B$346,O32,$C$3:$C$346) -> 13.45 | R32: =P32*Q32 -> 26900
A33: BU TETTY HAMDI | B33: Tutup Botol | C33: 0.1 | D33: 2500 | E33: 250 | G33: BU TUNUT | H33: 26.7 | I33: 32480 | K33: Grand Total | L33: 621.21 | N33: 30 | O33: Kantung Semen | P33: =VLOOKUP(O33,KamiBox!$C$2:$F$58,4,0) -> 1800 | Q33: =SUMIF($B$3:$B$346,O33,$C$3:$C$346) -> 0 | R33: =P33*Q33 -> 0
A34: BU TETTY HAMDI | B34: Kaleng | C34: 0.55 | D34: 1500 | E34: 825 | G34: BU WIDODO | H34: 2.75 | I34: 6758 | N34: 31 | O34: Kardus | P34: =VLOOKUP(O34,KamiBox!$C$2:$F$58,4,0) -> 1800 | Q34: =SUMIF($B$3:$B$346,O34,$C$3:$C$346) -> 156.9 | R34: =P34*Q34 -> 282420
A35: BU TETTY HAMDI | B35: Kardus | C35: 9.65 | D35: 1000 | E35: 9650 | G35: BU WIWIN | H35: 12.55 | I35: 17353 | N35: 32 | O35: Kaset CD | P35: =VLOOKUP(O35,KamiBox!$C$2:$F$58,4,0) -> 4000 | Q35: =SUMIF($B$3:$B$346,O35,$C$3:$C$346) -> 0 | R35: =P35*Q35 -> 0
A36: BU ANI | B36: Plastik Multilayer | C36: 0.7 | D36: 300 | E36: 210 | G36: BU YANTI | H36: 16.4 | I36: 18073 | N36: 33 | O36: Komputer | P36: =VLOOKUP(O36,KamiBox!$C$2:$F$58,4,0) -> 60000 | Q36: =SUMIF($B$3:$B$346,O36,$C$3:$C$346) -> 0 | R36: =P36*Q36 -> 0
A37: BU ANI | B37: Botol Kaca Bening/Putih | C37: 0.85 | D37: 150 | E37: 128 | G37: BU YANTI BELA | H37: 22.5 | I37: 26158 | K37: Keuntungan Penjualan | N37: 34 | O37: Kones | P37: =VLOOKUP(O37,KamiBox!$C$2:$F$58,4,0) -> 700 | Q37: =SUMIF($B$3:$B$346,O37,$C$3:$C$346) -> 0 | R37: =P37*Q37 -> 0
A38: BU ANI | B38: Gelas PP Warna | C38: 0.45 | D38: 1600 | E38: 720 | G38: BU YENVITRIATI | H38: 10.7 | I38: 16705 | K38: =R60+X7+AF4 -> #N/A | N38: 35 | O38: Kristal Putih | P38: =VLOOKUP(O38,KamiBox!$C$2:$F$58,4,0) -> 4000 | Q38: =SUMIF($B$3:$B$346,O38,$C$3:$C$346) -> 0.4 | R38: =P38*Q38 -> 1600
A39: BU ANI | B39: Emberan | C39: 0.45 | D39: 1000 | E39: 450 | G39: DAME | H39: 26.3 | I39: 46575 | K39: =K38-GETPIVOTDATA("Total",$G$2) -> #N/A | N39: 36 | O39: Kulkas | P39: =VLOOKUP(O39,KamiBox!$C$2:$F$58,4,0) -> 50000 | Q39: =SUMIF($B$3:$B$346,O39,$C$3:$C$346) -> 0 | R39: =P39*Q39 -> 0
A40: BU ANI | B40: Botol PET bersih | C40: 0.85 | D40: 2800 | E40: 2380 | G40: DANANG | H40: 1.5 | I40: 450 | N40: 37 | O40: Kuningan | P40: =VLOOKUP(O40,KamiBox!$C$2:$F$58,4,0) -> 35000 | Q40: =SUMIF($B$3:$B$346,O40,$C$3:$C$346) -> 0 | R40: =P40*Q40 -> 0
A41: BU ANI | B41: Kaleng | C41: 0.95 | D41: 1500 | E41: 1425 | G41: ESHAN | H41: 15.3 | I41: 45770 | N41: 38 | O41: Mesin Cuci | P41: =VLOOKUP(O41,KamiBox!$C$2:$F$58,4,0) -> 50000 | Q41: =SUMIF($B$3:$B$346,O41,$C$3:$C$346) -> 0 | R41: =P41*Q41 -> 0
...

Sheet 21-6-26 (2)
A2: Nasabah | B2: Material | C2: Berat | D2: Harga | E2: Total | G2: Row Labels | H2: Sum of Berat | I2: Sum of Total | K2: Row Labels | L2: Sum of Berat | N2: Timbangan Kami Box | Q2: Minggu, 21 Juni 2026 | T2: Timbangan Non Kami Box | W2: Minggu, 21 Juni 2026
A3: Aruna RT 5 | B3: Jelantah | C3: 8.95 | D3: 5000 | E3: 44750 | G3: Aruna RT 5 | H3: 8.95 | I3: 44750 | K3: Aluminium Rongsok | L3: 0.4 | N3: No | O3: Jenis Sampah | P3: Harga | Q3: Berat | R3: Total Harga | T3: No | U3: Jenis Sampah | V3: Harga | W3: Berat | X3: Total Harga
A4: Bu Admini | B4: Kardus | C4: 1.2 | D4: 1000 | E4: 1200 | G4: Bu Admini | H4: 6.6 | I4: 7200 | K4: Asoy | L4: 13.1 | N4: 1 | O4: AC | P4: =VLOOKUP(O4,KamiBox!$C$2:$F$58,4,0) -> 200000 | Q4: =SUMIF($B$3:$B$394,O4,$C$3:$C$394) -> 0 | R4: =P4*Q4 -> 0 | T4: 1 | U4: AC | V4: =VLOOKUP(U4,KamiBox!$C$2:$F$58,4,0) -> 200000 | X4: =V4*W4 -> 0
A5: Bu Admini | B5: Gelas PP Warna | C5: 0.9 | D5: 1600 | E5: 1440 | G5: Bu Angga | H5: 10.7 | I5: 26193 | K5: Besi | L5: 25.85 | N5: 2 | O5: Aki | P5: =VLOOKUP(O5,KamiBox!$C$2:$F$58,4,0) -> 9000 | Q5: =SUMIF($B$3:$B$394,O5,$C$3:$C$394) -> 0 | R5: =P5*Q5 -> 0 | T5: 2 | U5: Aki | V5: =VLOOKUP(U5,KamiBox!$C$2:$F$58,4,0) -> 9000 | X5: =V5*W5 -> 0
A6: Bu Admini | B6: MIX A/Boncos | C6: 2.3 | D6: 500 | E6: 1150 | G6: Bu Ani | H6: 9.15 | I6: 9943 | K6: Botol Kaca Bening/Putih | L6: 23.65 | N6: 3 | O6: Akrilik Putih | P6: =VLOOKUP(O6,KamiBox!$C$2:$F$58,4,0) -> 4000 | Q6: =SUMIF($B$3:$B$394,O6,$C$3:$C$394) -> 0 | R6: =P6*Q6 -> 0 | T6: 3 | U6: Akrilik Putih | V6: =VLOOKUP(U6,KamiBox!$C$2:$F$58,4,0) -> 4000 | X6: =V6*W6 -> 0
A7: Bu Admini | B7: Plastik Multilayer | C7: 1.1 | D7: 300 | E7: 330 | G7: Bu Betria | H7: 20.95 | I7: 19083 | K7: Botol Kaca Coklat/Merah | L7: 0.8 | N7: 4 | O7: Alumunium | P7: =VLOOKUP(O7,KamiBox!$C$2:$F$58,4,0) -> 10000 | Q7: 0.4 | R7: =P7*Q7 -> 4000 | T7: 4 | U7: Alumunium | V7: =VLOOKUP(U7,KamiBox!$C$2:$F$58,4,0) -> 10000 | X7: =V7*W7 -> 0
A8: Bu Admini | B8: Botol PET bersih | C8: 1.1 | D8: 2800 | E8: 3080 | G8: Bu Dida | H8: 16 | I8: 25413 | K8: Botol Kaca Hijau | L8: 8 | N8: 5 | O8: Arsip | P8: =VLOOKUP(O8,KamiBox!$C$2:$F$58,4,0) -> 1000 | Q8: =SUMIF($B$3:$B$394,O8,$C$3:$C$394) -> 0 | R8: =P8*Q8 -> 0 | T8: 5 | U8: Arsip | V8: =VLOOKUP(U8,KamiBox!$C$2:$F$58,4,0) -> 1000 | X8: =V8*W8 -> 0
A9: Bu Angga | B9: Botol Kaca Bening/Putih | C9: 0.35 | D9: 150 | E9: 53 | G9: Bu Ecin Dwi | H9: 17 | I9: 21273 | K9: Botol PET bersih | L9: 57.45 | N9: 6 | O9: Asoy | Q9: 0 | R9: =P9*Q9 -> 0 | S9: =W9-Q9 -> 16.05 | T9: 6 | U9: Asoy | V9: =VLOOKUP(U9,KamiBox!$C$2:$F$58,4,0) -> 1500 | W9: 16.05 | X9: 24825 | Y9: Pak Muslih
A10: Bu Angga | B10: Plastik PP | C10: 0.1 | D10: 1000 | E10: 100 | G10: Bu Fatimah | H10: 13.95 | I10: 15150 | K10: Botol PET Kotor | L10: 4.85 | N10: 7 | O10: Besi | P10: =VLOOKUP(O10,KamiBox!$C$2:$F$58,4,0) -> 4000 | Q10: =SUMIF($B$3:$B$394,O10,$C$3:$C$394) -> 25.85 | R10: =P10*Q10 -> 103400 | S10: =S9-1.95 -> 14.1 | T10: 7 | U10: Besi | V10: =VLOOKUP(U10,KamiBox!$C$2:$F$58,4,0) -> 4000 | X10: =V10*W10 -> 0
A11: Bu Angga | B11: Kaleng | C11: 0.75 | D11: 1500 | E11: 1125 | G11: Bu Fisca | H11: 10.55 | I11: 11880 | K11: Buku, majalah, brosur, koran | L11: 98.15 | N11: 8 | O11: Boncos Kotor | P11: =VLOOKUP(O11,KamiBox!$C$2:$F$58,4,0) -> 400 | Q11: =SUMIF($B$3:$B$394,O11,$C$3:$C$394) -> 0 | R11: =P11*Q11 -> 0 | T11: 8 | U11: Boncos Kotor | V11: =VLOOKUP(U11,KamiBox!$C$2:$F$58,4,0) -> 400 | X11: =V11*W11 -> 0
A12: Bu Angga | B12: Asoy | C12: 0.1 | D12: 500 | E12: 50 | G12: Bu Hadiyana | H12: 59.7 | I12: 86060 | K12: Emberan | L12: 93.68 | N12: 9 | O12: Botol Kaca Hijau | P12: =VLOOKUP(O12,KamiBox!$C$2:$F$58,4,0) -> 100 | Q12: =SUMIF($B$3:$B$394,O12,$C$3:$C$394) -> 8 | R12: =P12*Q12 -> 800 | T12: 9 | U12: Botol Kaca Hijau | V12: =VLOOKUP(U12,KamiBox!$C$2:$F$58,4,0) -> 100 | X12: =V12*W12 -> 0
A13: Bu Angga | B13: Plastik Multilayer | C13: 0.7 | D13: 300 | E13: 210 | G13: Bu Halimah | H13: 6.8 | I13: 8945 | K13: Gabrukan | L13: 37.7 | N13: 10 | O13: Botol Kaca Bening/Putih | P13: =VLOOKUP(O13,KamiBox!$C$2:$F$58,4,0) -> 200 | Q13: =SUMIF($B$3:$B$394,O13,$C$3:$C$394) -> 23.65 | R13: =P13*Q13 -> 4730 | T13: 10 | U13: Botol Kaca Bening/Putih | V13: =VLOOKUP(U13,KamiBox!$C$2:$F$58,4,0) -> 200 | X13: =V13*W13 -> 0
A14: Bu Angga | B14: Jelantah | C14: 3.75 | D14: 5000 | E14: 18750 | G14: Bu Hartinah | H14: 12.6 | I14: 11160 | K14: Gelas PP Bersih (bening) | L14: 3.8 | N14: 11 | O14: Botol Kaca Campur | P14: =VLOOKUP(O14,KamiBox!$C$2:$F$58,4,0) -> 100 | Q14: =SUMIF($B$3:$B$394,O14,$C$3:$C$394) -> 0 | R14: =P14*Q14 -> 0 | T14: 11 | U14: Botol Kaca Campur | V14: =VLOOKUP(U14,KamiBox!$C$2:$F$58,4,0) -> 100 | X14: =V14*W14 -> 0
A15: Bu Angga | B15: Emberan | C15: 0.25 | D15: 1000 | E15: 250 | G15: Bu Ida Amanah | H15: 6.65 | I15: 7288 | K15: Gelas PP Warna | L15: 4.55 | N15: 12 | O15: Botol Kaca Coklat/Merah | P15: =VLOOKUP(O15,KamiBox!$C$2:$F$58,4,0) -> 800 | Q15: =SUMIF($B$3:$B$394,O15,$C$3:$C$394) -> 0.8 | R15: =P15*Q15 -> 640 | T15: 12 | U15: Botol Kaca Coklat/Merah | V15: =VLOOKUP(U15,KamiBox!$C$2:$F$58,4,0) -> 800 | X15: =V15*W15 -> 0
A16: Bu Angga | B16: MIX A/Boncos | C16: 1.45 | D16: 500 | E16: 725 | G16: Bu Irma | H16: 3.1 | I16: 2230 | K16: HVS/Putihan | L16: 1.8 | N16: 13 | O16: Botol PET bersih | P16: =VLOOKUP(O16,KamiBox!$C$2:$F$58,4,0) -> 5000 | Q16: 4.3 | R16: =P16*Q16 -> 21500 | S16: 57.45 | T16: 13 | U16: Botol PET bersih | V16: 5500 | W16: 62 | X16: 342000 | Y16: Pak Surat
A17: Bu Angga | B17: Kardus | C17: 0.9 | D17: 1000 | E17: 900 | G17: Bu Kamiem | H17: 7.65 | I17: 15285 | K17: Jelantah | L17: 91.45 | M17: =C383 -> 46 | N17: 14 | O17: Botol PET Kotor | P17: =VLOOKUP(O17,KamiBox!$C$2:$F$58,4,0) -> 2500 | Q17: =SUMIF($B$3:$B$394,O17,$C$3:$C$394) -> 4.85 | R17: =P17*Q17 -> 12125 | T17: 14 | U17: Botol PET Kotor | V17: =VLOOKUP(U17,KamiBox!$C$2:$F$58,4,0) -> 2500 | X17: =V17*W17 -> 0
A18: Bu Angga | B18: Botol PET bersih | C18: 0.85 | D18: 2800 | E18: 2380 | G18: Bu Lilis | H18: 44.4 | I18: 53002 | K18: Kabel Alumunium | L18: 2.25 | M18: =GETPIVOTDATA("Berat",$K$2,"Material","Jelantah")-M17 -> 45.45 | N18: 15 | O18: Botol Plastik Kemasan Campur | P18: =VLOOKUP(O18,KamiBox!$C$2:$F$58,4,0) -> 1000 | Q18: =SUMIF($B$3:$B$394,O18,$C$3:$C$394) -> 0 | R18: =P18*Q18 -> 0 | T18: 15 | U18: Botol Plastik Kemasan Campur | V18: =VLOOKUP(U18,KamiBox!$C$2:$F$58,4,0) -> 1000 | X18: =V18*W18 -> 0
A19: Bu Angga | B19: Gabrukan | C19: 1.4 | D19: 1000 | E19: 1400 | G19: Bu Mimin | H19: 5.05 | I19: 6130 | K19: Kaleng | L19: 12.9 | M19: =M18*5000 -> 227250 | N19: 16 | O19: Buku, majalah, brosur, koran | P19: =VLOOKUP(O19,KamiBox!$C$2:$F$58,4,0) -> 1000 | Q19: =SUMIF($B$3:$B$394,O19,$C$3:$C$394) -> 98.15 | R19: =P19*Q19 -> 98150 | T19: 16 | U19: Buku, majalah, brosur, koran | V19: =VLOOKUP(U19,KamiBox!$C$2:$F$58,4,0) -> 1000 | X19: =V19*W19 -> 0
A20: Bu Angga | B20: Tutup Botol | C20: 0.1 | D20: 2500 | E20: 250 | G20: Bu Minah | H20: 1.5 | I20: 1970 | K20: Kardus | L20: 168.7 | N20: 17 | O20: Emberan | P20: =VLOOKUP(O20,KamiBox!$C$2:$F$58,4,0) -> 1200 | Q20: =SUMIF($B$3:$B$394,O20,$C$3:$C$394) -> 93.68 | R20: =P20*Q20 -> 112416 | T20: 17 | U20: Emberan | V20: =VLOOKUP(U20,KamiBox!$C$2:$F$58,4,0) -> 1200 | X20: =V20*W20 -> 0
A21: Bu Ani | B21: Plastik Multilayer | C21: 0.5 | D21: 300 | E21: 150 | G21: Bu Nining | H21: 10.28 | I21: 8220 | K21: Karung | L21: 3.8 | N21: 18 | O21: Gabrukan | P21: =VLOOKUP(O21,KamiBox!$C$2:$F$58,4,0) -> 1000 | Q21: 35.7 | R21: =P21*Q21 -> 35700 | T21: 18 | U21: Gabrukan | V21: =VLOOKUP(U21,KamiBox!$C$2:$F$58,4,0) -> 1000 | X21: =V21*W21 -> 0
A22: Bu Ani | B22: Botol Kaca Bening/Putih | C22: 0.95 | D22: 150 | E22: 143 | G22: Bu Nita | H22: 2.75 | I22: 3545 | K22: Kones | L22: 1.4 | N22: 19 | O22: Galon PC | P22: =VLOOKUP(O22,KamiBox!$C$2:$F$58,4,0) -> 3000 | Q22: =SUMIF($B$3:$B$394,O22,$C$3:$C$394) -> 0 | R22: =P22*Q22 -> 0 | T22: 19 | U22: Galon PC | V22: =VLOOKUP(U22,KamiBox!$C$2:$F$58,4,0) -> 3000 | X22: =V22*W22 -> 0
A23: Bu Ani | B23: Emberan | C23: 1.05 | D23: 1000 | E23: 1050 | G23: Bu Nurhayati | H23: 2.15 | I23: 1820 | K23: Kristal Putih | L23: 1.75 | N23: 20 | O23: Gelas PP Bersih | P23: =VLOOKUP(O23,KamiBox!$C$2:$F$58,4,0) -> 4000 | Q23: 3.8 | R23: =P23*Q23 -> 15200 | T23: 20 | U23: Gelas PP Bersih | V23: =VLOOKUP(U23,KamiBox!$C$2:$F$58,4,0) -> 4000 | X23: =V23*W23 -> 0
A24: Bu Ani | B24: Botol PET bersih | C24: 1.5 | D24: 2800 | E24: 4200 | G24: Bu Nurjanah | H24: 8.65 | I24: 9815 | K24: MIX A/Boncos | L24: 45.55 | N24: 21 | O24: Gelas PP Warna | P24: =VLOOKUP(O24,KamiBox!$C$2:$F$58,4,0) -> 2000 | Q24: =SUMIF($B$3:$B$394,O24,$C$3:$C$394) -> 4.55 | R24: =P24*Q24 -> 9100 | T24: 21 | U24: Gelas PP Warna | V24: =VLOOKUP(U24,KamiBox!$C$2:$F$58,4,0) -> 2000 | X24: =V24*W24 -> 0
A25: Bu Ani | B25: MIX A/Boncos | C25: 1.5 | D25: 500 | E25: 750 | G25: Bu Nurlayli | H25: 4.2 | I25: 6708 | K25: Plastik Multilayer | L25: 87.4 | N25: 22 | O25: Handphone | P25: =VLOOKUP(O25,KamiBox!$C$2:$F$58,4,0) -> 5000 | Q25: =SUMIF($B$3:$B$394,O25,$C$3:$C$394) -> 0 | R25: =P25*Q25 -> 0 | T25: 22 | U25: Handphone | V25: =VLOOKUP(U25,KamiBox!$C$2:$F$58,4,0) -> 5000 | X25: =V25*W25 -> 0
A26: Bu Ani | B26: Kardus | C26: 3.65 | D26: 1000 | E26: 3650 | G26: Bu Purwani | H26: 7.9 | I26: 7810 | K26: Plastik PE | L26: 2.1 | N26: 23 | O26: HVS/Putihan | P26: =VLOOKUP(O26,KamiBox!$C$2:$F$58,4,0) -> 2000 | Q26: =SUMIF($B$3:$B$394,O26,$C$3:$C$394) -> 1.8 | R26: =P26*Q26 -> 3600 | T26: 23 | U26: HVS/Putihan | V26: =VLOOKUP(U26,KamiBox!$C$2:$F$58,4,0) -> 2000 | X26: =V26*W26 -> 0
A27: Bu Betria | B27: Kaleng | C27: 0.7 | D27: 1500 | E27: 1050 | G27: Bu Ratu Tuti | H27: 2.95 | I27: 4330 | K27: Plastik PP | L27: 11.05 | N27: 24 | O27: Impact | P27: =VLOOKUP(O27,KamiBox!$C$2:$F$58,4,0) -> 700 | Q27: =SUMIF($B$3:$B$394,O27,$C$3:$C$394) -> 0 | R27: =P27*Q27 -> 0 | T27: 24 | U27: Impact | V27: =VLOOKUP(U27,KamiBox!$C$2:$F$58,4,0) -> 700 | X27: =V27*W27 -> 0
A28: Bu Betria | B28: Botol Kaca Bening/Putih | C28: 1.45 | D28: 150 | E28: 218 | G28: Bu Riris | H28: 6.35 | I28: 7415 | K28: STAL/Kabin/Enamel | L28: 17.2 | N28: 25 | O28: Jelantah | P28: =VLOOKUP(O28,KamiBox!$C$2:$F$58,4,0) -> 7000 | Q28: 0 | R28: =P28*Q28 -> 0 | T28: 25 | U28: Jelantah | V28: 8800 | W28: =45.45+46 -> 91.45 | X28: =V28*W28 -> 804760 | Y28: Titipan
A29: Bu Betria | B29: Botol PET Kotor | C29: 0.25 | D29: 1600 | E29: 400 | G29: Bu Rumiyati | H29: 2.45 | I29: 2075 | K29: Styrofoam | L29: 0.25 | N29: 26 | O29: Kabel | P29: =VLOOKUP(O29,KamiBox!$C$2:$F$58,4,0) -> 1500 | Q29: 2.25 | R29: =P29*Q29 -> 3375 | T29: 26 | U29: Kabel | V29: =VLOOKUP(U29,KamiBox!$C$2:$F$58,4,0) -> 1500 | X29: =V29*W29 -> 0
A30: Bu Betria | B30: MIX A/Boncos | C30: 3.7 | D30: 500 | E30: 1850 | G30: Bu Sandra | H30: 7.75 | I30: 6565 | K30: Tutup Botol | L30: 5.55 | N30: 27 | O30: Kabin | P30: =VLOOKUP(O30,KamiBox!$C$2:$F$58,4,0) -> 2000 | Q30: 17.2 | R30: =P30*Q30 -> 34400 | T30: 27 | U30: Kabin | V30: =VLOOKUP(U30,KamiBox!$C$2:$F$58,4,0) -> 2000 | X30: =V30*W30 -> 0
A31: Bu Betria | B31: Plastik Multilayer | C31: 2.75 | D31: 300 | E31: 825 | G31: Bu Sariyanti | H31: 6.45 | I31: 6695 | K31: Tutup Galon | L31: 0.55 | N31: 28 | O31: Kaca | P31: =VLOOKUP(O31,KamiBox!$C$2:$F$58,4,0) -> 100 | Q31: =SUMIF($B$3:$B$394,O31,$C$3:$C$394) -> 0 | R31: =P31*Q31 -> 0 | T31: 28 | U31: Kaca | V31: =VLOOKUP(U31,KamiBox!$C$2:$F$58,4,0) -> 100 | X31: =V31*W31 -> 0
A32: Bu Betria | B32: Buku, majalah, brosur, koran | C32: 3.45 | D32: 800 | E32: 2760 | G32: Bu Sarmiyah | H32: 11.3 | I32: 30020 | K32: Grand Total | L32: 825.68 | N32: 29 | O32: Kaleng | P32: =VLOOKUP(O32,KamiBox!$C$2:$F$58,4,0) -> 2000 | Q32: =SUMIF($B$3:$B$394,O32,$C$3:$C$394) -> 12.9 | R32: =P32*Q32 -> 25800 | T32: 29 | U32: Kaleng | V32: =VLOOKUP(U32,KamiBox!$C$2:$F$58,4,0) -> 2000 | X32: =V32*W32 -> 0
A33: Bu Betria | B33: Kardus | C33: 5.15 | D33: 1000 | E33: 5150 | G33: Bu Satini | H33: 13.6 | I33: 13880 | N33: 30 | O33: Kantung Semen | P33: =VLOOKUP(O33,KamiBox!$C$2:$F$58,4,0) -> 1800 | Q33: =SUMIF($B$3:$B$394,O33,$C$3:$C$394) -> 0 | R33: =P33*Q33 -> 0 | T33: 30 | U33: Kantung Semen | V33: =VLOOKUP(U33,KamiBox!$C$2:$F$58,4,0) -> 1800 | X33: =V33*W33 -> 0
A34: Bu Betria | B34: Botol PET bersih | C34: 1.85 | D34: 2800 | E34: 5180 | G34: Bu Suci | H34: 8.85 | I34: 8690 | N34: 31 | O34: Kardus | P34: =VLOOKUP(O34,KamiBox!$C$2:$F$58,4,0) -> 1800 | Q34: =SUMIF($B$3:$B$394,O34,$C$3:$C$394) -> 168.7 | R34: =P34*Q34 -> 303660 | T34: 31 | U34: Kardus | V34: =VLOOKUP(U34,KamiBox!$C$2:$F$58,4,0) -> 1800 | X34: =V34*W34 -> 0
A35: Bu Betria | B35: Emberan | C35: 1.65 | D35: 1000 | E35: 1650 | G35: Bu Suhermiati | H35: 24.65 | I35: 20800 | K35: Keuntungan Penjualan | N35: 32 | O35: Kaset CD | P35: =VLOOKUP(O35,KamiBox!$C$2:$F$58,4,0) -> 4000 | Q35: =SUMIF($B$3:$B$394,O35,$C$3:$C$394) -> 0 | R35: =P35*Q35 -> 0 | T35: 32 | U35: Kaset CD | V35: =VLOOKUP(U35,KamiBox!$C$2:$F$58,4,0) -> 4000 | X35: =V35*W35 -> 0
A36: Bu Dida | B36: Besi | C36: 6.35 | D36: 2500 | E36: 15875 | G36: Bu Sukayah | H36: 8.8 | I36: 6720 | K36: =X58+R58-GETPIVOTDATA("Sum of Total",$G$2) -> 735626 | N36: 33 | O36: Komputer | P36: =VLOOKUP(O36,KamiBox!$C$2:$F$58,4,0) -> 60000 | Q36: =SUMIF($B$3:$B$394,O36,$C$3:$C$394) -> 0 | R36: =P36*Q36 -> 0 | T36: 33 | U36: Komputer | V36: =VLOOKUP(U36,KamiBox!$C$2:$F$58,4,0) -> 60000 | X36: =V36*W36 -> 0
A37: Bu Dida | B37: Botol Kaca Bening/Putih | C37: 1.95 | D37: 150 | E37: 293 | G37: Bu Suriya | H37: 7.7 | I37: 8510 | N37: 34 | O37: Kones | P37: =VLOOKUP(O37,KamiBox!$C$2:$F$58,4,0) -> 700 | Q37: =SUMIF($B$3:$B$394,O37,$C$3:$C$394) -> 1.4 | R37: =P37*Q37 -> 980 | T37: 34 | U37: Kones | V37: =VLOOKUP(U37,KamiBox!$C$2:$F$58,4,0) -> 700 | X37: =V37*W37 -> 0
A38: Bu Dida | B38: Tutup Botol | C38: 0.05 | D38: 2500 | E38: 125 | G38: Bu Wiwin | H38: 32.4 | I38: 122373 | N38: 35 | O38: Kristal Putih | P38: =VLOOKUP(O38,KamiBox!$C$2:$F$58,4,0) -> 4000 | Q38: =SUMIF($B$3:$B$394,O38,$C$3:$C$394) -> 1.75 | R38: =P38*Q38 -> 7000 | T38: 35 | U38: Kristal Putih | V38: =VLOOKUP(U38,KamiBox!$C$2:$F$58,4,0) -> 4000 | X38: =V38*W38 -> 0
A39: Bu Dida | B39: Aluminium Rongsok | C39: 0.1 | D39: 8000 | E39: 800 | G39: Bu Wuri | H39: 17.45 | I39: 17135 | N39: 36 | O39: Kulkas | P39: =VLOOKUP(O39,KamiBox!$C$2:$F$58,4,0) -> 50000 | Q39: =SUMIF($B$3:$B$394,O39,$C$3:$C$394) -> 0 | R39: =P39*Q39 -> 0 | T39: 36 | U39: Kulkas | V39: =VLOOKUP(U39,KamiBox!$C$2:$F$58,4,0) -> 50000 | X39: =V39*W39 -> 0
A40: Bu Dida | B40: Asoy | C40: 0.2 | D40: 500 | E40: 100 | G40: Bu Yanti Bela | H40: 30.85 | I40: 39145 | N40: 37 | O40: Kuningan | P40: =VLOOKUP(O40,KamiBox!$C$2:$F$58,4,0) -> 35000 | Q40: =SUMIF($B$3:$B$394,O40,$C$3:$C$394) -> 0 | R40: =P40*Q40 -> 0 | T40: 37 | U40: Kuningan | V40: =VLOOKUP(U40,KamiBox!$C$2:$F$58,4,0) -> 35000 | X40: =V40*W40 -> 0
A41: Bu Dida | B41: Plastik Multilayer | C41: 1.05 | D41: 300 | E41: 315 | G41: Bu Yanti Warmindo | H41: 1.45 | I41: 435 | N41: 38 | O41: Mesin Cuci | P41: =VLOOKUP(O41,KamiBox!$C$2:$F$58,4,0) -> 50000 | Q41: =SUMIF($B$3:$B$394,O41,$C$3:$C$394) -> 0 | R41: =P41*Q41 -> 0 | T41: 38 | U41: Mesin Cuci | V41: =VLOOKUP(U41,KamiBox!$C$2:$F$58,4,0) -> 50000 | X41: =V41*W41 -> 0
...

Sheet KamiBox
B2: No | C2: Jenis Barang | D2: Jumlah | E2: Harga Nasabah | F2: Harga Lapak | G2: Satuan | H2: Total
C3: AC | E3: 90000 | F3: 200000 | G3: set
C4: Aki | E4: =VLOOKUP(C4,'[1]Bu Erta'!$C$2:$E$66,3,0) -> 6000 | F4: 9000
C5: Akrilik Putih | E5: 1200 | F5: 4000
C6: Alumunium | E6: =VLOOKUP(C6,'[1]Bu Erta'!$C$2:$E$66,3,0) -> 8000 | F6: 10000
C7: Arsip | E7: 800 | F7: 1000
C8: Asoy | E8: 500 | F8: 1500
C9: Baja Ringan | E9: 1500 | F9: 2000
C10: Besi | E10: =VLOOKUP(C10,'[1]Bu Erta'!$C$2:$E$66,3,0) -> 2500 | F10: 4000
C11: Boncos Kotor | E11: 300 | F11: 400
C12: Botol Kaca Hijau | E12: 80 | F12: 100
C13: Botol Kaca Bening/Putih | E13: 150 | F13: 200
C14: Botol Kaca Campur | E14: 80 | F14: 100
C15: Botol Kaca Coklat/Merah | E15: 600 | F15: 800
C16: Botol PET Bersih | E16: 2800 | F16: 5000
C17: Botol PET Kotor | E17: 1600 | F17: 2500
C18: Botol Plastik Kemasan Campur | E18: 800 | F18: 1000
C19: Buku, Majalah, Brosur, Koran | E19: 800 | F19: 1000
C20: Emberan | E20: 1000 | F20: 1200
C21: Gabrukan | E21: 800 | F21: 1000
C22: Galon PC | E22: 2500 | F22: 3000
... C24: Gelas PP Warna | E24: 1600 | F24: 2000
C25: Handphone | E25: =VLOOKUP(C25,'[1]Bu Erta'!$C$2:$E$66,3,0) -> 1800 | F25: 5000 | G25: pcs
C26: HVS/Putihan | E26: 1400 | F26: 2000
C27: Impact | E27: =VLOOKUP(C27,'[1]Bu Erta'!$C$2:$E$66,3,0) -> 600 | F27: 700
C28: Jelantah | E28: 5000 | F28: 7000
C29: Kabel | E29: =VLOOKUP(C29,'[1]Bu Erta'!$C$2:$E$66,3,0) -> 1400 | F29: 1500 | G29: kg
C30: Kabin | E30: =VLOOKUP(C30,'[1]Bu Erta'!$C$2:$E$66,3,0) -> 1800 | F30: 2000
C31: Kaca | E31: 80 | F31: 100
C32: Kaleng | E32: =VLOOKUP(C32,'[1]Bu Erta'!$C$2:$E$66,3,0) -> 1500 | F32: 2000
C33: Kantung Semen | E33: 1300 | F33: 1800
C34: Kardus | E34: 1000 | F34: 1800
C35: Kaset CD | E35: 3500 | F35: 4000
C36: Kipas Angin | E36: 13000 | F36: 15000
C37: Komputer | E37: 50000 | F37: 60000 | G37: set
C38: Kones | E38: 500 | F38: 700
C39: Karung | E39: 400 | F39: 1200
C40: Kristal Putih | E40: 2700 | F40: 4000
C41: Kulkas | E41: 40000 | F41: 50000 | G41: set
C42: Kuningan | E42: =VLOOKUP(C42,'[1]Bu Erta'!$C$2:$E$66,3,0) -> 25000 | F42: 35000
...

Sheet Kas Baru
A2: Tanggal | B2: Deskripsi | C2: Masuk | D2: Keluar | E2: Total | F2: Keterangan
B3: Saldo | E3: 0
A4: 46151 | B4: Keuntungan Penjualan | C4: ='9-5-26'!G46 -> 184227.5 | E4: =IF(AND(C4="",D4=""),"",E3+C4-D4) -> 184227.5
A5: 46151 | B5: Konsumsi Anggota | D5: 40000 | E5: =IF(AND(C5="",D5=""),"",E4+C5-D5) -> 144227.5 | F5: Bubur Kacang Ijo
A6: 46151 | B6: P3K | D6: 5000 | E6: =IF(AND(C6="",D6=""),"",E5+C6-D6) -> 139227.5 | F6: Handsaplast
A7: 46151 | B7: Konsumsi Anggota | D7: =29000+40000 -> 69000 | E7: =IF(AND(C7="",D7=""),"",E6+C7-D7) -> 70227.5 | F7: Es Kelapa
A8: 46151 | B8: Konsumsi Anggota | D8: 5000 | E8: =IF(AND(C8="",D8=""),"",E7+C8-D8) -> 65227.5 | F8: Kertas Nasi
A9: 46151 | B9: Konsumsi Anggota | D9: 10000 | E9: =IF(AND(C9="",D9=""),"",E8+C9-D9) -> 55227.5 | F9: Sarung Tangan Plastik
A10: 46151 | B10: Tip Supir | D10: 20000 | E10: =IF(AND(C10="",D10=""),"",E9+C10-D10) -> 35227.5
A11: 46159 | B11: Sedot WC Bulan Mei | C11: =30000*8 -> 240000 | E11: =IF(AND(C11="",D11=""),"",E10+C11-D11) -> 275227.5
A12: 46166 | B12: Peralatan Bank Sampah | D12: 52000 | E12: =IF(AND(C12="",D12=""),"",E11+C12-D12) -> 223227.5 | F12: Cat Pot
A13: 46166 | B13: Peralatan Bank Sampah | D13: 10000 | E13: =IF(AND(C13="",D13=""),"",E12+C13-D13) -> 213227.5 | F13: Paku
A14: 46168 | B14: Deposit PKK | C14: 100000 | E14: =IF(AND(C14="",D14=""),"",E13+C14-D14) -> 313227.5
A15: 46172 | B15: Konsumsi Anggota | D15: 65000 | E15: =IF(AND(C15="",D15=""),"",E14+C15-D15) -> 248227.5 | F15: Soto
A16: 46172 | B16: Tip Supir | D16: 20000 | E16: =IF(AND(C16="",D16=""),"",E15+C16-D16) -> 228227.5
A17: 46172 | B17: Keuntungan Penjualan | C17: ='30-5-26'!I66 -> 558142.5 | E17: =IF(AND(C17="",D17=""),"",E16+C17-D17) -> 786370
A18: 46178 | B18: Peralatan Bank Sampah | D18: 313500 | E18: =IF(AND(C18="",D18=""),"",E17+C18-D18) -> 472870 | F18: Kawat
A19: 46180 | B19: Peralatan Bank Sampah | D19: 185000 | E19: =IF(AND(C19="",D19=""),"",E18+C19-D19) -> 287870 | F19: Besi ke Pak Surat
A20: 46181 | B20: Sedot WC Bulan Juni | C20: =30000*4 -> 120000 | E20: =IF(AND(C20="",D20=""),"",E19+C20-D20) -> 407870
A21: 46193 | B21: Peralatan Bank Sampah | D21: 12000 | E21: =IF(AND(C21="",D21=""),"",E20+C21-D21) -> 395870 | F21: Paku
A22: 46193 | B22: Peralatan Bank Sampah | D22: 15000 | E22: =IF(AND(C22="",D22=""),"",E21+C22-D22) -> 380870 | F22: Baja ke Pak Surat
A23: 46193 | B23: Peralatan Bank Sampah | D23: 25000 | E23: =IF(AND(C23="",D23=""),"",E22+C23-D23) -> 355870 | F23: Engsel
A24: 46193 | B24: Peralatan Bank Sampah | D24: 15000 | E24: =IF(AND(C24="",D24=""),"",E23+C24-D24) -> 340870 | F24: Kabel
A25: 46194 | B25: Keuntungan Penjualan | C25: ='21-6-26'!K36 -> -69134 | E25: =IF(AND(C25="",D25=""),"",E24+C25-D25) -> 271736
A26: 46195 | B26: Tip Supir | D26: 50000 | E26: =IF(AND(C26="",D26=""),"",E25+C26-D26) -> 221736 | F26: Tip Supir+Kopi
A27: 46200 | B27: Tabungan | D27: 200000 | E27: =IF(AND(C27="",D27=""),"",E26+C27-D27) -> 21736
A28: 46200 | B28: Peralatan Bank Sampah | D28: 25000 | E28: =IF(AND(C28="",D28=""),"",E27+C28-D28) -> -3264 | F28: Tanah
A29: 46210 | B29: Sedot WC Bulan Juli | C29: =30000*1 -> 30000 | E29: =IF(AND(C29="",D29=""),"",E28+C29-D29) -> 26736
A30: 46214 | B30: Keuntungan Penjualan | C30: ='11-07-26'!K39 -> 273768 | E30: =IF(AND(C30="",D30=""),"",E29+C30-D30) -> 300504
A31: 46214 | B31: Konsumsi Anggota | D31: =11000*9 -> 99000 | E31: =IF(AND(C31="",D31=""),"",E30+C31-D31) -> 201504 | F31: Mie ayam
A32: 46214 | B32: Konsumsi Anggota | D32: =15000*2 -> 30000 | E32: =IF(AND(C32="",D32=""),"",E31+C32-D32) -> 171504 | F32: Sop buah
A33: 46214 | B33: Konsumsi Anggota | D33: 11000 | E33: =IF(AND(C33="",D33=""),"",E32+C33-D33) -> 160504 | F33: Kelapa
A34: 46214 | B34: Peralatan Bank Sampah | D34: 15000 | E34: =IF(AND(C34="",D34=""),"",E33+C34-D34) -> 145504 | F34: Sekrup
A35: 46214 | B35: Konsumsi Anggota | D35: 14000 | E35: =IF(AND(C35="",D35=""),"",E34+C35-D35) -> 131504 | F35: Air+sendok
A36: 46214 | B36: Konsumsi Anggota | D36: 24000 | E36: =IF(AND(C36="",D36=""),"",E35+C36-D36) -> 107504 | F36: Nasi ayam
A37: 46214 | B37: Tip Supir | D37: 20000 | E37: =IF(AND(C37="",D37=""),"",E36+C37-D37) -> 87504
A38: 46221 | B38: Konsumsi Anggota | D38: 55000 | E38: =IF(AND(C38="",D38=""),"",E37+C38-D38) -> 32504 | F38: Rapat Inti
A39: 46227 | B39: Peralatan Bank Sampah | D39: 40000 | E39: =IF(AND(C39="",D39=""),"",E38+C39-D39) -> -7496 | F39: Karung
A40: 46235 | B40: Konsumsi Anggota | D40: =100000+5000 -> 105000 | E40: =IF(AND(C40="",D40=""),"",E39+C40-D40) -> -112496 | F40: Sop Bakso
A41: 46235 | B41: Konsumsi Anggota | D41: 55000 | E41: =IF(AND(C41="",D41=""),"",E40+C41-D41) -> -167496 | F41: Rujak, Es Jeruk
...

Sheet Tabungan Nasabah
E1: 2025 | O1: 2026
C2: Nama | D2: No. RT | E2: 12 Juli | F2: 26 Juli | G2: 9 Agustus | H2: 23 Agustus | I2: 7 September | J2: 21 September | K2: 19 Oktober | L2: 1 November | M2: 15 November | N2: 13 Desember | O2: 3 Januari | P2: 31 Januari | Q2: 15 Februari | R2: 5 April | S2: 26 April | T2: 8 Mei | U2: 30 Mei | V2: 21 Juni | W2: 11 Juli | X2: 1Agustus | Y2: 22 Agustus | Z2: 12 September | AC2: Total | AD2: Sisa Saldo | AE2: Tanggal Ambil | AF2: Keterangan
B3: 1 | C3: Bu Admini | D3: 1 | E3: 16430 | F3: 952.5 | G3: 7450 | H3: 9167.5 | I3: 6900 | K3: 9965 | L3: 3680 | N3: 9965 | Q3: 7245 | R3: 16827 | S3: 4205 | V3: 7200 | X3: =VLOOKUP(C3,'1-8-26'!$G$2:$I$50,3,0) -> 16663 | Y3: =VLOOKUP(C3,'22-8-26'!G2:I49,3,0) -> 7705 | Z3: =VLOOKUP(C3,'12-9-26'!$G$2:$I$55,3,0) -> 6385 | AC3: =SUM(E3:AB3) -> 130740 | AD3: =AC3 -> 130740
B4: 2 | C4: Bu Betria | D4: 1 | H4: 17495 | I4: 9545 | J4: 3800 | K4: 92900 | L4: 19550 | M4: 4660 | N4: 24155 | P4: 32960 | Q4: 14305 | S4: 23995 | T4: 8153 | U4: 24055 | V4: 19083 | W4: 16223 | X4: =VLOOKUP(C4,'1-8-26'!$G$2:$I$50,3,0) -> 33440 | Y4: =VLOOKUP(C4,'22-8-26'!G3:I50,3,0) -> 33875 | Z4: =VLOOKUP(C4,'12-9-26'!$G$2:$I$55,3,0) -> 22035 | AC4: =SUM(E4:AB4) -> 400229 | AD4: =AC4-300000 -> 100229
B5: 3 | C5: Bu Mala | D5: 1 | E5: 1010 | F5: 980 | AC5: =SUM(E5:AB5) -> 1990 | AD5: =AC5 -> 1990
B6: 4 | C6: Bu Maryani | D6: 1 | G6: 20520 | K6: 600 | O6: 150 | AC6: =SUM(E6:AB6) -> 21270 | AD6: =AC6-20000 -> 1270 | AE6: 19 Oktober | AF6: Cash
B7: 5 | C7: Bu Nita | D7: 1 | G7: 2200 | J7: 9665 | K7: 8670 | M7: 4190 | O7: 23150 | Q7: 11945 | R7: 9730 | T7: 3515 | U7: 5575 | V7: 3545 | X7: =VLOOKUP(C7,'1-8-26'!$G$2:$I$50,3,0) -> 5235 | Z7: =VLOOKUP(C7,'12-9-26'!$G$2:$I$55,3,0) -> 17960 | AC7: =SUM(E7:AB7) -> 105380 | AD7: =AC7 -> 105380
B8: 6 | C8: Bu Nurjanah | D8: 1 | G8: 24060 | H8: 3065 | I8: 940 | J8: 1860 | M8: 800 | N8: 3200 | O8: 7460 | R8: 7227.5 | V8: 9815 | W8: 6855 | Y8: =VLOOKUP(C8,'22-8-26'!G7:I54,3,0) -> 4685 | Z8: =VLOOKUP(C8,'12-9-26'!$G$2:$I$55,3,0) -> 1785 | AC8: =SUM(E8:AB8) -> 71752.5 | AD8: =AC8 -> 71752.5
B9: 7 | C9: Bu Sunarti | D9: 1 | F9: 23928.5 | H9: 2355 | L9: 24875 | M9: 8355 | O9: 9162.5 | P9: 17270 | T9: 21929 | X9: =VLOOKUP(C9,'1-8-26'!$G$2:$I$50,3,0) -> 32038 | Y9: =VLOOKUP(C9,'22-8-26'!G8:I55,3,0) -> 8195 | AC9: =SUM(E9:AB9) -> 148108 | AD9: =AC9 -> 148108
B10: 8 | C10: Bu Tetty Hamdi | D10: 1 | F10: 29705 | J10: 2115 | N10: 1800 | R10: 23335 | U10: 30042.5 | W10: 14260 | Y10: =VLOOKUP(C10,'22-8-26'!G9:I56,3,0) -> 19158 | AC10: =SUM(E10:AB10) -> 120415.5 | AD10: =AC10 -> 120415.5
B11: 9 | C11: Bu Wulandari | D11: 1 | H11: 11970 | N11: 12695 | S11: 7477.5 | AC11: =SUM(E11:AB11) -> 32142.5 | AD11: =AC11 -> 32142.5
B12: 10 | C12: Bu Yenvitriati | D12: 1 | G12: 2800 | H12: 5380 | I12: 2585 | K12: 12940 | L12: 30517.5 | N12: 4742.5 | P12: 3050 | Q12: 6905 | S12: 16330 | T12: 4575 | U12: 7610 | V12: 9640 | W12: 16705 | X12: =VLOOKUP(C12,'1-8-26'!$G$2:$I$50,3,0) -> 9280 | Y12: =VLOOKUP(C12,'22-8-26'!G11:I58,3,0) -> 5760 | Z12: =VLOOKUP(C12,'12-9-26'!$G$2:$I$55,3,0) -> 8120 | AC12: =SUM(E12:AB12) -> 146940 | AD12: =AC12 -> 146940
B13: 11 | C13: Pak Danny | D13: 1 | E13: 28292.5 | L13: 15870 | O13: 6650 | X13: =VLOOKUP(C13,'1-8-26'!$G$2:$I$50,3,0) -> 28020 | AC13: =SUM(E13:AB13) -> 78832.5 | AD13: =AC13 -> 78832.5
B14: 12 | C14: Mama Wahyu | D14: 1 | F14: 14120 | G14: 1060 | H14: 580 | I14: 1125 | K14: 4900 | M14: 3425 | N14: 2300 | O14: 840 | P14: 5145 | Q14: 1930 | R14: 10610 | S14: 5950 | V14: 5150 | X14: =VLOOKUP(C14,'1-8-26'!$G$2:$I$50,3,0) -> 6665 | Y14: =VLOOKUP(C14,'22-8-26'!G13:I60,3,0) -> 2680 | Z14: =VLOOKUP(C14,'12-9-26'!$G$2:$I$55,3,0) -> 1700 | AC14: =SUM(E14:AB14) -> 68180 | AD14: =AC14 -> 68180
B15: 13 | C15: Okta | D15: 1 | L15: 10075 | AC15: =SUM(E15:AB15) -> 10075 | AD15: =AC15 -> 10075
B16: 14 | C16: Bu Suhermiati | D16: 1 | M16: 8613 | P16: 9497.5 | S16: 4455 | V16: 20800 | W16: 5815 | Y16: =VLOOKUP(C16,'22-8-26'!G15:I62,3,0) -> 5830 | AC16: =SUM(E16:AB16) -> 55010.5 | AD16: =AC16 -> 55010.5
B17: 15 | C17: Bu Susi | D17: 1 | M17: 11245 | AC17: =SUM(E17:AB17) -> 11245 | AD17: =AC17 -> 11245
B18: 16 | C18: Bu Termin | D18: 1 | M18: 3300 | N18: 5257.5 | O18: 5727.5 | P18: 6072.5 | R18: 10130 | U18: 12257.5 | W18: 9385 | Y18: =VLOOKUP(C18,'22-8-26'!G17:I64,3,0) -> 5850 | Z18: =VLOOKUP(C18,'12-9-26'!$G$2:$I$55,3,0) -> 3475 | AC18: =SUM(E18:AB18) -> 61455 | AD18: =AC18 -> 61455
B19: 17 | C19: Akhsan | D19: 2 | E19: 1600 | F19: 215 | G19: 16650 | H19: 14000 | K19: 10582.5 | N19: 21140 | R19: 53975 | W19: 16305 | Y19: =GETPIVOTDATA("Sum of Total",'22-8-26'!$G$2,"Nasabah","AKHSAN") -> 6230 | AC19: =SUM(E19:AB19) -> 140697.5 | AD19: =AC19 -> 140697.5
B20: 18 | C20: Bela | D20: 2 | E20: 6577.5 | K20: 1575 | N20: 5845 | AC20: =SUM(E20:AB20) -> 13997.5 | AD20: =AC20 -> 13997.5
B21: 19 | C21: Bu Alim | D21: 2 | E21: 2100 | F21: 26180 | I21: 16570 | AC21: =SUM(E21:AB21) -> 44850 | AD21: =AC21-44000 -> 850 | AE21: 23 Oktober | AF21: TF
B22: 20 | C22: Bu Angga | D22: 2 | E22: 63745 | F22: 5235 | G22: 3550 | I22: 33070 | L22: 18835 | N22: 36465 | O22: 5570 | P22: 2642.5 | Q22: 33395 | R22: 13000 | S22: 4015 | U22: 8467.5 | V22: 26193 | X22: =VLOOKUP(C22,'1-8-26'!$G$2:$I$50,3,0) -> 8433 | Y22: =GETPIVOTDATA("Sum of Total",'22-8-26'!$G$2,"Nasabah","BU ANGGA") -> 20928 | Z22: =VLOOKUP(C22,'12-9-26'!$G$2:$I$55,3,0) -> 42865 | AC22: =SUM(E22:AB22) -> 326409 | AD22: =AC22-200000 -> 126409
B23: 21 | C23: Bu Fardani | D23: 2 | E23: 17560 | AC23: =SUM(E23:AB23) -> 17560 | AD23: =AC23-17560 -> 0 | AE23: 2 Agustus | AF23: Cash
B24: 22 | C24: Bu Hartinah | D24: 2 | F24: 5360 | G24: 4235 | H24: 8792.5 | I24: 8267.5 | J24: 5040 | K24: 4465 | M24: 11955 | R24: 4315 | S24: 3200 | V24: 11160 | W24: 10828 | AC24: =SUM(E24:AB24) -> 77618 | AD24: =AC24-77000 -> 618
B25: 23 | C25: Bu Lia RT 2 | D25: 2 | J25: 63000 | AC25: =SUM(E25:AB25) -> 63000 | AD25: =AC25-63000 -> 0 | AE25: 1 Oktober | AF25: TF
B26: 24 | C26: Bu Martinah | D26: 2 | E26: 2157.5 | H26: 4255 | J26: 3637.5 | K26: 15115 | AC26: =SUM(E26:AB26) -> 25165 | AD26: =AC26-25000 -> 165 | AE26: 23 Oktober | AF26: TF
B27: 25 | C27: Bu Nurhidayah | D27: 2 | E27: 3235 | AC27: =SUM(E27:AB27) -> 3235 | AD27: =AC27 -> 3235
B28: 26 | C28: Bu Ratu Tuti | D28: 2 | G28: 18635 | H28: 23787.5 | K28: 5155 | N28: 9355 | P28: 4760 | R28: 4500 | T28: 7374 | U28: 7910 | V28: 4330 | X28: =VLOOKUP(C28,'1-8-26'!$G$2:$I$50,3,0) -> 2898 | AC28: =SUM(E28:AB28) -> 88704.5 | AD28: =AC28-85000 -> 3704.5
B29: 27 | C29: Bu Rustinah | D29: 2 | J29: 2900 | K29: 13555 | AC29: =SUM(E29:AB29) -> 16455 | AD29: =AC29 -> 16455
B30: 28 | C30: Bu Widodo | D30: 2 | E30: 400 | F30: 44950 | H30: 23475 | K30: 5388.5 | N30: 70805 | P30: 13200 | Q30: 3740 | R30: 45625 | U30: 20365 | W30: 6758 | Y30: =VLOOKUP(C30,'22-8-26'!G29:I76,3,0) -> 8720 | AC30: =SUM(E30:AB30) -> 243426.5 | AD30: =AC30-140000 -> 103426.5
B31: 29 | C31: Bu Anwar | D31: 2 | H31: 3290 | J31: 2602.5 | K31: 6480 | L31: 21465 | N31: 4370 | Q31: 7552.5 | R31: 9727 | T31: 8435 | U31: 3515 | W31: 6345 | Z31: =VLOOKUP(C31,'12-9-26'!$G$2:$I$55,3,0) -> 4217.5 | AC31: =SUM(E31:AB31) -> 77999.5 | AD31: =AC31 -> 77999.5
B32: 30 | C32: Mbak Nurhayati | D32: 2 | E32: 19587.5 | F32: 36790 | H32: 32265 | J32: 15655 | K32: 7970 | M32: 11107 | N32: 27105 | O32: 19997.5 | P32: 23787.5 | Q32: 17585 | R32: 20435 | S32: 20310 | U32: 8285 | V32: 65783 | X32: =VLOOKUP(C32,'1-8-26'!$G$2:$I$50,3,0) -> 24758 | Y32: =VLOOKUP(C32,'22-8-26'!G31:I78,3,0) -> 21845 | Z32: =VLOOKUP(C32,'12-9-26'!$G$2:$I$55,3,0) -> 22350 | AC32: =SUM(E32:AB32) -> 395615.5 | AD32: =AC32-80000-30000-80000-60000-70000-50000 -> 25615.5 | AE32: 7 September | AF32: Transfer
B33: 31 | C33: Mbak Sari | D33: 2 | G33: 3665 | AC33: =SUM(E33:AB33) -> 3665 | AD33: =AC33 -> 3665
B34: 32 | C34: Mama Demas | D34: 2 | K34: 5460 | L34: 5332.5 | O34: 4970 | AC34: =SUM(E34:AB34) -> 15762.5 | AD34: =AC34 -> 15762.5
B35: 33 | C35: Pak Suprayitno | D35: 2 | I35: 26110 | J35: 3390 | N35: 24805 | O35: 8705 | R35: 3040 | S35: 1750 | T35: 2800 | U35: 7520 | X35: =VLOOKUP(C35,'1-8-26'!$G$2:$I$50,3,0) -> 2625 | Z35: =VLOOKUP(C35,'12-9-26'!$G$2:$I$55,3,0) -> 1970 | AC35: =SUM(E35:AB35) -> 82715 | AD35: =AC35-29000 -> 53715
B36: 34 | C36: Novem | D36: 2 | E36: 2040 | H36: 1875 | L36: 16762.5 | N36: 3410 | O36: 4135 | U36: 17615 | Z36: =VLOOKUP(C36,'12-9-26'!$G$2:$I$55,3,0) -> 11935 | AC36: =SUM(E36:AB36) -> 57772.5 | AD36: =AC36 -> 57772.5
B37: 35 | C37: Sela | D37: 2 | E37: 40955 | J37: 2300 | K37: 4727.5 | M37: 5365 | P37: 9472.5 | AC37: =SUM(E37:AB37) -> 62820 | AD37: =AC37 -> 62820
B38: 36 | C38: Vena | D38: 2 | J38: 18522.5 | K38: 2600 | T38: 3250 | V38: 3090 | W38: 3465 | Y38: =VLOOKUP(C38,'22-8-26'!G37:I84,3,0) -> 6628 | AC38: =SUM(E38:AB38) -> 37555.5 | AD38: =AC38 -> 37555.5
B39: 37 | C39: Pak Wawan | D39: 2 | E39: 4600 | F39: 20097.5 | G39: 2800 | H39: 5110 | I39: 6300 | J39: 12010 | K39: 11797.5 | L39: 20250 | N39: 19200 | O39: 20260 | P39: 7760 | Q39: 7500 | R39: 43570 | T39: 16100 | U39: 23055 | V39: 10960 | W39: 12580 | X39: =VLOOKUP(C39,'1-8-26'!$G$2:$I$50,3,0) -> 10270 | Z39: =VLOOKUP(C39,'12-9-26'!$G$2:$I$55,3,0) -> 16170 | AC39: =SUM(E39:AB39) -> 270390 | AD39: =AC39-100000 -> 170390
B40: 38 | C40: Bu Indrayani | D40: 3 | G40: 8395 | K40: 3660 | AC40: =SUM(E40:AB40) -> 12055 | AD40: =AC40 -> 12055
...

Sheet 12-9-26
A2: Nasabah | B2: Material | C2: Berat | D2: Harga | E2: Total | G2: Row Labels | H2: Sum of Berat | I2: Sum of Total | K2: Row Labels | L2: Sum of Berat | N2: Timbangan Kami Box | Q2: Sabtu, 12 September 2026 | T2: Timbangan Non Kami Box | W2: Sabtu, 12 September 2026
A3: VINA RT 3 | B3: MIX A/Boncos | C3: 0.55 | D3: 500 | E3: =C3*D3 -> 275 | G3: Bank Sampah Dasana UB | H3: 38.35 | I3: 13835 | K3: Aluminium Rongsok | L3: 1 | N3: No | O3: Jenis Sampah | P3: Harga | Q3: Berat | R3: Total Harga | T3: No | U3: Jenis Sampah | V3: Harga | W3: Berat | X3: Total Harga
A4: VINA RT 3 | B4: Tutup Botol | C4: 0.2 | D4: 2500 | E4: =C4*D4 -> 500 | G4: BU ADMINI | H4: 3.45 | I4: 6385 | K4: Asoy | L4: 29.85 | N4: 1 | O4: AC | P4: =VLOOKUP(O4,KamiBox!$C$2:$F$58,4,0) -> 200000 | Q4: =SUMIF($B$3:$B$357,O4,$C$3:$C$357) -> 0 | R4: =P4*Q4 -> 0 | T4: 1 | U4: Asoy | V4: =VLOOKUP(U4,KamiBox!$C$2:$F$58,4,0) -> 1500 | W4: =SUMIF($B$3:$B$357,U4,$C$3:$C$357) -> 29.85 | X4: =V4*W4 -> 44775
A5: VINA RT 3 | B5: Botol PET bersih | C5: 0.45 | D5: 2800 | E5: =C5*D5 -> 1260 | G5: BU ANGGA | H5: 19.25 | I5: 42865 | K5: Besi | L5: 21.5 | N5: 2 | O5: Aki | P5: =VLOOKUP(O5,KamiBox!$C$2:$F$58,4,0) -> 9000 | Q5: =SUMIF($B$3:$B$357,O5,$C$3:$C$357) -> 0 | R5: =P5*Q5 -> 0 | T5: 2 | U5: Plastik PE | V5: 1700 | W5: =SUMIF($B$3:$B$357,U5,$C$3:$C$357) -> 0.55 | X5: =V5*W5 -> 935
A6: VINA RT 3 | B6: Botol Kaca Bening/Putih | C6: 0.55 | D6: 150 | E6: =C6*D6 -> 82.5 | G6: BU ANI | H6: 10.65 | I6: 12400 | K6: Botol Kaca Bening/Putih | L6: 19.4 | N6: 3 | O6: Akrilik Putih | P6: =VLOOKUP(O6,KamiBox!$C$2:$F$58,4,0) -> 4000 | Q6: =SUMIF($B$3:$B$357,O6,$C$3:$C$357) -> 0 | R6: =P6*Q6 -> 0 | T6: 3 | U6: Plastik PP | V6: 1700 | W6: =SUMIF($B$3:$B$357,U6,$C$3:$C$357) -> 2.5 | X6: =V6*W6 -> 4250
A7: VINA RT 3 | B7: Kaleng | C7: 1.05 | D7: 1500 | E7: =C7*D7 -> 1575 | G7: BU ANWAR | H7: 6.55 | I7: 4217.5 | K7: Botol PET bersih | L7: 67.6 | N7: 4 | O7: Alumunium | P7: =VLOOKUP(O7,KamiBox!$C$2:$F$58,4,0) -> 10000 | Q7: 0 | R7: =P7*Q7 -> 0 | S7: 1 | U7: TOTAL | W7: =SUM(W4:W6) -> 32.9 | X7: =SUM(X4:X6) -> 49960
A8: VINA RT 3 | B8: Emberan | C8: 0.7 | D8: 1000 | E8: =C8*D8 -> 700 | G8: BU BETRIA | H8: 16.2 | I8: 22035 | K8: Botol PET Kotor | L8: 4.1 | N8: 5 | O8: Arsip | P8: =VLOOKUP(O8,KamiBox!$C$2:$F$58,4,0) -> 1000 | Q8: =SUMIF($B$3:$B$357,O8,$C$3:$C$357) -> 0 | R8: =P8*Q8 -> 0
A9: VINA RT 3 | B9: Plastik Multilayer | C9: 0.55 | D9: 300 | E9: =C9*D9 -> 165 | G9: BU DIDA | H9: 4 | I9: 7305 | K9: Buku, majalah, brosur, koran | L9: 18.65 | N9: 6 | O9: Asoy | R9: =P9*Q9 -> 0
A10: VINA RT 3 | B10: Asoy | C10: 0.15 | D10: 500 | E10: =C10*D10 -> 75 | G10: BU ECIN DWI | H10: 17.1 | I10: 21945 | K10: Emberan | L10: 68.1 | N10: 7 | O10: Besi | P10: =VLOOKUP(O10,KamiBox!$C$2:$F$58,4,0) -> 4000 | Q10: =SUMIF($B$3:$B$357,O10,$C$3:$C$357) -> 21.5 | R10: =P10*Q10 -> 86000
A11: MAMA ADAM | B11: Gelas PP Warna | C11: 2.25 | D11: 1600 | E11: =C11*D11 -> 3600 | G11: BU FATIMAH | H11: 2.2 | I11: 3010 | K11: Gabrukan | L11: 21.35 | N11: 8 | O11: Boncos Kotor | P11: =VLOOKUP(O11,KamiBox!$C$2:$F$58,4,0) -> 400 | Q11: =SUMIF($B$3:$B$357,O11,$C$3:$C$357) -> 0 | R11: =P11*Q11 -> 0
A12: MAMA ADAM | B12: Botol PET Kotor | C12: 1.15 | D12: 1600 | E12: =C12*D12 -> 1840 | G12: BU FEBRI | H12: 2.25 | I12: 1175 | K12: Gelas PP Bersih (bening) | L12: 2.8 | N12: 9 | O12: Botol Kaca Hijau | P12: =VLOOKUP(O12,KamiBox!$C$2:$F$58,4,0) -> 100 | Q12: =SUMIF($B$3:$B$357,O12,$C$3:$C$357) -> 0 | R12: =P12*Q12 -> 0
A13: MAMA ADAM | B13: Plastik Multilayer | C13: 1.8 | D13: 300 | E13: =C13*D13 -> 540 | G13: BU HADIYANA | H13: 36.45 | I13: 64430 | K13: Gelas PP Warna | L13: 3.15 | N13: 10 | O13: Botol Kaca Bening/Putih | P13: =VLOOKUP(O13,KamiBox!$C$2:$F$58,4,0) -> 200 | Q13: =SUMIF($B$3:$B$357,O13,$C$3:$C$357) -> 19.4 | R13: =P13*Q13 -> 3880
A14: MAMA WAHYU | B14: Karung | C14: 0.8 | D14: 400 | E14: =C14*D14 -> 320 | G14: BU IRMA | H14: 4.65 | I14: 5320 | K14: HVS/Putihan | L14: 1.9 | N14: 11 | O14: Botol Kaca Campur | P14: =VLOOKUP(O14,KamiBox!$C$2:$F$58,4,0) -> 100 | Q14: =SUMIF($B$3:$B$357,O14,$C$3:$C$357) -> 0 | R14: =P14*Q14 -> 0
A15: MAMA WAHYU | B15: Gabrukan | C15: 0.4 | D15: 1000 | E15: =C15*D15 -> 400 | G15: BU KAMIEM | H15: 11.95 | I15: 15905 | K15: Jelantah | L15: 45.7 | N15: 12 | O15: Botol Kaca Coklat/Merah | P15: =VLOOKUP(O15,KamiBox!$C$2:$F$58,4,0) -> 800 | Q15: =SUMIF($B$3:$B$357,O15,$C$3:$C$357) -> 0 | R15: =P15*Q15 -> 0
A16: MAMA WAHYU | B16: Asoy | C16: 0.5 | D16: 500 | E16: =C16*D16 -> 250 | G16: BU LILIS | H16: 28.6 | I16: 57845 | K16: Kabel Alumunium | L16: 2.7 | N16: 13 | O16: Botol PET bersih | P16: =VLOOKUP(O16,KamiBox!$C$2:$F$58,4,0) -> 5000 | Q16: =SUMIF($B$3:$B$357,O16,$C$3:$C$357)+4 -> 71.6 | R16: =P16*Q16 -> 358000
A17: MAMA WAHYU | B17: Plastik Multilayer | C17: 1.6 | D17: 300 | E17: =C17*D17 -> 480 | G17: BU MIMIN | H17: 2.9 | I17: 3325 | K17: Kaleng | L17: 19.6 | N17: 14 | O17: Botol PET Kotor | P17: =VLOOKUP(O17,KamiBox!$C$2:$F$58,4,0) -> 2500 | Q17: =SUMIF($B$3:$B$357,O17,$C$3:$C$357) -> 4.1 | R17: =P17*Q17 -> 10250
A18: MAMA WAHYU | B18: MIX A/Boncos | C18: 0.5 | D18: 500 | E18: =C18*D18 -> 250 | G18: BU MINAH | H18: 1.7 | I18: 3290 | K18: Kardus | L18: 103.15 | N18: 15 | O18: Botol Plastik Kemasan Campur | P18: =VLOOKUP(O18,KamiBox!$C$2:$F$58,4,0) -> 1000 | Q18: =SUMIF($B$3:$B$357,O18,$C$3:$C$357) -> 0 | R18: =P18*Q18 -> 0
A19: BU NURLAYLI | B19: Botol PET bersih | C19: 0.45 | D19: 2800 | E19: =C19*D19 -> 1260 | G19: BU NENI | H19: 9.3 | I19: 9020 | K19: Karung | L19: 1.05 | N19: 16 | O19: Buku, majalah, brosur, koran | P19: =VLOOKUP(O19,KamiBox!$C$2:$F$58,4,0) -> 1000 | Q19: =SUMIF($B$3:$B$357,O19,$C$3:$C$357) -> 18.65 | R19: =P19*Q19 -> 18650
A20: BU NURLAYLI | B20: Emberan | C20: 1.2 | D20: 1000 | E20: =C20*D20 -> 1200 | G20: BU NITA | H20: 10.95 | I20: 17960 | K20: Kristal Putih | L20: 0.7 | N20: 17 | O20: Emberan | P20: =VLOOKUP(O20,KamiBox!$C$2:$F$58,4,0) -> 1200 | Q20: =SUMIF($B$3:$B$357,O20,$C$3:$C$357) -> 68.1 | R20: =P20*Q20 -> 81720
A21: BU NURLAYLI | B21: Plastik Multilayer | C21: 0.5 | D21: 300 | E21: =C21*D21 -> 150 | G21: BU NURJANAH | H21: 2.05 | I21: 1785 | K21: MIX A/Boncos | L21: 39.4 | N21: 18 | O21: Gabrukan | P21: =VLOOKUP(O21,KamiBox!$C$2:$F$58,4,0) -> 1000 | Q21: =SUMIF($B$3:$B$357,O21,$C$3:$C$357) -> 21.35 | R21: =P21*Q21 -> 21350
A22: BU SITI ALFIYAH | B22: STAL/Kabin/Enamel | C22: 0.8 | D22: 1800 | E22: =C22*D22 -> 1440 | G22: BU NURLAYLI | H22: 2.15 | I22: 2610 | K22: Plastik Multilayer | L22: 79.65 | N22: 19 | O22: Galon PC | P22: =VLOOKUP(O22,KamiBox!$C$2:$F$58,4,0) -> 3000 | Q22: =SUMIF($B$3:$B$357,O22,$C$3:$C$357) -> 0 | R22: =P22*Q22 -> 0
A23: BU SITI ALFIYAH | B23: Emberan | C23: 1.7 | D23: 1000 | E23: =C23*D23 -> 1700 | G23: BU PURWANI | H23: 15.9 | I23: 45355 | K23: Plastik PE | L23: 0.55 | N23: 20 | O23: Gelas PP Bersih | P23: =VLOOKUP(O23,KamiBox!$C$2:$F$58,4,0) -> 4000 | Q23: =GETPIVOTDATA("Berat",$K$2,"Material","Gelas PP Bersih (bening)")+1 -> 3.8 | R23: =P23*Q23 -> 15200
A24: BU SITI ALFIYAH | B24: Asoy | C24: 0.85 | D24: 500 | E24: =C24*D24 -> 425 | G24: BU RINA | H24: 10.5 | I24: 17720 | K24: Plastik PP | L24: 2.5 | N24: 21 | O24: Gelas PP Warna | P24: =VLOOKUP(O24,KamiBox!$C$2:$F$58,4,0) -> 2000 | Q24: =SUMIF($B$3:$B$357,O24,$C$3:$C$357) -> 3.15 | R24: =P24*Q24 -> 6300
A25: BU SITI ALFIYAH | B25: MIX A/Boncos | C25: 2.35 | D25: 500 | E25: =C25*D25 -> 1175 | G25: BU RIRIS | H25: 14.8 | I25: 44980 | K25: STAL/Kabin/Enamel | L25: 5.6 | N25: 22 | O25: Handphone | P25: =VLOOKUP(O25,KamiBox!$C$2:$F$58,4,0) -> 5000 | Q25: =SUMIF($B$3:$B$357,O25,$C$3:$C$357) -> 0 | R25: =P25*Q25 -> 0
A26: BU SITI ALFIYAH | B26: Plastik Multilayer | C26: 1.05 | D26: 300 | E26: =C26*D26 -> 315 | G26: BU RUMIYATI | H26: 11.4 | I26: 15720 | K26: Styrofoam | L26: 2.25 | N26: 23 | O26: HVS/Putihan | P26: =VLOOKUP(O26,KamiBox!$C$2:$F$58,4,0) -> 2000 | Q26: =SUMIF($B$3:$B$357,O26,$C$3:$C$357) -> 1.9 | R26: =P26*Q26 -> 3800
A27: BU SITI ALFIYAH | B27: Botol PET bersih | C27: 0.9 | D27: 2800 | E27: =C27*D27 -> 2520 | G27: BU SANDRA | H27: 9.05 | I27: 8790 | K27: Tutup Botol | L27: 4.8 | N27: 24 | O27: Impact | P27: =VLOOKUP(O27,KamiBox!$C$2:$F$58,4,0) -> 700 | Q27: =SUMIF($B$3:$B$357,O27,$C$3:$C$357) -> 0 | R27: =P27*Q27 -> 0
A28: SELLY | B28: Gabrukan | C28: =0.85+1.15+1.05 -> 3.05 | D28: 1000 | E28: =C28*D28 -> 3050 | G28: BU SARIYANTI | H28: 3.2 | I28: 5025 | K28: Tutup Galon | L28: 1.5 | N28: 25 | O28: Jelantah | P28: 7000 | Q28: =SUMIF($B$3:$B$357,O28,$C$3:$C$357)+3.5 -> 49.2 | R28: =P28*Q28 -> 344400 | S28: 3.5
A29: SELLY | B29: Besi | C29: 1.7 | D29: 2500 | E29: =C29*D29 -> 4250 | G29: BU SARTI | H29: 5.2 | I29: 11560 | K29: Grand Total | L29: 568.55 | N29: 26 | O29: Kabel | P29: =VLOOKUP(O29,KamiBox!$C$2:$F$58,4,0) -> 1500 | Q29: =GETPIVOTDATA("Berat",$K$2,"Material","Kabel Alumunium") -> 2.7 | R29: =P29*Q29 -> 4050
A30: SELLY | B30: Botol Kaca Bening/Putih | C30: 0.4 | D30: 150 | E30: =C30*D30 -> 60 | G30: BU SATINI | H30: 11.15 | I30: 17115 | N30: 27 | O30: Kabin | P30: =VLOOKUP(O30,KamiBox!$C$2:$F$58,4,0) -> 2000 | Q30: =GETPIVOTDATA("Berat",$K$2,"Material","STAL/Kabin/Enamel") -> 5.6 | R30: =P30*Q30 -> 11200
A31: SELLY | B31: Botol PET bersih | C31: 1 | D31: 2800 | E31: =C31*D31 -> 2800 | G31: BU SITI ALFIYAH | H31: 7.65 | I31: 7575 | N31: 28 | O31: Kaca | P31: =VLOOKUP(O31,KamiBox!$C$2:$F$58,4,0) -> 100 | Q31: =SUMIF($B$3:$B$357,O31,$C$3:$C$357) -> 0 | R31: =P31*Q31 -> 0
A32: SELLY | B32: Emberan | C32: 1.4 | D32: 1000 | E32: =C32*D32 -> 1400 | G32: BU SRI RETNO | H32: 16.5 | I32: 35692.5 | K32: Keuntungan Penjualan | N32: 29 | O32: Kaleng | P32: =VLOOKUP(O32,KamiBox!$C$2:$F$58,4,0) -> 2000 | Q32: =SUMIF($B$3:$B$357,O32,$C$3:$C$357) -> 19.6 | R32: =P32*Q32 -> 39200
A33: SELLY | B33: MIX A/Boncos | C33: 2.2 | D33: 500 | E33: =C33*D33 -> 1100 | G33: BU SUCI | H33: 14.15 | I33: 29660 | K33: =(R60+X7)-GETPIVOTDATA("Sum of Total",$G$2) -> 504907.5 | N33: 30 | O33: Kantung Semen | P33: =VLOOKUP(O33,KamiBox!$C$2:$F$58,4,0) -> 1800 | Q33: =SUMIF($B$3:$B$357,O33,$C$3:$C$357) -> 0 | R33: =P33*Q33 -> 0
A34: SELLY | B34: Asoy | C34: 0.55 | D34: 500 | E34: =C34*D34 -> 275 | G34: BU SUKAYAH | H34: 4.65 | I34: 3535 | N34: 31 | O34: Kardus | P34: =VLOOKUP(O34,KamiBox!$C$2:$F$58,4,0) -> 1800 | Q34: =SUMIF($B$3:$B$357,O34,$C$3:$C$357)+5 -> 108.15 | R34: =P34*Q34 -> 194670
A35: SELLY | B35: Kardus | C35: 0.9 | D35: 1000 | E35: =C35*D35 -> 900 | G35: BU SURIYA | H35: 2.9 | I35: 3790 | N35: 32 | O35: Kaset CD | P35: =VLOOKUP(O35,KamiBox!$C$2:$F$58,4,0) -> 4000 | Q35: =SUMIF($B$3:$B$357,O35,$C$3:$C$357) -> 0 | R35: =P35*Q35 -> 0
A36: SELLY | B36: Plastik Multilayer | C36: 0.8 | D36: 300 | E36: =C36*D36 -> 240 | G36: BU TERMIN | H36: 2.75 | I36: 3475 | N36: 33 | O36: Kipas Angin | P36: 20000 | Q36: =SUMIF($B$3:$B$357,O36,$C$3:$C$357) -> 0 | R36: =P36*Q36 -> 0
A37: SELLY | B37: Aluminium Rongsok | C37: 0.05 | D37: 8000 | E37: =C37*D37 -> 400 | G37: BU TUNUT | H37: 3.6 | I37: 2025 | N37: 34 | O37: Komputer | P37: =VLOOKUP(O37,KamiBox!$C$2:$F$58,4,0) -> 60000 | Q37: =SUMIF($B$3:$B$357,O37,$C$3:$C$357) -> 0 | R37: =P37*Q37 -> 0
A38: SELLY | B38: Kaleng | C38: 0.25 | D38: 1500 | E38: =C38*D38 -> 375 | G38: BU WIWIN | H38: 13.95 | I38: 19667.5 | N38: 35 | O38: Kones | P38: =VLOOKUP(O38,KamiBox!$C$2:$F$58,4,0) -> 700 | Q38: =SUMIF($B$3:$B$357,O38,$C$3:$C$357) -> 0 | R38: =P38*Q38 -> 0
A39: BU NITA | B39: Jelantah | C39: 1.3 | D39: 5000 | E39: =C39*D39 -> 6500 | G39: BU WURI | H39: 21.15 | I39: 19180 | N39: 36 | O39: Kristal Putih | P39: =VLOOKUP(O39,KamiBox!$C$2:$F$58,4,0) -> 4000 | Q39: =SUMIF($B$3:$B$357,O39,$C$3:$C$357)+0.1 -> 0.8 | R39: =P39*Q39 -> 3200
A40: BU NITA | B40: Kaleng | C40: 0.15 | D40: 1500 | E40: =C40*D40 -> 225 | G40: BU YANTI BELA | H40: 23.7 | I40: 29925 | N40: 37 | O40: Kulkas | P40: =VLOOKUP(O40,KamiBox!$C$2:$F$58,4,0) -> 50000 | Q40: =SUMIF($B$3:$B$357,O40,$C$3:$C$357) -> 0 | R40: =P40*Q40 -> 0
A41: BU NITA | B41: Botol PET bersih | C41: 1.45 | D41: 2800 | E41: =C41*D41 -> 4060 | G41: BU YENVITRIATI | H41: 6.35 | I41: 8120 | N41: 38 | O41: Kuningan | P41: =VLOOKUP(O41,KamiBox!$C$2:$F$58,4,0) -> 35000 | Q41: =SUMIF($B$3:$B$357,O41,$C$3:$C$357) -> 0 | R41: =P41*Q41 -> 0
...

Sheet 22-8-26
A2: Nasabah | B2: Material | C2: Berat | D2: Harga | E2: Total | G2: Row Labels | H2: Sum of Berat | I2: Sum of Total | K2: Row Labels | L2: Sum of Berat | O2: Timbangan Kami Box | R2: Sabtu, 22 Agustus 2026 | U2: Timbangan Non Kami Box | X2: Sabtu, 22 Agustus 2026
A3: PAK GIRI | B3: Asoy | C3: 1 | D3: 500 | E3: 500 | G3: AKHSAN | H3: 5.2 | I3: 6230 | K3: Aluminium Rongsok | L3: 0.2 | O3: No | P3: Jenis Sampah | Q3: Harga | R3: Berat | S3: Total Harga | U3: No | V3: Jenis Sampah | W3: Harga | X3: Berat | Y3: Total Harga
A4: PAK GIRI | B4: Plastik Multilayer | C4: 0.65 | D4: 300 | E4: 195 | G4: BU ADMINI | H4: 7.15 | I4: 7705 | K4: Asoy | L4: 18.5 | O4: 1 | P4: AC | Q4: =VLOOKUP(P4,KamiBox!$C$2:$F$58,4,0) -> 200000 | R4: =SUMIF($B$3:$B$332,P4,$C$3:$C$332) -> 0 | S4: =Q4*R4 -> 0 | U4: 1 | V4: Asoy | W4: =VLOOKUP(V4,KamiBox!$C$2:$F$58,4,0) -> 1500 | X4: =SUMIF($B$3:$B$346,V4,$C$3:$C$346) -> 18.5 | Y4: =W4*X4 -> 27750
A5: PAK GIRI | B5: Botol Kaca Bening/Putih | C5: 2.95 | D5: 150 | E5: 443 | G5: BU ANGGA | H5: 10.05 | I5: 20928 | K5: Besi | L5: 17.25 | O5: 2 | P5: Aki | Q5: =VLOOKUP(P5,KamiBox!$C$2:$F$58,4,0) -> 9000 | R5: =SUMIF($B$3:$B$332,P5,$C$3:$C$332) -> 0 | S5: =Q5*R5 -> 0 | U5: 2 | V5: Plastik PE | W5: 1700 | X5: =SUMIF($B$3:$B$346,V5,$C$3:$C$346) -> 0.5 | Y5: =W5*X5 -> 850
A6: PAK GIRI | B6: Gabrukan | C6: 2.45 | D6: 1000 | E6: 2450 | G6: BU ANI | H6: 7.4 | I6: 8985 | K6: Botol Kaca Bening/Putih | L6: 29.3 | O6: 3 | P6: Akrilik Putih | Q6: =VLOOKUP(P6,KamiBox!$C$2:$F$58,4,0) -> 4000 | R6: =SUMIF($B$3:$B$332,P6,$C$3:$C$332) -> 0 | S6: =Q6*R6 -> 0 | U6: 3 | V6: Plastik PP | W6: 1700 | X6: =SUMIF($B$3:$B$346,V6,$C$3:$C$346) -> 0.35 | Y6: =W6*X6 -> 595
A7: VENA | B7: Botol PET bersih | C7: 1 | D7: 2800 | E7: 2800 | G7: BU BETRIA | H7: 37.15 | I7: 33875 | K7: Botol PET bersih | L7: 52.45 | O7: 4 | P7: Alumunium | Q7: =VLOOKUP(P7,KamiBox!$C$2:$F$58,4,0) -> 10000 | R7: 0.2 | S7: =Q7*R7 -> 2000 | V7: TOTAL | X7: =SUM(X4:X6) -> 19.35 | Y7: =SUM(Y4:Y6) -> 29195
A8: VENA | B8: Asoy | C8: 0.25 | D8: 500 | E8: 125 | G8: BU DIDA | H8: 35 | I8: 41830 | K8: Botol PET Kotor | L8: 6.7 | O8: 5 | P8: Arsip | Q8: =VLOOKUP(P8,KamiBox!$C$2:$F$58,4,0) -> 1000 | R8: =SUMIF($B$3:$B$332,P8,$C$3:$C$332) -> 0 | S8: =Q8*R8 -> 0 | Y8: ='1-8-26'!X7 -> 23945
A9: VENA | B9: Kardus | C9: 0.65 | D9: 1000 | E9: 650 | G9: BU ECIN DWI | H9: 18.85 | I9: 34258 | K9: Buku, majalah, brosur, koran | L9: 12.5 | O9: 6 | P9: Asoy | S9: =Q9*R9 -> 0
A10: VENA | B10: Emberan | C10: 1.3 | D10: 1000 | E10: 1300 | G10: BU HADIYANA | H10: 41.8 | I10: 66643 | K10: Emberan | L10: 69.5 | O10: 7 | P10: Besi | Q10: =VLOOKUP(P10,KamiBox!$C$2:$F$58,4,0) -> 4000 | R10: =SUMIF($B$3:$B$332,P10,$C$3:$C$332) -> 17.25 | S10: =Q10*R10 -> 69000
