Workbook

Sheet Cashflow
A2: Tanggal | B2: Deskripsi | C2: Masuk | D2: Keluar | E2: Total | F2: Keterangan
B3: Saldo awal | E3: 0
A4: 45864 | B4: Setor sampah | C4: ='12-7-2025'!V67 -> 748802.5 | E4: =IF(AND(C4="",D4=""),"",E3+C4-D4) -> 748802.5 | F4: Jual ke Bu Erta 12 Juli
A5: 45864 | B5: Tabungan nasabah | D5: =GETPIVOTDATA("Sum of Total Harga",'12-7-2025'!$J$2) -> 633711 | E5: =IF(AND(C5="",D5=""),"",E4+C5-D5) -> 115091.5 | F5: Tabungan 12 Juli
A6: 45864 | B6: Konsumsi anggota | D6: 74000 | E6: =IF(AND(C6="",D6=""),"",E5+C6-D6) -> 41091.5 | F6: Soto Pak Beny (Qris)
A7: 45864 | B7: Setor sampah | C7: ='26-7-2025'!AB68 -> 60000 | E7: =IF(AND(C7="",D7=""),"",E6+C7-D7) -> 101091.5 | F7: Jual ke Pak Surat 26 Juli
A8: 45864 | B8: Fotocopy | D8: 10000 | E8: =IF(AND(C8="",D8=""),"",E7+C8-D8) -> 91091.5 | F8: FC daftar hadir (Cash)
A9: 45864 | B9: ATK | D9: 58082 | E9: =IF(AND(C9="",D9=""),"",E8+C9-D9) -> 33009.5
A10: 45878 | B10: Setor sampah | C10: ='26-7-2025'!V68 -> 663626.5 | E10: =IF(AND(C10="",D10=""),"",E9+C10-D10) -> 696636 | F10: Jual ke Bu Erta 26 Juli
A11: 45878 | B11: Tabungan nasabah | D11: =GETPIVOTDATA("Sum of Total Harga",'26-7-2025'!$J$2) -> 620721 | E11: =IF(AND(C11="",D11=""),"",E10+C11-D11) -> 75915 | F11: Tabungan 26 Juli
A12: 45878 | B12: Konsumsi anggota | D12: 92000 | E12: =IF(AND(C12="",D12=""),"",E11+C12-D12) -> -16085 | F12: Mie Gacoan
A13: 45878 | B13: Setor sampah | C13: ='9-8-2025'!AB68 -> 282000 | E13: =IF(AND(C13="",D13=""),"",E12+C13-D13) -> 265915 | F13: Jual ke Pak Surat 9 Agustus
A14: 45878 | B14: Hasil Tabungan | C14: 28245 | E14: =IF(AND(C14="",D14=""),"",E13+C14-D14) -> 294160
A15: 45892 | B15: Setor sampah | C15: ='9-8-2025'!V68 -> 622167.5 | E15: =IF(AND(C15="",D15=""),"",E14+C15-D15) -> 916327.5 | F15: Jual ke Bu Erta 9 Agustus
A16: 45892 | B16: Tabungan nasabah | D16: =GETPIVOTDATA("Sum of Total Harga",'9-8-2025'!$J$2) -> 644175 | E16: =IF(AND(C16="",D16=""),"",E15+C16-D16) -> 272152.5 | F16: Tabungan 9 Agustus
A17: 45892 | B17: Konsumsi anggota | D17: 43000 | E17: =IF(AND(C17="",D17=""),"",E16+C17-D17) -> 229152.5 | F17: Gorengan
A18: 45892 | B18: Konsumsi anggota | D18: 4000 | E18: =IF(AND(C18="",D18=""),"",E17+C18-D18) -> 225152.5 | F18: Minum
A19: 45892 | B19: Setor sampah | C19: ='23-8-2025'!X68 -> 193700 | E19: =IF(AND(C19="",D19=""),"",E18+C19-D19) -> 418852.5 | F19: Jual ke Pak Surat 23 Agustus
A20: 45892 | B20: Setor sampah | C20: ='23-8-2025'!R68 -> 550750 | E20: =IF(AND(C20="",D20=""),"",E19+C20-D20) -> 969602.5 | F20: Jual ke Bu Erta 23 Agustus
A21: 45892 | B21: Tabungan nasabah | D21: =GETPIVOTDATA("Sum of Total Harga",'23-8-2025'!$J$2) -> 615287.5 | E21: =IF(AND(C21="",D21=""),"",E20+C21-D21) -> 354315 | F21: Tabungan 23 Agustus
A22: 45892 | B22: Hasil Tabungan | C22: 13000 | E22: =IF(AND(C22="",D22=""),"",E21+C22-D22) -> 367315
A23: 45893 | B23: Admin Pinjaman PKK | C23: 100000 | E23: =IF(AND(C23="",D23=""),"",E22+C23-D23) -> 467315 | F23: Dipinjamkan ke PKK
A24: 45907 | B24: Konsumsi anggota | D24: =35000 -> 35000 | E24: =IF(AND(C24="",D24=""),"",E23+C24-D24) -> 432315 | F24: Rujak
A25: 45907 | B25: Banner | D25: 54000 | E25: =IF(AND(C25="",D25=""),"",E24+C25-D25) -> 378315 | F25: Cetak Banner Bank Sampah
A26: 45907 | B26: Setor sampah | C26: ='7-9-2025'!R68 -> 706727.5 | E26: =IF(AND(C26="",D26=""),"",E25+C26-D26) -> 1085042.5 | F26: Jual ke Bu Erta 7 September
A27: 45907 | B27: Tabungan nasabah | D27: =GETPIVOTDATA("Sum of Total Harga",'7-9-2025'!$J$2) -> 606410 | E27: =IF(AND(C27="",D27=""),"",E26+C27-D27) -> 478632.5 | F27: Tabungan 7 September
A28: 45907 | B28: Hasil Tabungan | C28: 15940 | E28: =IF(AND(C28="",D28=""),"",E27+C28-D28) -> 494572.5
A29: 45921 | B29: Konsumsi anggota | D29: 30000 | E29: =IF(AND(C29="",D29=""),"",E28+C29-D29) -> 464572.5 | F29: Bubur Kacang
A30: 45921 | B30: Konsumsi anggota | D30: 60000 | E30: =IF(AND(C30="",D30=""),"",E29+C30-D30) -> 404572.5 | F30: Es Jeruk
A31: 45921 | B31: Setor sampah | C31: ='21-9-2025'!X67 -> 115080 | E31: =IF(AND(C31="",D31=""),"",E30+C31-D31) -> 519652.5 | F31: Jual ke Pak Surat 21 September
A32: 45921 | B32: Setor sampah | C32: ='21-9-2025'!R67 -> 607945 | E32: =IF(AND(C32="",D32=""),"",E31+C32-D32) -> 1127597.5 | F32: Jual ke Bu Erta 21 September
A33: 45921 | B33: Tabungan nasabah | D33: =GETPIVOTDATA("Sum of Total Harga",'21-9-2025'!$J$2) -> 639949.5 | E33: =IF(AND(C33="",D33=""),"",E32+C33-D33) -> 487648 | F33: Tabungan 21 September
A34: 45921 | B34: Hasil Tabungan | C34: 45602.5 | E34: =IF(AND(C34="",D34=""),"",E33+C34-D34) -> 533250.5
A35: 45937 | B35: Limpahan AC Bekas dari RW | C35: 200000 | E35: =IF(AND(C35="",D35=""),"",E34+C35-D35) -> 733250.5
A36: 45949 | B36: Trash Bag | D36: 12000 | E36: =IF(AND(C36="",D36=""),"",E35+C36-D36) -> 721250.5
A37: 45953 | B37: Timbangan | D37: 44600 | E37: =IF(AND(C37="",D37=""),"",E36+C37-D37) -> 676650.5
A38: 45962 | B38: Bangku Jongkok | D38: 20000 | E38: =IF(AND(C38="",D38=""),"",E37+C38-D38) -> 656650.5
A39: 45962 | B39: Konsumsi anggota | D39: =75000+25000 -> 100000 | E39: =IF(AND(C39="",D39=""),"",E38+C39-D39) -> 556650.5 | F39: Nasi Oncom + Telur
A40: 45962 | B40: Konsumsi tamu | D40: 3000 | E40: =IF(AND(C40="",D40=""),"",E39+C40-D40) -> 553650.5
A41: 45962 | B41: Setor sampah | C41: ='1-11-25'!X68 -> 282000 | E41: =IF(AND(C41="",D41=""),"",E40+C41-D41) -> 835650.5 | F41: Jual ke Pak Surat 1 November
...

Sheet Sheet1
A3: Form Data Nasabah Bank Sampah
A4: Tangerang Selatan
A5: Eco Bank 26
A6: No | B6: Nama | C6: Alamat / RT | D6: No. HP | E6: Kota | F6: Provinsi | G6: Kode Pos | H6: No Rekening | I6: Nama Rekening
A7: 1 | B7: Bu Admini | C7: 1 | D7: 081316755852 | E7: Tangerang | F7: Banten | G7: 15810 | H7: 100620112110 | I7: Luthfi Lailatul Arifah Syakur
A8: 2 | B8: Bu Betria | C8: 1 | D8: 081316755852 | E8: Tangerang | F8: Banten | G8: 15810 | H8: 100620112110 | I8: Luthfi Lailatul Arifah Syakur
A9: 3 | B9: Bu Mala | C9: 1 | D9: 081316755852 | E9: Tangerang | F9: Banten | G9: 15810 | H9: 100620112110 | I9: Luthfi Lailatul Arifah Syakur
A10: 4 | B10: Bu Maryani | C10: 1 | D10: 081316755852 | E10: Tangerang | F10: Banten | G10: 15810 | H10: 100620112110 | I10: Luthfi Lailatul Arifah Syakur
A11: 5 | B11: Bu Nita | C11: 1 | D11: 081316755852 | E11: Tangerang | F11: Banten | G11: 15810 | H11: 100620112110 | I11: Luthfi Lailatul Arifah Syakur
A12: 6 | B12: Bu Nurjanah | C12: 1 | D12: 081316755852 | E12: Tangerang | F12: Banten | G12: 15810 | H12: 100620112110 | I12: Luthfi Lailatul Arifah Syakur
A13: 7 | B13: Bu Sunarti | C13: 1 | D13: 081316755852 | E13: Tangerang | F13: Banten | G13: 15810 | H13: 100620112110 | I13: Luthfi Lailatul Arifah Syakur
A14: 8 | B14: Bu Tetty Hamdi | C14: 1 | D14: 081316755852 | E14: Tangerang | F14: Banten | G14: 15810 | H14: 100620112110 | I14: Luthfi Lailatul Arifah Syakur
A15: 9 | B15: Bu Wulan | C15: 1 | D15: 081316755852 | E15: Tangerang | F15: Banten | G15: 15810 | H15: 100620112110 | I15: Luthfi Lailatul Arifah Syakur
A16: 10 | B16: Bu Yenvitriati | C16: 1 | D16: 081316755852 | E16: Tangerang | F16: Banten | G16: 15810 | H16: 100620112110 | I16: Luthfi Lailatul Arifah Syakur
A17: 11 | B17: Pak Danny | C17: 1 | D17: 081316755852 | E17: Tangerang | F17: Banten | G17: 15810 | H17: 100620112110 | I17: Luthfi Lailatul Arifah Syakur
A18: 12 | B18: Mama Wahyu | C18: 1 | D18: 081316755852 | E18: Tangerang | F18: Banten | G18: 15810 | H18: 100620112110 | I18: Luthfi Lailatul Arifah Syakur
... A108: 102 | B108: Dipo | C108: 7 | D108: 081316755852 | E108: Tangerang | F108: Banten | G108: 15810 | H108: 100620112110 | I108: Luthfi Lailatul Arifah Syakur
A109: 103 | B109: Bu Devilie | C109: Kp Bambu | D109: 081316755852 | E109: Tangerang | F109: Banten | G109: 15810 | H109: 100620112110 | I109: Luthfi Lailatul Arifah Syakur
A110: 104 | B110: Bu Lena | C110: Kp Bambu | D110: 081316755852 | E110: Tangerang | F110: Banten | G110: 15810 | H110: 100620112110 | I110: Luthfi Lailatul Arifah Syakur
A111: 105 | B111: Karang Taruna | C111: Pos | D111: 081316755852 | E111: Tangerang | F111: Banten | G111: 15810 | H111: 100620112110 | I111: Luthfi Lailatul Arifah Syakur
A112: 106 | B112: Kas | C112: Pos | D112: 081316755852 | E112: Tangerang | F112: Banten | G112: 15810 | H112: 100620112110 | I112: Luthfi Lailatul Arifah Syakur
A113: 107 | B113: Bu Mutia | C113: TD | D113: 081316755852 | E113: Tangerang | F113: Banten | G113: 15810 | H113: 100620112110 | I113: Luthfi Lailatul Arifah Syakur
A114: 108 | B114: Bu Larasati | C114: UE | D114: 081316755852 | E114: Tangerang | F114: Banten | G114: 15810 | H114: 100620112110 | I114: Luthfi Lailatul Arifah Syakur

Sheet Pak Surat
B2: No | C2: Jenis Barang | D2: Jumlah | E2: Harga Nasabah | F2: Harga Lapak | G2: Satuan | H2: Harga Baru
B3: 1 | C3: Acrylic | G3: kg
B4: 2 | C4: AC Blower | G4: unit
B5: 3 | C5: AC Indoor | F5: 250000 | G5: unit
B6: 4 | C6: AKI | F6: 12000 | G6: kg
B7: 5 | C7: Alumunium | F7: 15000 | G7: kg
B8: 6 | C8: Alumunium Foil | G8: kg
B9: 7 | C9: Asoy | G9: kg
B10: 8 | C10: Babet | G10: kg
B11: 9 | C11: Ban Bekas | G11: kg
B12: 10 | C12: Besi | F12: 4000 | G12: kg | H12: 4500
B13: 11 | C13: Boncos | G13: kg
B14: 12 | C14: Botol & Gelas Putih (Kotor) | G14: kg
B15: 13 | C15: Botol & Kaca Beling | G15: kg
B16: 14 | C16: Botol Berwarna | G16: kg
B17: 15 | C17: Botol Putih Bersih | F17: 6000 | G17: kg | H17: 4000 | M17: Contact Person
B18: 16 | C18: Buku Tulis & Pelajaran | F18: 1200 | G18: kg | M18: Pak Hotles | N18: 083813791409
B19: 17 | C19: CD Kristal | G19: kg
B20: 18 | C20: CPU | G20: unit
B21: 19 | C21: Emberan | F21: 1500 | G21: kg
B22: 20 | C22: Gabrukan | G22: kg
B23: 21 | C23: Galon Aqua | F23: 1000 | G23: unit | H23: 700
B24: 22 | C24: Gelas Berwarna | G24: kg
B25: 23 | C25: Gelas Putih Bersih | F25: 4000 | G25: kg | H25: 4000
B26: 24 | C26: Handphone | G26: unit
B27: 25 | C27: Impact | G27: kg
B28: 26 | C28: Injek | G28: kg
B29: 27 | C29: Kabel | G29: kg
B30: 28 | C30: Kabel Internet | G30: kg
B31: 29 | C31: Kabel Kulit | G31: kg
B32: 30 | C32: Kabin | G32: kg
B33: 31 | C33: Kaleng | F33: 2000 | G33: kg
B34: 32 | C34: Kardus Baik/Kering | F34: 1600 | G34: kg
B35: 33 | C35: Karpet Talang | G35: kg
B36: 34 | C36: Karung Beras | G36: kg
B37: 35 | C37: Kawat | G37: kg
B38: 36 | C38: Kertas HVS Putih | G38: kg
B39: 37 | C39: Kertas Semen | G39: kg
B40: 38 | C40: Kipas Angin | G40: unit
B41: 39 | C41: Koran/LKS | G41: kg
...

Sheet Kas
A2: Tanggal | B2: Deskripsi | C2: Masuk | D2: Keluar | E2: Total | F2: Keterangan
B3: Saldo awal | E3: 0
A4: 45850 | B4: Keuntungan Penjualan | C4: ='12-7-2025'!N61 -> 115091.5 | E4: =IF(AND(C4="",D4=""),"",E3+C4-D4) -> 115091.5
A5: 45864 | B5: Konsumsi anggota | D5: 74000 | E5: =IF(AND(C5="",D5=""),"",E4+C5-D5) -> 41091.5 | F5: Soto Pak Beny (Qris)
A6: 45864 | B6: Keuntungan Penjualan | C6: ='26-7-2025'!N57 -> 102905.5 | E6: =IF(AND(C6="",D6=""),"",E5+C6-D6) -> 143997
A7: 45864 | B7: Fotocopy | D7: 10000 | E7: =IF(AND(C7="",D7=""),"",E6+C7-D7) -> 133997 | F7: FC daftar hadir (Cash) | I7: =337000+450000+110000+1157446 -> 2054446
A8: 45864 | B8: ATK | D8: 58082 | E8: =IF(AND(C8="",D8=""),"",E7+C8-D8) -> 75915
A9: 45878 | B9: Keuntungan Penjualan | C9: ='9-8-2025'!L65 -> 259992.5 | E9: =IF(AND(C9="",D9=""),"",E8+C9-D9) -> 335907.5
A10: 45878 | B10: Konsumsi anggota | D10: 92000 | E10: =IF(AND(C10="",D10=""),"",E9+C10-D10) -> 243907.5 | F10: Mie Gacoan
A11: 45878 | B11: Hasil Tabungan | C11: 28245 | E11: =IF(AND(C11="",D11=""),"",E10+C11-D11) -> 272152.5 | F11: Timbangan 9 Agustus
A12: 45892 | B12: Keuntungan Penjualan | C12: ='23-8-2025'!L63 -> 129162.5 | E12: =IF(AND(C12="",D12=""),"",E11+C12-D12) -> 401315
A13: 45892 | B13: Konsumsi anggota | D13: 43000 | E13: =IF(AND(C13="",D13=""),"",E12+C13-D13) -> 358315 | F13: Gorengan
A14: 45892 | B14: Konsumsi anggota | D14: 4000 | E14: =IF(AND(C14="",D14=""),"",E13+C14-D14) -> 354315 | F14: Minum
A15: 45892 | B15: Hasil Tabungan | C15: 13000 | E15: =IF(AND(C15="",D15=""),"",E14+C15-D15) -> 367315 | F15: Timbangan 23 Agustus
A16: 45893 | B16: Admin Pinjaman PKK | C16: 100000 | E16: =IF(AND(C16="",D16=""),"",E15+C16-D16) -> 467315
A17: 45907 | B17: Konsumsi anggota | D17: =35000 -> 35000 | E17: =IF(AND(C17="",D17=""),"",E16+C17-D17) -> 432315 | F17: Rujak
A18: 45907 | B18: Banner | D18: 54000 | E18: =IF(AND(C18="",D18=""),"",E17+C18-D18) -> 378315
A19: 45907 | B19: Keuntungan Penjualan | C19: ='7-9-2025'!L62 -> 100317.5 | E19: =IF(AND(C19="",D19=""),"",E18+C19-D19) -> 478632.5
A20: 45907 | B20: Hasil Tabungan | C20: 15940 | E20: =IF(AND(C20="",D20=""),"",E19+C20-D20) -> 494572.5 | F20: Timbangan 7 September
A21: 45921 | B21: Konsumsi anggota | D21: 30000 | E21: =IF(AND(C21="",D21=""),"",E20+C21-D21) -> 464572.5 | F21: Bubur Kacang
A22: 45921 | B22: Konsumsi anggota | D22: 60000 | E22: =IF(AND(C22="",D22=""),"",E21+C22-D22) -> 404572.5 | F22: Es Jeruk
A23: 45921 | B23: Keuntungan Penjualan | C23: ='21-9-2025'!L61 -> 83075.5 | E23: =IF(AND(C23="",D23=""),"",E22+C23-D23) -> 487648
A24: 45921 | B24: Hasil Tabungan | C24: 45602.5 | E24: =IF(AND(C24="",D24=""),"",E23+C24-D24) -> 533250.5 | F24: Timbangan 21 September
A25: 45937 | B25: Limpahan AC Bekas dari RW | C25: 200000 | E25: =IF(AND(C25="",D25=""),"",E24+C25-D25) -> 733250.5
A26: 45949 | B26: Trash Bag | D26: 12000 | E26: =IF(AND(C26="",D26=""),"",E25+C26-D26) -> 721250.5
A27: 45949 | B27: Keuntungan Penjualan | C27: ='19-10-25'!L73 -> 89048 | E27: =IF(AND(C27="",D27=""),"",E26+C27-D27) -> 810298.5
A28: 45953 | B28: Timbangan | D28: 44600 | E28: =IF(AND(C28="",D28=""),"",E27+C28-D28) -> 765698.5
A29: 45962 | B29: Bangku Jongkok | D29: 20000 | E29: =IF(AND(C29="",D29=""),"",E28+C29-D29) -> 745698.5
A30: 45962 | B30: Konsumsi anggota | D30: =75000+25000 -> 100000 | E30: =IF(AND(C30="",D30=""),"",E29+C30-D30) -> 645698.5 | F30: Nasi Oncom + Telur
A31: 45962 | B31: Konsumsi tamu | D31: 3000 | E31: =IF(AND(C31="",D31=""),"",E30+C31-D31) -> 642698.5
A32: 45962 | B32: Keuntungan Penjualan | C32: ='1-11-25'!J55 -> 354225 | E32: =IF(AND(C32="",D32=""),"",E31+C32-D32) -> 996923.5
A33: 45962 | B33: Pembelian Buku Tabungan | C33: =(43*3000)-1000 -> 128000 | E33: =IF(AND(C33="",D33=""),"",E32+C33-D33) -> 1124923.5
A34: 45976 | B34: Konsumsi anggota | D34: 30000 | E34: =IF(AND(C34="",D34=""),"",E33+C34-D34) -> 1094923.5 | F34: Bubur Kacang
A35: 45976 | B35: Konsumsi anggota | D35: =13000*2 -> 26000 | E35: =IF(AND(C35="",D35=""),"",E34+C35-D35) -> 1068923.5 | F35: Gado-Gado
A36: 45976 | B36: Keuntungan Penjualan | C36: ='15-11-25'!J51 -> 313736 | E36: =IF(AND(C36="",D36=""),"",E35+C36-D36) -> 1382659.5
A37: 45976 | B37: Konsumsi anggota | D37: 60000 | E37: =IF(AND(C37="",D37=""),"",E36+C37-D37) -> 1322659.5 | F37: Es Campur
A38: 45977 | B38: Saklar, Tespen | D38: 25000 | E38: =IF(AND(C38="",D38=""),"",E37+C38-D38) -> 1297659.5
A39: 46004 | B39: Konsumsi anggota | D39: =226000-33000 -> 193000 | E39: =IF(AND(C39="",D39=""),"",E38+C39-D39) -> 1104659.5 | F39: Nasi Padang
A40: 46004 | B40: Konsumsi | D40: 24000 | E40: =IF(AND(C40="",D40=""),"",E39+C40-D40) -> 1080659.5 | F40: Kopi
A41: 46004 | B41: Super pel | D41: 5000 | E41: =IF(AND(C41="",D41=""),"",E40+C41-D41) -> 1075659.5
...

Sheet Tabungan
A2: Tanggal | B2: Deskripsi | C2: Masuk | D2: Keluar | E2: Total | F2: Keterangan
A3: 45864 | B3: Tabungan Nasabah | C3: =GETPIVOTDATA("Sum of Total Harga",'12-7-2025'!$J$2) -> 633711 | E3: =C3 -> 633711 | F3: Tanggal 12 Juli 2025
A4: 45871 | B4: Tarik Tunai Nasabah | D4: 17000 | E4: =IF(AND(C4="",D4=""),"",E3+C4-D4) -> 616711 | F4: Bu Fardani | G4: Cash
A5: 45878 | B5: Tarik Tunai Nasabah | D5: 41000 | E5: =IF(AND(C5="",D5=""),"",E4+C5-D5) -> 575711 | F5: Bu Arsudin | G5: Cash
A6: 45878 | B6: Tarik Tunai Nasabah | D6: ='Tabungan Nasabah'!G114 -> 28245 | E6: =IF(AND(C6="",D6=""),"",E5+C6-D6) -> 547466 | F6: Kas
A7: 45878 | B7: Tabungan Nasabah | C7: =GETPIVOTDATA("Sum of Total Harga",'26-7-2025'!$J$2) -> 620721 | E7: =IF(AND(C7="",D7=""),"",E6+C7-D7) -> 1168187 | F7: Tabungan 26 Juli 2025
A8: 45892 | B8: Tabungan Nasabah | C8: =GETPIVOTDATA("Sum of Total Harga",'9-8-2025'!$J$2) -> 644175 | E8: =IF(AND(C8="",D8=""),"",E7+C8-D8) -> 1812362 | F8: Tanggal 9 Agustus 2025
A9: 45892 | B9: Tabungan Nasabah | C9: =GETPIVOTDATA("Sum of Total Harga",'23-8-2025'!$J$2) -> 615287.5 | E9: =IF(AND(C9="",D9=""),"",E8+C9-D9) -> 2427649.5 | F9: Tanggal 23 Agustus 2025
A10: 45892 | B10: Tarik Tunai Nasabah | D10: ='Tabungan Nasabah'!H114 -> 13000 | E10: =IF(AND(C10="",D10=""),"",E9+C10-D10) -> 2414649.5 | F10: Kas
A11: 45893 | B11: Dipinjamkan ke koperasi PKK | D11: 2000000 | E11: =IF(AND(C11="",D11=""),"",E10+C11-D11) -> 414649.5 | G11: Cash
A12: 45871 | B12: Tarik Tunai Nasabah | D12: 72000 | E12: =IF(AND(C12="",D12=""),"",E11+C12-D12) -> 342649.5 | F12: Bu Devilie
A13: 45907 | B13: Tabungan Nasabah | C13: =GETPIVOTDATA("Sum of Total Harga",'7-9-2025'!$J$2) -> 606410 | E13: =IF(AND(C13="",D13=""),"",E12+C13-D13) -> 949059.5 | F13: Tanggal 7 September 2025 | G13: TF
A14: 45907 | B14: Tarik Tunai Nasabah | D14: ='Tabungan Nasabah'!I114 -> 15940 | E14: =IF(AND(C14="",D14=""),"",E13+C14-D14) -> 933119.5 | F14: Kas
A15: 45909 | B15: Tarik Tunai Nasabah | D15: 80000 | E15: =IF(AND(C15="",D15=""),"",E14+C15-D15) -> 853119.5 | F15: Mba Nurhayati
A16: 45921 | B16: Tabungan Nasabah | C16: =GETPIVOTDATA("Sum of Total Harga",'21-9-2025'!$J$2) -> 639949.5 | E16: =IF(AND(C16="",D16=""),"",E15+C16-D16) -> 1493069 | F16: Tanggal 21 September 2025 | G16: TF
A17: 45931 | B17: Tarik Tunai Nasabah | D17: 63000 | E17: =IF(AND(C17="",D17=""),"",E16+C17-D17) -> 1430069 | F17: Bu Lia RT 2
A18: 45949 | B18: Tabungan Nasabah | C18: =GETPIVOTDATA("Sum of Total Harga",'19-10-25'!$J$2) -> 765996 | E18: =IF(AND(C18="",D18=""),"",E17+C18-D18) -> 2196065 | F18: Tanggal 19 Oktoberr 2025
A19: 45949 | B19: Tarik Tunai Nasabah | D19: 20000 | E19: =IF(AND(C19="",D19=""),"",E18+C19-D19) -> 2176065 | F19: Bu Maryani | G19: TF
A20: 45921 | B20: Tarik Tunai Nasabah | D20: ='Tabungan Nasabah'!J114 -> 45602.5 | E20: =IF(AND(C20="",D20=""),"",E19+C20-D20) -> 2130462.5 | F20: Kas
A21: 45953 | B21: Tarik Tunai Nasabah | D21: 44000 | E21: =IF(AND(C21="",D21=""),"",E20+C21-D21) -> 2086462.5 | F21: Bu Alim | G21: TF
A22: 45953 | B22: Tarik Tunai Nasabah | D22: 25000 | E22: =IF(AND(C22="",D22=""),"",E21+C22-D22) -> 2061462.5 | F22: Bu Martinah | G22: TF
A23: 45954 | B23: Tarik Tunai Nasabah | D23: 30000 | E23: =IF(AND(C23="",D23=""),"",E22+C23-D23) -> 2031462.5 | F23: Mba Nurhayati | G23: TF
A24: 45962 | B24: Tarik Tunai Nasabah | D24: 29000 | E24: =IF(AND(C24="",D24=""),"",E23+C24-D24) -> 2002462.5 | F24: Pak Suprayitno | G24: Cash
A25: 45962 | B25: Tabungan Nasabah | C25: =GETPIVOTDATA("Sum of Total Harga",'1-11-25'!$J$2) -> 560888.5 | E25: =IF(AND(C25="",D25=""),"",E24+C25-D25) -> 2563351 | F25: Tanggal 1 November
A26: 45965 | B26: Tarik Tunai Nasabah | D26: 43000 | E26: =IF(AND(C26="",D26=""),"",E25+C26-D26) -> 2520351 | F26: Bu Purwani | G26: TF
A27: 45976 | B27: Tabungan Nasabah | C27: =GETPIVOTDATA("Sum of Total Harga",'15-11-25'!$J$2) -> 507306.5 | E27: =IF(AND(C27="",D27=""),"",E26+C27-D27) -> 3027657.5 | F27: Tanggal 15 November 2025
A28: 45976 | B28: Tarik Tunai Nasabah | D28: 50000 | E28: =IF(AND(C28="",D28=""),"",E27+C28-D28) -> 2977657.5 | F28: Bu Ani | G28: Cash
A29: 46004 | B29: Tabungan Nasabah | C29: =GETPIVOTDATA("Sum of Total Harga",'13-12-25'!$J$2) -> 866252.5 | E29: =IF(AND(C29="",D29=""),"",E28+C29-D29) -> 3843910 | F29: Tanggal 13 Desember 2025
A30: 46014 | B30: Tarik Tunai Nasabah | D30: 100000 | E30: =IF(AND(C30="",D30=""),"",E29+C30-D30) -> 3743910 | F30: Bu Ecin Dwi | G30: TF
A31: 46023 | B31: Tabungan Nasabah | C31: =GETPIVOTDATA("Sum of Total Harga",'3-1-26'!$J$2) -> 755582.5 | E31: =IF(AND(C31="",D31=""),"",E30+C31-D31) -> 4499492.5 | F31: Tanggal 3 Januari 2026
A32: 46047 | B32: Tarik Tunai Nasabah | D32: 140000 | E32: =IF(AND(C32="",D32=""),"",E31+C32-D32) -> 4359492.5 | F32: Bu Widodo | G32: Cash
A33: 46053 | B33: Tabungan Nasabah | C33: =GETPIVOTDATA("Sum of Total Harga",'31-1-26'!$J$4) -> 709346.5 | E33: =IF(AND(C33="",D33=""),"",E32+C33-D33) -> 5068839 | F33: Tanggal 31 Januari 2026
A34: 46053 | B34: Tarik Tunai Nasabah | D34: 3000 | E34: =IF(AND(C34="",D34=""),"",E33+C34-D34) -> 5065839 | F34: Bu Purwani | G34: Cash
A35: 46053 | B35: Tarik Tunai Nasabah | D35: 41000 | E35: =IF(AND(C35="",D35=""),"",E34+C35-D35) -> 5024839 | F35: Bu Devilie | G35: Cash | H35: diambil oleh Bu Yenvitriati
A36: 46054 | B36: Tarik Tunai Nasabah | D36: 80000 | E36: =IF(AND(C36="",D36=""),"",E35+C36-D36) -> 4944839 | F36: Mba Nurhayati | G36: Cash
A37: 46062 | B37: Tarik Tunai Nasabah | D37: 200000 | E37: =IF(AND(C37="",D37=""),"",E36+C37-D37) -> 4744839 | F37: Bu Neni | G37: Cash
A38: 46062 | B38: Tarik Tunai Nasabah | D38: 19572.5 | E38: =IF(AND(C38="",D38=""),"",E37+C38-D38) -> 4725266.5 | F38: Bu Yayuk | G38: TF
A39: 46068 | B39: Tabungan Nasabah | C39: =GETPIVOTDATA("Sum of Total Harga",'15-02-26'!$J$2) -> 543322.5 | E39: =IF(AND(C39="",D39=""),"",E38+C39-D39) -> 5268589 | F39: Tanggal 15 Februari 2026
A40: 46068 | B40: Tarik Tunai Nasabah | D40: 110000 | E40: =IF(AND(C40="",D40=""),"",E39+C40-D40) -> 5158589 | F40: Bu Uum | G40: Cash
A41: 46068 | B41: Tarik Tunai Nasabah | D41: 150000 | E41: =IF(AND(C41="",D41=""),"",E40+C41-D41) -> 5008589 | F41: Bu Wiwin | G41: TF
...

Sheet Bu Erta
B2: No | C2: Jenis Barang | D2: Jumlah | E2: Harga Nasabah | F2: Harga Lapak | G2: Satuan | H2: Total
B3: 1 | C3: Acrylic | E3: 1200 | F3: 1500 | G3: kg
B4: 2 | C4: AC Blower | E4: 90000 | F4: 100000 | G4: unit
B5: 3 | C5: AC Indoor | E5: 35000 | F5: 40000 | G5: unit
B6: 4 | C6: Aki | E6: 6000 | F6: 6500 | G6: kg
B7: 5 | C7: Alumunium | E7: 8000 | F7: 8500 | G7: kg
B8: 6 | C8: Alumunium Foil | E8: 3500 | F8: 4000 | G8: kg
B9: 7 | C9: Asoy | E9: 200 | F9: 300 | G9: kg
B10: 8 | C10: Babet | E10: 7500 | F10: 8000 | G10: kg
B11: 9 | C11: Ban Bekas | E11: 150 | F11: 200 | G11: kg
B12: 10 | C12: Besi | E12: 2500 | F12: 3000 | G12: kg
B13: 11 | C13: Boncos | E13: 300 | F13: 400 | G13: kg
B14: 12 | C14: Botol & Gelas Putih (Kotor) | E14: 1600 | F14: 1700 | G14: kg
... B66: 64 | C66: TV Tabung | E66: 13000 | F66: 15000 | G66: unit

Sheet KamiBox
B2: No | C2: Jenis Barang | D2: Jumlah | E2: Harga Nasabah | F2: Harga Lapak | G2: Satuan | H2: Total
C3: AC | F3: 200000 | G3: set
C4: Aki | F4: 9000
C5: Aluminium | F5: 10000
C6: Arsip | F6: 1000
C7: Asoy | F7: Tidak Terima
C8: Besi | F8: 4000
C9: Boncos Kotor | F9: 400
C10: Botol Kaca Hijau | F10: 100
C11: Botol Kaca Bening/Putih | F11: 200
C12: Botol Kaca Campur | F12: 100
C13: Botol Kaca Coklat/Merah | F13: 800
C14: Botol PET Bersih | F14: 4000
C15: Botol PET Kotor | F15: 2000
C16: Botol Plastik Kemasan Campur | F16: 1000
C17: Buku, Majalah, Brosur, Koran | F17: 1000
C18: Emberan | F18: 1200
C19: Gabrukan | F19: 1000
... C22: Gelas PP Warna | F22: 2000
C23: Handphone | F23: 5000 | G23: pcs
C24: HVS | F24: 2000
C25: Impact | F25: 700
C26: Jelantah | F26: 7000
C27: Kabel | F27: 1500 | G27: kg
C28: Kabin | F28: 2000
C29: Kaca | F29: 100
C30: Kaleng | F30: 2000
C31: Kantung Semen | F31: 1800
C32: Kardus | F32: 1700
C33: Kaset CD | F33: 4000
C34: Komputer | F34: 60000 | G34: set
C35: Kones | F35: 700
C36: Karung Beras | F36: 1200
C37: Kristal Putih | F37: 4000
C38: Kulkas | F38: 50000 | G38: set
C39: Kuningan | F39: 35000
C40: Mesin Cuci | F40: 50000 | G40: set
C41: Mika | F41: Tidak Terima
C42: MIX A/Boncos | F42: 700
C43: Plastik Minyak goreng | F43: Gabung dengan Multilayer
...

Sheet Sheet2
A2: No | B2: Nama | C2: RT | D2: Jenis Sampah | E2: Harga | F2: Berat | G2: Total Harga
A3: 1 | B3: Bu Tetty Hamdi | C3: 1 | D3: Gabrukan | E3: =VLOOKUP(D3,KamiBox!$C$2:$F$54,4,0) -> 1000 | F3: =0.65+2.75 -> 3.4 | G3: =E3*F3 -> 3400 | H3: =VLOOKUP(D3,'Bu Erta'!$C$2:$F$66,4,0)*F3 -> 3740
B4: Bu Tetty Hamdi | D4: Plastik Multilayer | E4: =VLOOKUP(D4,KamiBox!$C$2:$F$54,4,0) -> 500 | F4: =0.95+0.6+0.35+1.5 -> 3.4 | G4: =E4*F4 -> 1700 | H4: =VLOOKUP(D4,'Bu Erta'!$C$2:$F$66,4,0)*F4 -> #N/A
B5: Bu Tetty Hamdi | D5: Boncos Kotor | E5: =VLOOKUP(D5,KamiBox!$C$2:$F$54,4,0) -> 400 | F5: 0.75 | G5: =E5*F5 -> 300 | H5: =VLOOKUP(D5,'Bu Erta'!$C$2:$F$66,4,0)*F5 -> #N/A
B6: Bu Tetty Hamdi | D6: Plastik PE | E6: =VLOOKUP(D6,KamiBox!$C$2:$F$54,4,0) -> 1000 | F6: 0.3 | G6: =E6*F6 -> 300 | H6: =VLOOKUP(D6,'Bu Erta'!$C$2:$F$66,4,0)*F6 -> #N/A
B7: Bu Tetty Hamdi | D7: Kardus | E7: =VLOOKUP(D7,KamiBox!$C$2:$F$54,4,0) -> 1700 | F7: =7.05+11.4 -> 18.45 | G7: =E7*F7 -> 31365 | H7: =VLOOKUP(D7,'Bu Erta'!$C$2:$F$66,4,0)*F7 -> #N/A
A8: 2 | B8: Bu Wuri | C8: 4 | D8: Kardus | E8: =VLOOKUP(D8,KamiBox!$C$2:$F$54,4,0) -> 1700 | F8: 2.09 | G8: =E8*F8 -> 3553 | H8: =VLOOKUP(D8,'Bu Erta'!$C$2:$F$66,4,0)*F8 -> #N/A
B9: Bu Wuri | D9: Styrofoam | E9: =VLOOKUP(D9,KamiBox!$C$2:$F$54,4,0) -> 400 | F9: 0.1 | G9: =E9*F9 -> 40 | H9: =VLOOKUP(D9,'Bu Erta'!$C$2:$F$66,4,0)*F9 -> #N/A
B10: Bu Wuri | D10: Plastik Multilayer | E10: =VLOOKUP(D10,KamiBox!$C$2:$F$54,4,0) -> 500 | F10: 1.1 | G10: =E10*F10 -> 550 | H10: =VLOOKUP(D10,'Bu Erta'!$C$2:$F$66,4,0)*F10 -> #N/A
B11: Bu Wuri | D11: Tutup Galon | E11: =VLOOKUP(D11,KamiBox!$C$2:$F$54,4,0) -> 4500 | F11: 0.3 | G11: =E11*F11 -> 1350 | H11: =VLOOKUP(D11,'Bu Erta'!$C$2:$F$66,4,0)*F11 -> 1200
B12: Bu Wuri | D12: Tutup Botol | E12: =VLOOKUP(D12,KamiBox!$C$2:$F$54,4,0) -> 3000 | F12: 0.25 | G12: =E12*F12 -> 750 | H12: =VLOOKUP(D12,'Bu Erta'!$C$2:$F$66,4,0)*F12 -> 750
B13: Bu Wuri | D13: Botol PET Bersih | E13: =VLOOKUP(D13,KamiBox!$C$2:$F$54,4,0) -> 4000 | F13: 1.8 | G13: =E13*F13 -> 7200 | H13: =VLOOKUP(D13,'Bu Erta'!$C$2:$F$66,4,0)*F13 -> #N/A
B14: Bu Wuri | D14: Emberan | E14: =VLOOKUP(D14,KamiBox!$C$2:$F$54,4,0) -> 1200 | F14: 4.15 | G14: =E14*F14 -> 4980 | H14: =VLOOKUP(D14,'Bu Erta'!$C$2:$F$66,4,0)*F14 -> 6640
B15: Bu Wuri | D15: Plastik PE | E15: =VLOOKUP(D15,KamiBox!$C$2:$F$54,4,0) -> 1000 | F15: =0.2+0.3 -> 0.5 | G15: =E15*F15 -> 500 | H15: =VLOOKUP(D15,'Bu Erta'!$C$2:$F$66,4,0)*F15 -> #N/A
B16: Bu Wuri | D16: Naso | E16: =VLOOKUP(D16,KamiBox!$C$2:$F$54,4,0) -> #N/A | F16: 0.25 | G16: =E16*F16 -> #N/A | H16: =VLOOKUP(D16,'Bu Erta'!$C$2:$F$66,4,0)*F16 -> 625
B17: Bu Wuri | D17: Impact | E17: =VLOOKUP(D17,KamiBox!$C$2:$F$54,4,0) -> 700 | F17: =0.55+0.65 -> 1.2 | G17: =E17*F17 -> 840 | H17: =VLOOKUP(D17,'Bu Erta'!$C$2:$F$66,4,0)*F17 -> 780
B18: Bu Wuri | D18: Gelas PP Bersih | E18: =VLOOKUP(D18,KamiBox!$C$2:$F$54,4,0) -> 3500 | F18: 0.1 | G18: =E18*F18 -> 350 | H18: =VLOOKUP(D18,'Bu Erta'!$C$2:$F$66,4,0)*F18 -> #N/A
B19: Bu Wuri | D19: Kaca | E19: =VLOOKUP(D19,KamiBox!$C$2:$F$54,4,0) -> 100 | F19: 0.55 | G19: =E19*F19 -> 55 | H19: =VLOOKUP(D19,'Bu Erta'!$C$2:$F$66,4,0)*F19 -> #N/A
B20: Bu Wuri | D20: Kabin | E20: =VLOOKUP(D20,KamiBox!$C$2:$F$54,4,0) -> 2000 | F20: 0.1 | G20: =E20*F20 -> 200 | H20: =VLOOKUP(D20,'Bu Erta'!$C$2:$F$66,4,0)*F20 -> 200
B21: Bu Wuri | D21: Kaleng | E21: =VLOOKUP(D21,KamiBox!$C$2:$F$54,4,0) -> 2000 | F21: 0.6 | G21: =E21*F21 -> 1200 | H21: =VLOOKUP(D21,'Bu Erta'!$C$2:$F$66,4,0)*F21 -> 1200
B22: Bu Wuri | D22: Kristal Putih | E22: =VLOOKUP(D22,KamiBox!$C$2:$F$54,4,0) -> 4000 | F22: 0.2 | G22: =E22*F22 -> 800 | H22: =VLOOKUP(D22,'Bu Erta'!$C$2:$F$66,4,0)*F22 -> #N/A
B23: Bu Wuri | D23: Boncos Kotor | E23: =VLOOKUP(D23,KamiBox!$C$2:$F$54,4,0) -> 400 | F23: 1.8 | G23: =E23*F23 -> 720 | H23: =VLOOKUP(D23,'Bu Erta'!$C$2:$F$66,4,0)*F23 -> #N/A
A24: 3 | B24: Bu Suci | C24: 4 | D24: Botol PET Bersih | E24: =VLOOKUP(D24,KamiBox!$C$2:$F$54,4,0) -> 4000 | F24: 1.1 | G24: =E24*F24 -> 4400 | H24: =VLOOKUP(D24,'Bu Erta'!$C$2:$F$66,4,0)*F24 -> #N/A
B25: Bu Suci | D25: Tutup Botol | E25: =VLOOKUP(D25,KamiBox!$C$2:$F$54,4,0) -> 3000 | F25: 0.05 | G25: =E25*F25 -> 150 | H25: =VLOOKUP(D25,'Bu Erta'!$C$2:$F$66,4,0)*F25 -> 150
B26: Bu Suci | D26: Emberan | E26: =VLOOKUP(D26,KamiBox!$C$2:$F$54,4,0) -> 1200 | F26: =0.7+1.95+4.2+4.8+3+1.55+0.2+0.6+2+1.85 -> 20.85 | G26: =E26*F26 -> 25020 | H26: =VLOOKUP(D26,'Bu Erta'!$C$2:$F$66,4,0)*F26 -> 33360
B27: Bu Suci | D27: Kaca | E27: =VLOOKUP(D27,KamiBox!$C$2:$F$54,4,0) -> 100 | F27: =3.25+2+0.3+1.05+0.65 -> 7.25 | G27: =E27*F27 -> 725 | H27: =VLOOKUP(D27,'Bu Erta'!$C$2:$F$66,4,0)*F27 -> #N/A
B28: Bu Suci | D28: Kaleng | E28: =VLOOKUP(D28,KamiBox!$C$2:$F$54,4,0) -> 2000 | F28: =0.8+1.8 -> 2.6 | G28: =E28*F28 -> 5200 | H28: =VLOOKUP(D28,'Bu Erta'!$C$2:$F$66,4,0)*F28 -> 5200
B29: Bu Suci | D29: Kabin | E29: =VLOOKUP(D29,KamiBox!$C$2:$F$54,4,0) -> 2000 | F29: =1.15+1.9+1.15+2.35+3.75 -> 10.3 | G29: =E29*F29 -> 20600 | H29: =VLOOKUP(D29,'Bu Erta'!$C$2:$F$66,4,0)*F29 -> 20600
B30: Bu Suci | D30: Styrofoam | E30: =VLOOKUP(D30,KamiBox!$C$2:$F$54,4,0) -> 400 | F30: 0.25 | G30: =E30*F30 -> 100 | H30: =VLOOKUP(D30,'Bu Erta'!$C$2:$F$66,4,0)*F30 -> #N/A
B31: Bu Suci | D31: Buku, Majalah, Brosur, Koran | E31: =VLOOKUP(D31,KamiBox!$C$2:$F$54,4,0) -> 1000 | F31: 0.6 | G31: =E31*F31 -> 600 | H31: =VLOOKUP(D31,'Bu Erta'!$C$2:$F$66,4,0)*F31 -> #N/A
B32: Bu Suci | D32: Galon PC | E32: =VLOOKUP(D32,KamiBox!$C$2:$F$54,4,0) -> 3000 | F32: 1 | G32: =E32*F32 -> 3000 | H32: =VLOOKUP(D32,'Bu Erta'!$C$2:$F$66,4,0)*F32 -> #N/A
B33: Bu Suci | D33: Injek | E33: =VLOOKUP(D33,KamiBox!$C$2:$F$54,4,0) -> #N/A | F33: 0.2 | G33: =E33*F33 -> #N/A | H33: =VLOOKUP(D33,'Bu Erta'!$C$2:$F$66,4,0)*F33 -> 400
B34: Bu Suci | D34: Kristal Putih | E34: =VLOOKUP(D34,KamiBox!$C$2:$F$54,4,0) -> 4000 | F34: 0.25 | G34: =E34*F34 -> 1000 | H34: =VLOOKUP(D34,'Bu Erta'!$C$2:$F$66,4,0)*F34 -> #N/A
B35: Bu Suci | D35: Kardus | E35: =VLOOKUP(D35,KamiBox!$C$2:$F$54,4,0) -> 1700 | F35: =5.1+2.2 -> 7.3 | G35: =E35*F35 -> 12410 | H35: =VLOOKUP(D35,'Bu Erta'!$C$2:$F$66,4,0)*F35 -> #N/A
B36: Bu Suci | D36: Boncos Kotor | E36: =VLOOKUP(D36,KamiBox!$C$2:$F$54,4,0) -> 400 | F36: 0.6 | G36: =E36*F36 -> 240 | H36: =VLOOKUP(D36,'Bu Erta'!$C$2:$F$66,4,0)*F36 -> #N/A
B37: Bu Suci | D37: Besi | E37: =VLOOKUP(D37,KamiBox!$C$2:$F$54,4,0) -> 4000 | F37: =1.95+6.6 -> 8.55 | G37: =E37*F37 -> 34200 | H37: =VLOOKUP(D37,'Bu Erta'!$C$2:$F$66,4,0)*F37 -> 25650
B38: Bu Suci | D38: Kabel | E38: =VLOOKUP(D38,KamiBox!$C$2:$F$54,4,0) -> 1500 | F38: =0.8+1.3 -> 2.1 | G38: =E38*F38 -> 3150 | H38: =VLOOKUP(D38,'Bu Erta'!$C$2:$F$66,4,0)*F38 -> 3360
B39: Bu Suci | D39: Akrilik | E39: =VLOOKUP(D39,KamiBox!$C$2:$F$54,4,0) -> #N/A | F39: 2.35 | G39: =E39*F39 -> #N/A | H39: =VLOOKUP(D39,'Bu Erta'!$C$2:$F$66,4,0)*F39 -> #N/A
A40: 4 | B40: Bu Ecin Dwi | C40: 5 | D40: Kardus | E40: =VLOOKUP(D40,KamiBox!$C$2:$F$54,4,0) -> 1700 | F40: 3.85 | G40: =E40*F40 -> 6545 | H40: =VLOOKUP(D40,'Bu Erta'!$C$2:$F$66,4,0)*F40 -> #N/A
B41: Bu Ecin Dwi | D41: Gelas PP Bersih | E41: =VLOOKUP(D41,KamiBox!$C$2:$F$54,4,0) -> 3500 | F41: 0.55 | G41: =E41*F41 -> 1925 | H41: =VLOOKUP(D41,'Bu Erta'!$C$2:$F$66,4,0)*F41 -> #N/A
...

Sheet Tabungan Nasabah
E1: 2025 | O1: 2026
C2: Nama | D2: No. RT | E2: 12 Juli | F2: 26 Juli | G2: 9 Agustus | H2: 23 Agustus | I2: 7 September | J2: 21 September | K2: 19 Oktober | L2: 1 November | M2: 15 November | N2: 13 Desember | O2: 3 Januari | P2: 31 Januari | Q2: 15 Februari | V2: Total | W2: Sisa Saldo | X2: Tanggal Ambil | Y2: Keterangan
B3: 1 | C3: Bu Admini | D3: 1 | E3: =VLOOKUP(C3,'12-7-2025'!$J$2:$L$53,3,0) -> 16430 | F3: =VLOOKUP(C3,'26-7-2025'!$N$2:$P$50,3,0) -> 952.5 | G3: =VLOOKUP(C3,'9-8-2025'!$N$2:$P$57,3,0) -> 7450 | H3: =VLOOKUP(C3,'23-8-2025'!$J$2:$L$54,3,0) -> 9167.5 | I3: =VLOOKUP(C3,'7-9-2025'!$J$2:$L$57,3,0) -> 6900 | K3: =VLOOKUP(C3,'19-10-25'!$J$2:$L$69,3,0) -> 9965 | L3: =VLOOKUP(C3,'1-11-25'!$J$2:$L$48,3,0) -> 3680 | N3: =VLOOKUP(C3,'13-12-25'!$J$2:$L$64,3,0) -> 9965 | Q3: =VLOOKUP(C3,'15-02-26'!$J$2:$L$41,3,0) -> 7245 | V3: =SUM(E3:U3) -> 71755 | W3: =V3 -> 71755
B4: 2 | C4: Bu Betria | D4: 1 | H4: =VLOOKUP(C4,'23-8-2025'!$J$2:$L$54,3,0) -> 17495 | I4: =VLOOKUP(C4,'7-9-2025'!$J$2:$L$57,3,0) -> 9545 | J4: =VLOOKUP(C4,'21-9-2025'!$J$2:$L$55,3,0) -> 3800 | K4: =VLOOKUP(C4,'19-10-25'!$J$2:$L$69,3,0) -> 92900 | L4: =VLOOKUP(C4,'1-11-25'!$J$2:$L$48,3,0) -> 19550 | M4: =VLOOKUP(C4,'15-11-25'!$J$2:$L$46,3,0) -> 4660 | N4: =VLOOKUP(C4,'13-12-25'!$J$2:$L$64,3,0) -> 24155 | P4: =VLOOKUP(C4,'31-1-26'!$J$4:$L$53,3,0) -> 32960 | Q4: =VLOOKUP(C4,'15-02-26'!$J$2:$L$41,3,0) -> 14305 | V4: =SUM(E4:U4) -> 219370 | W4: =V4 -> 219370
B5: 3 | C5: Bu Mala | D5: 1 | E5: =VLOOKUP(C5,'12-7-2025'!$J$2:$L$53,3,0) -> 1010 | F5: =VLOOKUP(C5,'26-7-2025'!$N$2:$P$50,3,0) -> 980 | V5: =SUM(E5:U5) -> 1990 | W5: =V5 -> 1990
B6: 4 | C6: Bu Maryani | D6: 1 | G6: =VLOOKUP(C6,'9-8-2025'!$N$2:$P$57,3,0) -> 20520 | K6: =VLOOKUP(C6,'19-10-25'!$J$2:$L$69,3,0) -> 600 | O6: =VLOOKUP(C6,'3-1-26'!$J$2:$L$48,3,0) -> 150 | V6: =SUM(E6:U6) -> 21270 | W6: =V6-20000 -> 1270 | X6: 19 Oktober | Y6: Cash
B7: 5 | C7: Bu Nita | D7: 1 | G7: =VLOOKUP(C7,'9-8-2025'!$N$2:$P$57,3,0) -> 2200 | J7: =VLOOKUP(C7,'21-9-2025'!$J$2:$L$55,3,0) -> 9665 | K7: =VLOOKUP(C7,'19-10-25'!$J$2:$L$69,3,0) -> 8670 | M7: =VLOOKUP(C7,'15-11-25'!$J$2:$L$46,3,0) -> 4190 | O7: =VLOOKUP(C7,'3-1-26'!$J$2:$L$48,3,0) -> 23150 | Q7: =VLOOKUP(C7,'15-02-26'!$J$2:$L$41,3,0) -> 11945 | V7: =SUM(E7:U7) -> 59820 | W7: =V7 -> 59820
B8: 6 | C8: Bu Nurjanah | D8: 1 | G8: =VLOOKUP(C8,'9-8-2025'!$N$2:$P$57,3,0) -> 24060 | H8: =VLOOKUP(C8,'23-8-2025'!$J$2:$L$54,3,0) -> 3065 | I8: =VLOOKUP(C8,'7-9-2025'!$J$2:$L$57,3,0) -> 940 | J8: =VLOOKUP(C8,'21-9-2025'!$J$2:$L$55,3,0) -> 1860 | M8: =VLOOKUP(C8,'15-11-25'!$J$2:$L$46,3,0) -> 800 | N8: =VLOOKUP(C8,'13-12-25'!$J$2:$L$64,3,0) -> 3200 | O8: =VLOOKUP(C8,'3-1-26'!$J$2:$L$48,3,0) -> 7460 | V8: =SUM(E8:U8) -> 41385 | W8: =V8 -> 41385
B9: 7 | C9: Bu Sunarti | D9: 1 | F9: =VLOOKUP(C9,'26-7-2025'!$N$2:$P$50,3,0) -> 23928.5 | H9: =VLOOKUP(C9,'23-8-2025'!$J$2:$L$54,3,0) -> 2355 | L9: =VLOOKUP(C9,'1-11-25'!$J$2:$L$48,3,0) -> 24875 | M9: =VLOOKUP(C9,'15-11-25'!$J$2:$L$46,3,0) -> 8355 | O9: =VLOOKUP(C9,'3-1-26'!$J$2:$L$48,3,0) -> 9162.5 | P9: =VLOOKUP(C9,'31-1-26'!$J$4:$L$53,3,0) -> 17270 | V9: =SUM(E9:U9) -> 85946 | W9: =V9 -> 85946
B10: 8 | C10: Bu Tetty Hamdi | D10: 1 | F10: =VLOOKUP(C10,'26-7-2025'!$N$2:$P$50,3,0) -> 29705 | J10: =VLOOKUP(C10,'21-9-2025'!$J$2:$L$55,3,0) -> 2115 | N10: =VLOOKUP(C10,'13-12-25'!$J$2:$L$64,3,0) -> 1800 | V10: =SUM(E10:U10) -> 33620 | W10: =V10 -> 33620
B11: 9 | C11: Bu Wulan | D11: 1 | H11: =VLOOKUP(C11,'23-8-2025'!$J$2:$L$54,3,0) -> 11970 | N11: =VLOOKUP(C11,'13-12-25'!$J$2:$L$64,3,0) -> 12695 | V11: =SUM(E11:U11) -> 24665 | W11: =V11 -> 24665
B12: 10 | C12: Bu Yenvitriati | D12: 1 | G12: =VLOOKUP(C12,'9-8-2025'!$N$2:$P$57,3,0) -> 2800 | H12: =VLOOKUP(C12,'23-8-2025'!$J$2:$L$54,3,0) -> 5380 | I12: =VLOOKUP(C12,'7-9-2025'!$J$2:$L$57,3,0) -> 2585 | K12: =VLOOKUP(C12,'19-10-25'!$J$2:$L$69,3,0) -> 12940 | L12: =VLOOKUP(C12,'1-11-25'!$J$2:$L$48,3,0) -> 30517.5 | N12: =VLOOKUP(C12,'13-12-25'!$J$2:$L$64,3,0) -> 4742.5 | P12: =VLOOKUP(C12,'31-1-26'!$J$4:$L$53,3,0) -> 3050 | Q12: =VLOOKUP(C12,'15-02-26'!$J$2:$L$41,3,0) -> 6905 | V12: =SUM(E12:U12) -> 68920 | W12: =V12 -> 68920
B13: 11 | C13: Pak Danny | D13: 1 | E13: =VLOOKUP(C13,'12-7-2025'!$J$2:$L$53,3,0) -> 28292.5 | L13: =VLOOKUP(C13,'1-11-25'!$J$2:$L$48,3,0) -> 15870 | O13: =VLOOKUP(C13,'3-1-26'!$J$2:$L$48,3,0) -> 6650 | V13: =SUM(E13:U13) -> 50812.5 | W13: =V13 -> 50812.5
B14: 12 | C14: Mama Wahyu | D14: 1 | F14: =VLOOKUP(C14,'26-7-2025'!$N$2:$P$50,3,0) -> 14120 | G14: =VLOOKUP(C14,'9-8-2025'!$N$2:$P$57,3,0) -> 1060 | H14: =VLOOKUP(C14,'23-8-2025'!$J$2:$L$54,3,0) -> 580 | I14: =VLOOKUP(C14,'7-9-2025'!$J$2:$L$57,3,0) -> 1125 | K14: =VLOOKUP(C14,'19-10-25'!$J$2:$L$69,3,0) -> 4900 | M14: =VLOOKUP(C14,'15-11-25'!$J$2:$L$46,3,0) -> 3425 | N14: =VLOOKUP(C14,'13-12-25'!$J$2:$L$64,3,0) -> 2300 | O14: =VLOOKUP(C14,'3-1-26'!$J$2:$L$48,3,0) -> 840 | P14: =VLOOKUP(C14,'31-1-26'!$J$4:$L$53,3,0) -> 5145 | Q14: =VLOOKUP(C14,'15-02-26'!$J$2:$L$41,3,0) -> 1930 | V14: =SUM(E14:U14) -> 35425 | W14: =V14 -> 35425
B15: 13 | C15: Okta | D15: 1 | L15: =VLOOKUP(C15,'1-11-25'!$J$2:$L$48,3,0) -> 10075 | V15: =SUM(E15:U15) -> 10075 | W15: =V15 -> 10075
B16: 14 | C16: Bu Suhermiati | D16: 1 | M16: =VLOOKUP(C16,'15-11-25'!$J$2:$L$46,3,0) -> 8613 | P16: =VLOOKUP(C16,'31-1-26'!$J$4:$L$53,3,0) -> 9497.5 | V16: =SUM(E16:U16) -> 18110.5 | W16: =V16 -> 18110.5
B17: 15 | C17: Bu Susi | D17: 1 | M17: =VLOOKUP(C17,'15-11-25'!$J$2:$L$46,3,0) -> 11245 | V17: =SUM(E17:U17) -> 11245 | W17: =V17 -> 11245
B18: 16 | C18: Bu Termin | D18: 1 | M18: =VLOOKUP(C18,'15-11-25'!$J$2:$L$46,3,0) -> 3300 | N18: =VLOOKUP(C18,'13-12-25'!$J$2:$L$64,3,0) -> 5257.5 | O18: =VLOOKUP(C18,'3-1-26'!$J$2:$L$48,3,0) -> 5727.5 | P18: =VLOOKUP(C18,'31-1-26'!$J$4:$L$53,3,0) -> 6072.5 | V18: =SUM(E18:U18) -> 20357.5 | W18: =V18 -> 20357.5
B19: 17 | C19: Akhsan | D19: 2 | E19: =VLOOKUP(C19,'12-7-2025'!$J$2:$L$53,3,0) -> 1600 | F19: =VLOOKUP(C19,'26-7-2025'!$N$2:$P$50,3,0) -> 215 | G19: =VLOOKUP(C19,'9-8-2025'!$N$2:$P$57,3,0) -> 16650 | H19: =VLOOKUP(C19,'23-8-2025'!$J$2:$L$54,3,0) -> 14000 | K19: =VLOOKUP(C19,'19-10-25'!$J$2:$L$69,3,0) -> 10582.5 | N19: =VLOOKUP(C19,'13-12-25'!$J$2:$L$64,3,0) -> 21140 | V19: =SUM(E19:U19) -> 64187.5 | W19: =V19 -> 64187.5
B20: 18 | C20: Bela | D20: 2 | E20: =VLOOKUP(C20,'12-7-2025'!$J$2:$L$53,3,0) -> 6577.5 | K20: =VLOOKUP(C20,'19-10-25'!$J$2:$L$69,3,0) -> 1575 | N20: =VLOOKUP(C20,'13-12-25'!$J$2:$L$64,3,0) -> 5845 | V20: =SUM(E20:U20) -> 13997.5 | W20: =V20 -> 13997.5
B21: 19 | C21: Bu Alim | D21: 2 | E21: =VLOOKUP(C21,'12-7-2025'!$J$2:$L$53,3,0) -> 2100 | F21: =VLOOKUP(C21,'26-7-2025'!$N$2:$P$50,3,0) -> 26180 | I21: =VLOOKUP(C21,'7-9-2025'!$J$2:$L$57,3,0) -> 16570 | V21: =SUM(E21:U21) -> 44850 | W21: =V21-44000 -> 850 | X21: 23 Oktober | Y21: TF
B22: 20 | C22: Bu Angga | D22: 2 | E22: =VLOOKUP(C22,'12-7-2025'!$J$2:$L$53,3,0) -> 63745 | F22: =VLOOKUP(C22,'26-7-2025'!$N$2:$P$50,3,0) -> 5235 | G22: =VLOOKUP(C22,'9-8-2025'!$N$2:$P$57,3,0) -> 3550 | I22: =VLOOKUP(C22,'7-9-2025'!$J$2:$L$57,3,0) -> 33070 | L22: =VLOOKUP(C22,'1-11-25'!$J$2:$L$48,3,0) -> 18835 | N22: =VLOOKUP(C22,'13-12-25'!$J$2:$L$64,3,0) -> 36465 | O22: =VLOOKUP(C22,'3-1-26'!$J$2:$L$48,3,0) -> 5570 | P22: =VLOOKUP(C22,'31-1-26'!$J$4:$L$53,3,0) -> 2642.5 | Q22: =VLOOKUP(C22,'15-02-26'!$J$2:$L$41,3,0) -> 33395 | V22: =SUM(E22:U22) -> 202507.5 | W22: =V22-200000 -> 2507.5
B23: 21 | C23: Bu Fardani | D23: 2 | E23: =VLOOKUP(C23,'12-7-2025'!$J$2:$L$53,3,0) -> 17560 | V23: =SUM(E23:U23) -> 17560 | W23: =V23-17560 -> 0 | X23: 2 Agustus | Y23: Cash
B24: 22 | C24: Bu Hartinah | D24: 2 | F24: =VLOOKUP(C24,'26-7-2025'!$N$2:$P$50,3,0) -> 5360 | G24: =VLOOKUP(C24,'9-8-2025'!$N$2:$P$57,3,0) -> 4235 | H24: =VLOOKUP(C24,'23-8-2025'!$J$2:$L$54,3,0) -> 8792.5 | I24: =VLOOKUP(C24,'7-9-2025'!$J$2:$L$57,3,0) -> 8267.5 | J24: =VLOOKUP(C24,'21-9-2025'!$J$2:$L$55,3,0) -> 5040 | K24: =VLOOKUP(C24,'19-10-25'!$J$2:$L$69,3,0) -> 4465 | M24: =VLOOKUP(C24,'15-11-25'!$J$2:$L$46,3,0) -> 11955 | V24: =SUM(E24:U24) -> 48115 | W24: =V24 -> 48115
B25: 23 | C25: Bu Lia RT 2 | D25: 2 | J25: =VLOOKUP(C25,'21-9-2025'!$J$2:$L$55,3,0) -> 63000 | V25: =SUM(E25:U25) -> 63000 | W25: =V25-63000 -> 0 | X25: 1 Oktober | Y25: TF
B26: 24 | C26: Bu Martinah | D26: 2 | E26: =VLOOKUP(C26,'12-7-2025'!$J$2:$L$53,3,0) -> 2157.5 | H26: =VLOOKUP(C26,'23-8-2025'!$J$2:$L$54,3,0) -> 4255 | J26: =VLOOKUP(C26,'21-9-2025'!$J$2:$L$55,3,0) -> 3637.5 | K26: =VLOOKUP(C26,'19-10-25'!$J$2:$L$69,3,0) -> 15115 | V26: =SUM(E26:U26) -> 25165 | W26: =V26-25000 -> 165 | X26: 23 Oktober | Y26: TF
B27: 25 | C27: Bu Nurhidayah | D27: 2 | E27: =VLOOKUP(C27,'12-7-2025'!$J$2:$L$53,3,0) -> 3235 | V27: =SUM(E27:U27) -> 3235 | W27: =V27 -> 3235
B28: 26 | C28: Bu Ratu Tuti | D28: 2 | G28: =VLOOKUP(C28,'9-8-2025'!$N$2:$P$57,3,0) -> 18635 | H28: =VLOOKUP(C28,'23-8-2025'!$J$2:$L$54,3,0) -> 23787.5 | K28: =VLOOKUP(C28,'19-10-25'!$J$2:$L$69,3,0) -> 5155 | N28: =VLOOKUP(C28,'13-12-25'!$J$2:$L$64,3,0) -> 9355 | P28: =VLOOKUP(C28,'31-1-26'!$J$4:$L$53,3,0) -> 4760 | V28: =SUM(E28:U28) -> 61692.5 | W28: =V28 -> 61692.5
B29: 27 | C29: Bu Rustinah | D29: 2 | J29: =VLOOKUP(C29,'21-9-2025'!$J$2:$L$55,3,0) -> 2900 | K29: =VLOOKUP(C29,'19-10-25'!$J$2:$L$69,3,0) -> 13555 | V29: =SUM(E29:U29) -> 16455 | W29: =V29 -> 16455
B30: 28 | C30: Bu Widodo | D30: 2 | E30: =VLOOKUP(C30,'12-7-2025'!$J$2:$L$53,3,0) -> 400 | F30: =VLOOKUP(C30,'26-7-2025'!$N$2:$P$50,3,0) -> 44950 | H30: =VLOOKUP(C30,'23-8-2025'!$J$2:$L$54,3,0) -> 23475 | K30: =VLOOKUP(C30,'19-10-25'!$J$2:$L$69,3,0) -> 5388.5 | N30: =VLOOKUP(C30,'13-12-25'!$J$2:$L$64,3,0) -> 70805 | P30: =VLOOKUP(C30,'31-1-26'!$J$4:$L$53,3,0) -> 13200 | Q30: =VLOOKUP(C30,'15-02-26'!$J$2:$L$41,3,0) -> 3740 | V30: =SUM(E30:U30) -> 161958.5 | W30: =V30-140000 -> 21958.5
B31: 29 | C31: Bu Anwar | D31: 2 | H31: =VLOOKUP(C31,'23-8-2025'!$J$2:$L$54,3,0) -> 3290 | J31: =VLOOKUP(C31,'21-9-2025'!$J$2:$L$55,3,0) -> 2602.5 | K31: =VLOOKUP(C31,'19-10-25'!$J$2:$L$69,3,0) -> 6480 | L31: =VLOOKUP(C31,'1-11-25'!$J$2:$L$48,3,0) -> 21465 | N31: =VLOOKUP(C31,'13-12-25'!$J$2:$L$64,3,0) -> 4370 | Q31: =VLOOKUP(C31,'15-02-26'!$J$2:$L$41,3,0) -> 7552.5 | V31: =SUM(E31:U31) -> 45760 | W31: =V31 -> 45760
B32: 30 | C32: Mbak Nurhayati | D32: 2 | E32: =VLOOKUP(C32,'12-7-2025'!$J$2:$L$53,3,0) -> 19587.5 | F32: =VLOOKUP(C32,'26-7-2025'!$N$2:$P$50,3,0) -> 36790 | H32: =VLOOKUP(C32,'23-8-2025'!$J$2:$L$54,3,0) -> 32265 | J32: =VLOOKUP(C32,'21-9-2025'!$J$2:$L$55,3,0) -> 15655 | K32: =VLOOKUP(C32,'19-10-25'!$J$2:$L$69,3,0) -> 7970 | M32: =VLOOKUP(C32,'15-11-25'!$J$2:$L$46,3,0) -> 11107 | N32: =VLOOKUP(C32,'13-12-25'!$J$2:$L$64,3,0) -> 27105 | O32: =VLOOKUP(C32,'3-1-26'!$J$2:$L$48,3,0) -> 19997.5 | P32: =VLOOKUP(C32,'31-1-26'!$J$4:$L$53,3,0) -> 23787.5 | Q32: =VLOOKUP(C32,'15-02-26'!$J$2:$L$41,3,0) -> 17585 | V32: =SUM(E32:U32) -> 211849.5 | W32: =V32-80000-30000-80000 -> 21849.5 | X32: 7 September | Y32: Transfer
B33: 31 | C33: Mbak Sari | D33: 2 | G33: =VLOOKUP(C33,'9-8-2025'!$N$2:$P$57,3,0) -> 3665 | V33: =SUM(E33:U33) -> 3665 | W33: =V33 -> 3665
B34: 32 | C34: Mama Demas | D34: 2 | K34: =VLOOKUP(C34,'19-10-25'!$J$2:$L$69,3,0) -> 5460 | L34: =VLOOKUP(C34,'1-11-25'!$J$2:$L$48,3,0) -> 5332.5 | O34: =VLOOKUP(C34,'3-1-26'!$J$2:$L$48,3,0) -> 4970 | V34: =SUM(E34:U34) -> 15762.5 | W34: =V34 -> 15762.5
B35: 33 | C35: Pak Suprayitno | D35: 2 | I35: =VLOOKUP(C35,'7-9-2025'!$J$2:$L$57,3,0) -> 26110 | J35: =VLOOKUP(C35,'21-9-2025'!$J$2:$L$55,3,0) -> 3390 | N35: =VLOOKUP(C35,'13-12-25'!$J$2:$L$64,3,0) -> 24805 | O35: =VLOOKUP(C35,'3-1-26'!$J$2:$L$48,3,0) -> 8705 | V35: =SUM(E35:U35) -> 63010 | W35: =V35-29000 -> 34010
B36: 34 | C36: Novem | D36: 2 | E36: =VLOOKUP(C36,'12-7-2025'!$J$2:$L$53,3,0) -> 2040 | H36: =VLOOKUP(C36,'23-8-2025'!$J$2:$L$54,3,0) -> 1875 | L36: =VLOOKUP(C36,'1-11-25'!$J$2:$L$48,3,0) -> 16762.5 | N36: =VLOOKUP(C36,'13-12-25'!$J$2:$L$64,3,0) -> 3410 | O36: =VLOOKUP(C36,'3-1-26'!$J$2:$L$48,3,0) -> 4135 | V36: =SUM(E36:U36) -> 28222.5 | W36: =V36 -> 28222.5
B37: 35 | C37: Sela | D37: 2 | E37: =VLOOKUP(C37,'12-7-2025'!$J$2:$L$53,3,0) -> 40955 | J37: =VLOOKUP(C37,'21-9-2025'!$J$2:$L$55,3,0) -> 2300 | K37: =VLOOKUP(C37,'19-10-25'!$J$2:$L$69,3,0) -> 4727.5 | M37: =VLOOKUP(C37,'15-11-25'!$J$2:$L$46,3,0) -> 5365 | P37: =VLOOKUP(C37,'31-1-26'!$J$4:$L$53,3,0) -> 9472.5 | V37: =SUM(E37:U37) -> 62820 | W37: =V37 -> 62820
B38: 36 | C38: Vena | D38: 2 | J38: =VLOOKUP(C38,'21-9-2025'!$J$2:$L$55,3,0) -> 18522.5 | K38: =VLOOKUP(C38,'19-10-25'!$J$2:$L$69,3,0) -> 2600 | V38: =SUM(E38:U38) -> 21122.5 | W38: =V38 -> 21122.5
B39: 37 | C39: Pak Wawan | D39: 2 | E39: =VLOOKUP(C39,'12-7-2025'!$J$2:$L$53,3,0) -> 4600 | F39: =VLOOKUP(C39,'26-7-2025'!$N$2:$P$50,3,0) -> 20097.5 | G39: =VLOOKUP(C39,'9-8-2025'!$N$2:$P$57,3,0) -> 2800 | H39: =VLOOKUP(C39,'23-8-2025'!$J$2:$L$54,3,0) -> 5110 | I39: =VLOOKUP(C39,'7-9-2025'!$J$2:$L$57,3,0) -> 6300 | J39: =VLOOKUP(C39,'21-9-2025'!$J$2:$L$55,3,0) -> 12010 | K39: =VLOOKUP(C39,'19-10-25'!$J$2:$L$69,3,0) -> 11797.5 | L39: =VLOOKUP(C39,'1-11-25'!$J$2:$L$48,3,0) -> 20250 | N39: =VLOOKUP(C39,'13-12-25'!$J$2:$L$64,3,0) -> 19200 | O39: =VLOOKUP(C39,'3-1-26'!$J$2:$L$48,3,0) -> 20260 | P39: =VLOOKUP(C39,'31-1-26'!$J$4:$L$53,3,0) -> 7760 | Q39: =VLOOKUP(C39,'15-02-26'!$J$2:$L$41,3,0) -> 7500 | V39: =SUM(E39:U39) -> 137685 | W39: =V39-100000 -> 37685
B40: 38 | C40: Bu Indrayani | D40: 3 | G40: =VLOOKUP(C40,'9-8-2025'!$N$2:$P$57,3,0) -> 8395 | K40: =VLOOKUP(C40,'19-10-25'!$J$2:$L$69,3,0) -> 3660 | V40: =SUM(E40:U40) -> 12055 | W40: =V40 -> 12055
...

Sheet 15-02-26
A2: No | B2: Nama | C2: RT | D2: Jenis Sampah | E2: Harga | F2: Berat | G2: Total Harga | J2: Row Labels | K2: Sum of RT | L2: Sum of Total Harga | N2: Timbangan Bu Erta | Q2: Minggu, 15 Februari 2026 | T2: Timbangan Kami Box | W2: Minggu, 15 Februari 2026 | Z2: Timbangan Kami Box | AB2: Minggu, 15 Februari 2026
A3: 1 | B3: Bu Angga | C3: 2 | D3: Botol Putih Bersih | E3: =VLOOKUP(D3,'Bu Erta'!$C$2:$E$66,3,0) -> 2800 | F3: 0.45 | G3: =E3*F3 -> 1260 | H3: =VLOOKUP(D3,'Bu Erta'!$C$2:$F$66,4,0)*F3 -> 1395 | J3: Bu Yanti Bela | K3: 0 | L3: 4775 | N3: No | O3: Jenis Sampah | P3: Harga | Q3: Berat | R3: Total Harga | T3: No | U3: Jenis Sampah | V3: Harga | W3: Berat | X3: Total Harga | Z3: No | AA3: Jenis Sampah | AB3: Berat
B4: Bu Angga | D4: Multilayer | E4: =VLOOKUP(D4,'Bu Erta'!$C$2:$E$66,3,0) -> 300 | F4: 0.5 | G4: =E4*F4 -> 150 | H4: =VLOOKUP(D4,'Bu Erta'!$C$2:$F$66,4,0)*F4 -> 200 | J4: Bu Nita | K4: 1 | L4: 11945 | N4: 1 | O4: Acrylic | P4: =VLOOKUP(O4,'Bu Erta'!$C$2:$F$66,4,0) -> 1500 | Q4: =SUMIF($D$3:$D$271,O4,$F$3:$F$271) -> 0 | R4: =P4*Q4 -> 0 | T4: 1 | U4: AC | V4: =VLOOKUP(U4,KamiBox!$C$2:$F$54,4,0) -> 200000 | X4: =V4*W4 -> 0 | Z4: 1 | AA4: AC
B5: Bu Angga | D5: Tutup Botol | E5: =VLOOKUP(D5,'Bu Erta'!$C$2:$E$66,3,0) -> 2500 | F5: 0.25 | G5: =E5*F5 -> 625 | H5: =VLOOKUP(D5,'Bu Erta'!$C$2:$F$66,4,0)*F5 -> 750 | J5: Bu Admini | K5: 1 | L5: 7245 | N5: 2 | O5: AC Blower | P5: =VLOOKUP(O5,'Bu Erta'!$C$2:$F$66,4,0) -> 100000 | Q5: =SUMIF($D$3:$D$271,O5,$F$3:$F$271) -> 0 | R5: =P5*Q5 -> 0 | T5: 2 | U5: Aki | V5: =VLOOKUP(U5,KamiBox!$C$2:$F$54,4,0) -> 9000 | X5: =V5*W5 -> 0 | Z5: 2 | AA5: Aki
B6: Bu Angga | D6: Boncos | E6: =VLOOKUP(D6,'Bu Erta'!$C$2:$E$66,3,0) -> 300 | F6: 0.35 | G6: =E6*F6 -> 105 | H6: =VLOOKUP(D6,'Bu Erta'!$C$2:$F$66,4,0)*F6 -> 140 | J6: Bu Betria | K6: 1 | L6: 14305 | N6: 3 | O6: AC Indoor | P6: =VLOOKUP(O6,'Bu Erta'!$C$2:$F$66,4,0) -> 40000 | Q6: =SUMIF($D$3:$D$271,O6,$F$3:$F$271) -> 0 | R6: =P6*Q6 -> 0 | T6: 3 | U6: Aluminium | V6: =VLOOKUP(U6,KamiBox!$C$2:$F$54,4,0) -> 10000 | W6: 0.25 | X6: =V6*W6 -> 2500 | Z6: 3 | AA6: Aluminium | AB6: 0.25
B7: Bu Angga | D7: Gabrukan | E7: =VLOOKUP(D7,'Bu Erta'!$C$2:$E$66,3,0) -> 1000 | F7: 0.95 | G7: =E7*F7 -> 950 | H7: =VLOOKUP(D7,'Bu Erta'!$C$2:$F$66,4,0)*F7 -> 1045 | J7: Mama Wahyu | K7: 1 | L7: 1930 | N7: 4 | O7: AKI | P7: =VLOOKUP(O7,'Bu Erta'!$C$2:$F$66,4,0) -> 6500 | Q7: =SUMIF($D$3:$D$271,O7,$F$3:$F$271) -> 0 | R7: =P7*Q7 -> 0 | T7: 4 | U7: Arsip | V7: =VLOOKUP(U7,KamiBox!$C$2:$F$54,4,0) -> 1000 | X7: =V7*W7 -> 0 | Z7: 4 | AA7: Arsip
B8: Bu Angga | D8: Botol & Gelas Putih (Kotor) | E8: =VLOOKUP(D8,'Bu Erta'!$C$2:$E$66,3,0) -> 1600 | F8: =0.3+0.3+0.3 -> 0.9 | G8: =E8*F8 -> 1440 | H8: =VLOOKUP(D8,'Bu Erta'!$C$2:$F$66,4,0)*F8 -> 1530 | J8: Bu Yenvitriati | K8: 1 | L8: 6905 | N8: 5 | O8: Alumunium | P8: =VLOOKUP(O8,'Bu Erta'!$C$2:$F$66,4,0) -> 8500 | Q8: =SUMIF($D$3:$D$271,O8,$F$3:$F$271) -> 0.25 | R8: =P8*Q8 -> 2125 | T8: 5 | U8: Asoy | X8: =V8*W8 -> 0 | Z8: 5 | AA8: Asoy
B9: Bu Angga | D9: Kardus Baik/Kering | E9: =VLOOKUP(D9,'Bu Erta'!$C$2:$E$66,3,0) -> 1000 | F9: =0.05+0.05+0.85+0.75 -> 1.7 | G9: =E9*F9 -> 1700 | H9: =VLOOKUP(D9,'Bu Erta'!$C$2:$F$66,4,0)*F9 -> 2040 | J9: Pak Wawan | K9: 2 | L9: 7500 | N9: 6 | O9: Alumunium Foil | P9: =VLOOKUP(O9,'Bu Erta'!$C$2:$F$66,4,0) -> 4000 | Q9: =SUMIF($D$3:$D$271,O9,$F$3:$F$271) -> 0 | R9: =P9*Q9 -> 0 | T9: 6 | U9: Besi | V9: =VLOOKUP(U9,KamiBox!$C$2:$F$54,4,0) -> 4000 | W9: 24.2 | X9: =V9*W9 -> 96800 | Z9: 6 | AA9: Besi | AC9: 24.2
B10: Bu Angga | D10: Plastik (PE) | E10: =VLOOKUP(D10,'Bu Erta'!$C$2:$E$66,3,0) -> 800 | F10: 0.05 | G10: =E10*F10 -> 40 | H10: =VLOOKUP(D10,'Bu Erta'!$C$2:$F$66,4,0)*F10 -> 45 | J10: Bu Anwar | K10: 2 | L10: 7552.5 | N10: 7 | O10: Asoy | P10: =VLOOKUP(O10,'Bu Erta'!$C$2:$F$66,4,0) -> 300 | Q10: =SUMIF($D$3:$D$271,O10,$F$3:$F$271) -> 0 | R10: =P10*Q10 -> 0 | T10: 7 | U10: Boncos Kotor | V10: =VLOOKUP(U10,KamiBox!$C$2:$F$54,4,0) -> 400 | X10: =V10*W10 -> 0 | Z10: 7 | AA10: Boncos Kotor
B11: Bu Angga | D11: Besi | E11: =VLOOKUP(D11,'Bu Erta'!$C$2:$E$66,3,0) -> 2500 | F11: =3.75+3.55+3.55 -> 10.85 | G11: =E11*F11 -> 27125 | H11: =VLOOKUP(D11,'Bu Erta'!$C$2:$F$66,4,0)*F11 -> 32550 | J11: Mbak Nurhayati | K11: 2 | L11: 17585 | N11: 8 | O11: Babet | P11: =VLOOKUP(O11,'Bu Erta'!$C$2:$F$66,4,0) -> 8000 | Q11: =SUMIF($D$3:$D$271,O11,$F$3:$F$271) -> 0 | R11: =P11*Q11 -> 0 | T11: 8 | U11: Botol Kaca Hijau | V11: =VLOOKUP(U11,KamiBox!$C$2:$F$54,4,0) -> 100 | X11: =V11*W11 -> 0 | Z11: 8 | AA11: Botol Kaca Hijau
A12: 2 | B12: Bu Suci | C12: 4 | D12: Emberan | E12: =VLOOKUP(D12,'Bu Erta'!$C$2:$E$66,3,0) -> 1400 | F12: =2.2+1.85+2.15+1.55+1.8+0.8+0.75+0.1+0.5+0.6+1.6 -> 13.9 | G12: =E12*F12 -> 19460 | H12: =VLOOKUP(D12,'Bu Erta'!$C$2:$F$66,4,0)*F12 -> 22240 | J12: Bu Widodo | K12: 2 | L12: 3740 | N12: 9 | O12: Ban Bekas | P12: =VLOOKUP(O12,'Bu Erta'!$C$2:$F$66,4,0) -> 200 | Q12: =SUMIF($D$3:$D$271,O12,$F$3:$F$271) -> 0 | R12: =P12*Q12 -> 0 | T12: 9 | U12: Botol Kaca Bening/Putih | V12: =VLOOKUP(U12,KamiBox!$C$2:$F$54,4,0) -> 200 | W12: 10.9 | X12: =V12*W12 -> 2180 | Z12: 9 | AA12: Botol Kaca Bening/Putih | AB12: 10.9
B13: Bu Suci | D13: Kaleng | E13: =VLOOKUP(D13,'Bu Erta'!$C$2:$E$66,3,0) -> 1500 | F13: =0.6+0.2 -> 0.8 | G13: =E13*F13 -> 1200 | H13: =VLOOKUP(D13,'Bu Erta'!$C$2:$F$66,4,0)*F13 -> 1600 | J13: Bu Angga | K13: 2 | L13: 33395 | N13: 10 | O13: Besi | P13: =VLOOKUP(O13,'Bu Erta'!$C$2:$F$66,4,0) -> 3000 | Q13: =SUMIF($D$3:$D$271,O13,$F$3:$F$271) -> 24.2 | R13: =P13*Q13 -> 72600 | T13: 10 | U13: Botol Kaca Campur | V13: =VLOOKUP(U13,KamiBox!$C$2:$F$54,4,0) -> 100 | X13: =V13*W13 -> 0 | Z13: 10 | AA13: Botol Kaca Campur
B14: Bu Suci | D14: Kabin | E14: =VLOOKUP(D14,'Bu Erta'!$C$2:$E$66,3,0) -> 1800 | F14: =2.1+0.7+0.3 -> 3.1 | G14: =E14*F14 -> 5580 | H14: =VLOOKUP(D14,'Bu Erta'!$C$2:$F$66,4,0)*F14 -> 6200 | J14: Bu Purwani | K14: 3 | L14: 18300 | N14: 11 | O14: Boncos | P14: =VLOOKUP(O14,'Bu Erta'!$C$2:$F$66,4,0) -> 400 | Q14: =SUMIF($D$3:$D$271,O14,$F$3:$F$271) -> 34.95 | R14: =P14*Q14 -> 13980 | T14: 11 | U14: Botol Kaca Coklat/Merah | V14: =VLOOKUP(U14,KamiBox!$C$2:$F$54,4,0) -> 800 | X14: =V14*W14 -> 0 | Z14: 11 | AA14: Botol Kaca Coklat/Merah
B15: Bu Suci | D15: Impact | E15: =VLOOKUP(D15,'Bu Erta'!$C$2:$E$66,3,0) -> 600 | F15: 1.4 | G15: =E15*F15 -> 840 | H15: =VLOOKUP(D15,'Bu Erta'!$C$2:$F$66,4,0)*F15 -> 910 | J15: Bu Minah | K15: 3 | L15: 2165 | N15: 12 | O15: Botol & Gelas Putih (Kotor) | P15: =VLOOKUP(O15,'Bu Erta'!$C$2:$F$66,4,0) -> 1700 | Q15: =SUMIF($D$3:$D$271,O15,$F$3:$F$271) -> 6.25 | R15: =P15*Q15 -> 10625 | T15: 12 | U15: Botol PET bersih | V15: =VLOOKUP(U15,KamiBox!$C$2:$F$54,4,0) -> 4000 | W15: =25.65+5 -> 30.65 | X15: =V15*W15 -> 122600 | Z15: 12 | AA15: Botol PET bersih | AB15: =25.65+5 -> 30.65
B16: Bu Suci | D16: Gelas Putih Bersih | E16: =VLOOKUP(D16,'Bu Erta'!$C$2:$E$66,3,0) -> 3500 | F16: 0.2 | G16: =E16*F16 -> 700 | H16: =VLOOKUP(D16,'Bu Erta'!$C$2:$F$66,4,0)*F16 -> 720 | J16: Bu Wiwin | K16: 3 | L16: 7790 | N16: 13 | O16: Botol & Kaca Beling | P16: =VLOOKUP(O16,'Bu Erta'!$C$2:$F$66,4,0) -> 200 | Q16: =SUMIF($D$3:$D$271,O16,$F$3:$F$271) -> 10.9 | R16: =P16*Q16 -> 2180 | T16: 13 | U16: Botol PET Kotor | V16: =VLOOKUP(U16,KamiBox!$C$2:$F$54,4,0) -> 2000 | W16: 1.25 | X16: =V16*W16 -> 2500 | Z16: 13 | AA16: Botol PET Kotor | AB16: 1.25
B17: Bu Suci | D17: Toples Kue Kristal | E17: =VLOOKUP(D17,'Bu Erta'!$C$2:$E$66,3,0) -> 2700 | F17: 0.55 | G17: =E17*F17 -> 1485 | H17: =VLOOKUP(D17,'Bu Erta'!$C$2:$F$66,4,0)*F17 -> 1650 | J17: Bu Sarti | K17: 4 | L17: 18825 | N17: 14 | O17: Botol Berwarna | P17: =VLOOKUP(O17,'Bu Erta'!$C$2:$F$66,4,0) -> 1000 | Q17: =SUMIF($D$3:$D$271,O17,$F$3:$F$271) -> 0 | R17: =P17*Q17 -> 0 | T17: 14 | U17: Botol Plastik Kemasan Campur | V17: =VLOOKUP(U17,KamiBox!$C$2:$F$54,4,0) -> 1000 | X17: =V17*W17 -> 0 | Z17: 14 | AA17: Botol Plastik Kemasan Campur
B18: Bu Suci | D18: Botol & Gelas Putih (Kotor) | E18: =VLOOKUP(D18,'Bu Erta'!$C$2:$E$66,3,0) -> 1600 | F18: 0.15 | G18: =E18*F18 -> 240 | H18: =VLOOKUP(D18,'Bu Erta'!$C$2:$F$66,4,0)*F18 -> 255 | J18: Bu Neni | K18: 4 | L18: 3720 | N18: 15 | O18: Botol Putih Bersih | P18: =VLOOKUP(O18,'Bu Erta'!$C$2:$F$66,4,0) -> 3100 | Q18: =SUMIF($D$3:$D$271,O18,$F$3:$F$271) -> 25.65 | R18: =P18*Q18 -> 79515 | T18: 15 | U18: Buku, majalah, brosur, koran | V18: =VLOOKUP(U18,KamiBox!$C$2:$F$54,4,0) -> 1000 | W18: =14.75+0.6 -> 15.35 | X18: =V18*W18 -> 15350 | Z18: 15 | AA18: Buku, majalah, brosur, koran | AB18: =14.75+0.6 -> 15.35
B19: Bu Suci | D19: Botol Putih Bersih | E19: =VLOOKUP(D19,'Bu Erta'!$C$2:$E$66,3,0) -> 2800 | F19: 0.25 | G19: =E19*F19 -> 700 | H19: =VLOOKUP(D19,'Bu Erta'!$C$2:$F$66,4,0)*F19 -> 775 | J19: Bu Febri | K19: 4 | L19: 12775 | N19: 16 | O19: Buku Tulis & Pelajaran | P19: =VLOOKUP(O19,'Bu Erta'!$C$2:$F$66,4,0) -> 1300 | Q19: =SUMIF($D$3:$D$271,O19,$F$3:$F$271) -> 14.75 | R19: =P19*Q19 -> 19175 | T19: 16 | U19: Emberan | V19: =VLOOKUP(U19,KamiBox!$C$2:$F$54,4,0) -> 1200 | W19: =68.65+1.2 -> 69.85 | X19: =V19*W19 -> 83820 | Z19: 16 | AA19: Emberan | AB19: =68.65+1.2 -> 69.85
B20: Bu Suci | D20: Tutup Botol | E20: =VLOOKUP(D20,'Bu Erta'!$C$2:$E$66,3,0) -> 2500 | F20: 0.1 | G20: =E20*F20 -> 250 | H20: =VLOOKUP(D20,'Bu Erta'!$C$2:$F$66,4,0)*F20 -> 300 | J20: Bu Rina | K20: 4 | L20: 15300 | N20: 17 | O20: CD Kristal | P20: =VLOOKUP(O20,'Bu Erta'!$C$2:$F$66,4,0) -> 6000 | Q20: =SUMIF($D$3:$D$271,O20,$F$3:$F$271) -> 2.95 | R20: =P20*Q20 -> 17700 | T20: 17 | U20: Gabrukan | V20: =VLOOKUP(U20,KamiBox!$C$2:$F$54,4,0) -> 1000 | W20: 15 | X20: =V20*W20 -> 15000 | Z20: 17 | AA20: Gabrukan | AB20: 15
B21: Bu Suci | D21: Boncos | E21: =VLOOKUP(D21,'Bu Erta'!$C$2:$E$66,3,0) -> 300 | F21: 0.75 | G21: =E21*F21 -> 225 | H21: =VLOOKUP(D21,'Bu Erta'!$C$2:$F$66,4,0)*F21 -> 300 | J21: Bu Sariyanti | K21: 4 | L21: 12367.5 | N21: 18 | O21: CPU | P21: =VLOOKUP(O21,'Bu Erta'!$C$2:$F$66,4,0) -> 15000 | Q21: =SUMIF($D$3:$D$271,O21,$F$3:$F$271) -> 0 | R21: =P21*Q21 -> 0 | T21: 18 | U21: Galon PC | V21: =VLOOKUP(U21,KamiBox!$C$2:$F$54,4,0) -> 3000 | X21: =V21*W21 -> 0 | Z21: 18 | AA21: Galon PC
B22: Bu Suci | D22: Multilayer | E22: =VLOOKUP(D22,'Bu Erta'!$C$2:$E$66,3,0) -> 300 | F22: =0.95+0.4 -> 1.35 | G22: =E22*F22 -> 405 | H22: =VLOOKUP(D22,'Bu Erta'!$C$2:$F$66,4,0)*F22 -> 540 | J22: Bu Riris | K22: 4 | L22: 40495 | N22: 19 | O22: Emberan | P22: =VLOOKUP(O22,'Bu Erta'!$C$2:$F$66,4,0) -> 1600 | Q22: =SUMIF($D$3:$D$271,O22,$F$3:$F$271) -> 68.65 | R22: =P22*Q22 -> 109840 | T22: 19 | U22: Gelas PP Bersih | V22: =VLOOKUP(U22,KamiBox!$C$2:$F$54,4,0) -> 3500 | W22: 2.7 | X22: =V22*W22 -> 9450 | Z22: 19 | AA22: Gelas PP Bersih | AB22: 2.7
B23: Bu Suci | D23: Kardus Baik/Kering | E23: =VLOOKUP(D23,'Bu Erta'!$C$2:$E$66,3,0) -> 1000 | F23: 0.85 | G23: =E23*F23 -> 850 | H23: =VLOOKUP(D23,'Bu Erta'!$C$2:$F$66,4,0)*F23 -> 1020 | J23: Bu Suci | K23: 4 | L23: 31942.5 | N23: 20 | O23: Gabrukan | P23: =VLOOKUP(O23,'Bu Erta'!$C$2:$F$66,4,0) -> 1100 | Q23: =SUMIF($D$3:$D$271,O23,$F$3:$F$271) -> 15 | R23: =P23*Q23 -> 16500 | T23: 20 | U23: Gelas PP Warna | V23: =VLOOKUP(U23,KamiBox!$C$2:$F$54,4,0) -> 2000 | X23: =V23*W23 -> 0 | Z23: 20 | AA23: Gelas PP Warna
B24: Bu Suci | D24: Sterofoam | E24: =VLOOKUP(D24,'Bu Erta'!$C$2:$E$66,3,0) -> 150 | F24: 0.05 | G24: =E24*F24 -> 7.5 | H24: =VLOOKUP(D24,'Bu Erta'!$C$2:$F$66,4,0)*F24 -> 10 | J24: Mama Adam | K24: 4 | L24: 3770 | N24: 21 | O24: Galon Aqua | P24: =VLOOKUP(O24,'Bu Erta'!$C$2:$F$66,4,0) -> 5000 | Q24: =SUMIF($D$3:$D$271,O24,$F$3:$F$271) -> 0 | R24: =P24*Q24 -> 0 | T24: 21 | U24: Handphone | V24: =VLOOKUP(U24,KamiBox!$C$2:$F$54,4,0) -> 5000 | X24: =V24*W24 -> 0 | Z24: 21 | AA24: Handphone
A25: 3 | B25: Bu Neni | C25: 4 | D25: Botol Putih Bersih | E25: =VLOOKUP(D25,'Bu Erta'!$C$2:$E$66,3,0) -> 2800 | F25: =0.15+0.25 -> 0.4 | G25: =E25*F25 -> 1120 | H25: =VLOOKUP(D25,'Bu Erta'!$C$2:$F$66,4,0)*F25 -> 1240 | J25: Bu Tunut | K25: 4 | L25: 28820 | N25: 22 | O25: Gelas Berwarna | P25: =VLOOKUP(O25,'Bu Erta'!$C$2:$F$66,4,0) -> 1400 | Q25: =SUMIF($D$3:$D$271,O25,$F$3:$F$271) -> 0 | R25: =P25*Q25 -> 0 | T25: 22 | U25: HVS | V25: =VLOOKUP(U25,KamiBox!$C$2:$F$54,4,0) -> 2000 | W25: 6.5 | X25: =V25*W25 -> 13000 | Z25: 22 | AA25: HVS | AB25: 6.5
B26: Bu Neni | D26: Boncos | E26: =VLOOKUP(D26,'Bu Erta'!$C$2:$E$66,3,0) -> 300 | F26: 0.25 | G26: =E26*F26 -> 75 | H26: =VLOOKUP(D26,'Bu Erta'!$C$2:$F$66,4,0)*F26 -> 100 | J26: Bu Nining | K26: 4 | L26: 15330 | N26: 23 | O26: Gelas Putih Bersih | P26: =VLOOKUP(O26,'Bu Erta'!$C$2:$F$66,4,0) -> 3600 | Q26: =SUMIF($D$3:$D$271,O26,$F$3:$F$271) -> 2.7 | R26: =P26*Q26 -> 9720 | T26: 23 | U26: Impact | V26: =VLOOKUP(U26,KamiBox!$C$2:$F$54,4,0) -> 700 | W26: 8.1 | X26: =V26*W26 -> 5670 | Z26: 23 | AA26: Impact | AB26: 8.1
B27: Bu Neni | D27: Botol & Kaca Beling | E27: =VLOOKUP(D27,'Bu Erta'!$C$2:$E$66,3,0) -> 150 | F27: =2.4+0.3 -> 2.7 | G27: =E27*F27 -> 405 | H27: =VLOOKUP(D27,'Bu Erta'!$C$2:$F$66,4,0)*F27 -> 540 | J27: Bu Irma | K27: 4 | L27: 7390 | N27: 24 | O27: Handphone | P27: =VLOOKUP(O27,'Bu Erta'!$C$2:$F$66,4,0) -> 2000 | Q27: =SUMIF($D$3:$D$271,O27,$F$3:$F$271) -> 0 | R27: =P27*Q27 -> 0 | T27: 24 | U27: Jelantah | V27: =VLOOKUP(U27,KamiBox!$C$2:$F$54,4,0) -> 7000 | W27: 14.55 | X27: =V27*W27 -> 101850 | Z27: 24 | AA27: Jelantah | AB27: 14.55
B28: Bu Neni | D28: Emberan | E28: =VLOOKUP(D28,'Bu Erta'!$C$2:$E$66,3,0) -> 1400 | F28: =0.3+0.9+0.1 -> 1.3 | G28: =E28*F28 -> 1820 | H28: =VLOOKUP(D28,'Bu Erta'!$C$2:$F$66,4,0)*F28 -> 2080 | J28: Bu Suriya | K28: 4 | L28: 5320 | N28: 25 | O28: Impact | P28: =VLOOKUP(O28,'Bu Erta'!$C$2:$F$66,4,0) -> 650 | Q28: =SUMIF($D$3:$D$271,O28,$F$3:$F$271) -> 8.1 | R28: =P28*Q28 -> 5265 | T28: 25 | U28: Kabel | V28: =VLOOKUP(U28,KamiBox!$C$2:$F$54,4,0) -> 1500 | W28: 2.3 | X28: =V28*W28 -> 3450 | Z28: 25 | AA28: Kabel | AB28: 2.3
B29: Bu Neni | D29: Kaleng | E29: =VLOOKUP(D29,'Bu Erta'!$C$2:$E$66,3,0) -> 1500 | F29: 0.2 | G29: =E29*F29 -> 300 | H29: =VLOOKUP(D29,'Bu Erta'!$C$2:$F$66,4,0)*F29 -> 400 | J29: Bu Wuri | K29: 4 | L29: 16020 | N29: 26 | O29: Injek | P29: =VLOOKUP(O29,'Bu Erta'!$C$2:$F$66,4,0) -> 2000 | Q29: =SUMIF($D$3:$D$271,O29,$F$3:$F$271) -> 0 | R29: =P29*Q29 -> 0 | T29: 26 | U29: Kabin | V29: =VLOOKUP(U29,KamiBox!$C$2:$F$54,4,0) -> 2000 | W29: 10.5 | X29: =V29*W29 -> 21000 | Z29: 26 | AA29: Kabin | AB29: 10.5
A30: 4 | B30: Bu Ecin Dwi | C30: 5 | D30: Kardus Baik/Kering | E30: =VLOOKUP(D30,'Bu Erta'!$C$2:$E$66,3,0) -> 1000 | F30: =14.3+2.85 -> 17.15 | G30: =E30*F30 -> 17150 | H30: =VLOOKUP(D30,'Bu Erta'!$C$2:$F$66,4,0)*F30 -> 20580 | J30: Bu Ani | K30: 4 | L30: 15205 | N30: 27 | O30: Kabel | P30: =VLOOKUP(O30,'Bu Erta'!$C$2:$F$66,4,0) -> 1600 | Q30: =SUMIF($D$3:$D$271,O30,$F$3:$F$271) -> 2.3 | R30: =P30*Q30 -> 3680 | T30: 27 | U30: Kaca | V30: =VLOOKUP(U30,KamiBox!$C$2:$F$54,4,0) -> 100 | X30: =V30*W30 -> 0 | Z30: 27 | AA30: Kaca
B31: Bu Ecin Dwi | D31: Botol Putih Bersih | E31: =VLOOKUP(D31,'Bu Erta'!$C$2:$E$66,3,0) -> 2800 | F31: 0.35 | G31: =E31*F31 -> 980 | H31: =VLOOKUP(D31,'Bu Erta'!$C$2:$F$66,4,0)*F31 -> 1085 | J31: Bu Ida Amanah | K31: 4 | L31: 21555 | N31: 28 | O31: Kabel Internet | P31: =VLOOKUP(O31,'Bu Erta'!$C$2:$F$66,4,0) -> 200 | Q31: =SUMIF($D$3:$D$271,O31,$F$3:$F$271) -> 0 | R31: =P31*Q31 -> 0 | T31: 28 | U31: Kaleng | V31: =VLOOKUP(U31,KamiBox!$C$2:$F$54,4,0) -> 2000 | W31: 6.25 | X31: =V31*W31 -> 12500 | Z31: 28 | AA31: Kaleng | AB31: 6.25
B32: Bu Ecin Dwi | D32: Tutup Botol | E32: =VLOOKUP(D32,'Bu Erta'!$C$2:$E$66,3,0) -> 2500 | F32: 0.25 | G32: =E32*F32 -> 625 | H32: =VLOOKUP(D32,'Bu Erta'!$C$2:$F$66,4,0)*F32 -> 750 | J32: Bu Nurlayli | K32: 4 | L32: 2920 | N32: 29 | O32: Kabel Kulit | P32: =VLOOKUP(O32,'Bu Erta'!$C$2:$F$66,4,0) -> 800 | Q32: =SUMIF($D$3:$D$271,O32,$F$3:$F$271) -> 0 | R32: =P32*Q32 -> 0 | T32: 29 | U32: Kantung Semen | V32: =VLOOKUP(U32,KamiBox!$C$2:$F$54,4,0) -> 1800 | X32: =V32*W32 -> 0 | Z32: 29 | AA32: Kantung Semen
